2024-12-21 16:20:35,313 - WARNING - PyNaCl is not installed, voice will NOT be supported
2024-12-21 16:20:38,884 - INFO - HTTP Request: GET https://3morrrrr-of-verification-bot.hf.space/config "HTTP/1.1 200 OK"
2024-12-21 16:20:39,954 - INFO - HTTP Request: GET https://3morrrrr-of-verification-bot.hf.space/gradio_api/info?serialize=False "HTTP/1.1 200 OK"
2024-12-21 16:20:39,980 - INFO - logging in using static token
2024-12-21 16:20:41,206 - INFO - HTTP Request: GET https://3morrrrr-of-verification-bot.hf.space/gradio_api/heartbeat/dbe122a6-bcd3-4e39-869b-853832621614 "HTTP/1.1 200 OK"
2024-12-21 16:20:43,291 - INFO - Shard ID None has connected to Gateway (Session ID: 18584d05d41b90b3e7d5771b67e7db2a).
2024-12-21 16:20:45,310 - INFO - Bot is online as OF verification#6016
2024-12-21 16:22:36,194 - INFO - Image saved temporarily to: temp_photo_12_2024-12-14_11-00-21.jpg
2024-12-21 16:22:36,194 - INFO - Overlay text: HEY MICHAEL I AM REAL DO YOU BELIEVE ME NOW , the date is 21/12/2024
2024-12-21 16:22:36,195 - INFO - Payload being sent to API: {'image': {'path': 'temp_photo_12_2024-12-14_11-00-21.jpg', 'meta': {'_type': 'gradio.FileData'}, 'orig_name': 'temp_photo_12_2024-12-14_11-00-21.jpg'}, 'text': 'HEY MICHAEL I AM REAL DO YOU BELIEVE ME NOW , the date is 21/12/2024'}
2024-12-21 16:22:37,924 - INFO - HTTP Request: POST https://3morrrrr-of-verification-bot.hf.space/gradio_api/upload "HTTP/1.1 200 OK"
2024-12-21 16:22:38,690 - INFO - HTTP Request: POST https://3morrrrr-of-verification-bot.hf.space/gradio_api/queue/join "HTTP/1.1 200 OK"
2024-12-21 16:22:39,391 - INFO - HTTP Request: GET https://3morrrrr-of-verification-bot.hf.space/gradio_api/queue/data?session_hash=dbe122a6-bcd3-4e39-869b-853832621614 "HTTP/1.1 200 OK"
2024-12-21 16:22:43,040 - INFO - HTTP Request: GET https://3morrrrr-of-verification-bot.hf.space/gradio_api/file=/tmp/gradio/89a29cf92c2ea7e8100365dd5c5f1fcde2def85a17444b2e2ff9dda5824763a3/output_image.png "HTTP/1.1 200 OK"
2024-12-21 16:22:50,941 - INFO - HTTP Request: GET https://3morrrrr-of-verification-bot.hf.space/gradio_api/file=/tmp/gradio/89a29cf92c2ea7e8100365dd5c5f1fcde2def85a17444b2e2ff9dda5824763a3/output_image.png "HTTP/1.1 200 OK"
2024-12-21 16:22:56,797 - WARNING - Shard ID None heartbeat blocked for more than 10 seconds.
Loop thread traceback (most recent call last):
  File "d:\OF Bot\bot.py", line 111, in <module>
    bot.run(config.BOT_TOKEN)  # Token is imported securely from the configuration file
  File "C:\Users\MSI\AppData\Local\Packages\PythonSoftwareFoundation.Python.3.11_qbz5n2kfra8p0\LocalCache\local-packages\Python311\site-packages\discord\client.py", line 869, in run
    asyncio.run(runner())
  File "C:\Program Files\WindowsApps\PythonSoftwareFoundation.Python.3.11_3.11.2544.0_x64__qbz5n2kfra8p0\Lib\asyncio\runners.py", line 190, in run
    return runner.run(main)
  File "C:\Program Files\WindowsApps\PythonSoftwareFoundation.Python.3.11_3.11.2544.0_x64__qbz5n2kfra8p0\Lib\asyncio\runners.py", line 118, in run
    return self._loop.run_until_complete(task)
  File "C:\Program Files\WindowsApps\PythonSoftwareFoundation.Python.3.11_3.11.2544.0_x64__qbz5n2kfra8p0\Lib\asyncio\base_events.py", line 641, in run_until_complete
    self.run_forever()
  File "C:\Program Files\WindowsApps\PythonSoftwareFoundation.Python.3.11_3.11.2544.0_x64__qbz5n2kfra8p0\Lib\asyncio\windows_events.py", line 321, in run_forever
    super().run_forever()
  File "C:\Program Files\WindowsApps\PythonSoftwareFoundation.Python.3.11_3.11.2544.0_x64__qbz5n2kfra8p0\Lib\asyncio\base_events.py", line 608, in run_forever
    self._run_once()
  File "C:\Program Files\WindowsApps\PythonSoftwareFoundation.Python.3.11_3.11.2544.0_x64__qbz5n2kfra8p0\Lib\asyncio\base_events.py", line 1936, in _run_once
    handle._run()
  File "C:\Program Files\WindowsApps\PythonSoftwareFoundation.Python.3.11_3.11.2544.0_x64__qbz5n2kfra8p0\Lib\asyncio\events.py", line 84, in _run
    self._context.run(self._callback, *self._args)
  File "C:\Users\MSI\AppData\Local\Packages\PythonSoftwareFoundation.Python.3.11_qbz5n2kfra8p0\LocalCache\local-packages\Python311\site-packages\discord\client.py", line 449, in _run_event
    await coro(*args, **kwargs)
  File "d:\OF Bot\bot.py", line 52, in on_message
    await bot.process_commands(message)
  File "C:\Users\MSI\AppData\Local\Packages\PythonSoftwareFoundation.Python.3.11_qbz5n2kfra8p0\LocalCache\local-packages\Python311\site-packages\discord\ext\commands\bot.py", line 1408, in process_commands
    await self.invoke(ctx)  # type: ignore
  File "C:\Users\MSI\AppData\Local\Packages\PythonSoftwareFoundation.Python.3.11_qbz5n2kfra8p0\LocalCache\local-packages\Python311\site-packages\discord\ext\commands\bot.py", line 1366, in invoke
    await ctx.command.invoke(ctx)
  File "C:\Users\MSI\AppData\Local\Packages\PythonSoftwareFoundation.Python.3.11_qbz5n2kfra8p0\LocalCache\local-packages\Python311\site-packages\discord\ext\commands\core.py", line 1029, in invoke
    await injected(*ctx.args, **ctx.kwargs)  # type: ignore
  File "C:\Users\MSI\AppData\Local\Packages\PythonSoftwareFoundation.Python.3.11_qbz5n2kfra8p0\LocalCache\local-packages\Python311\site-packages\discord\ext\commands\core.py", line 235, in wrapped
    ret = await coro(*args, **kwargs)
  File "d:\OF Bot\bot.py", line 91, in upload
    result = client.predict(
  File "C:\Users\MSI\AppData\Local\Packages\PythonSoftwareFoundation.Python.3.11_qbz5n2kfra8p0\LocalCache\local-packages\Python311\site-packages\gradio_client\client.py", line 477, in predict
    ).result()
  File "C:\Users\MSI\AppData\Local\Packages\PythonSoftwareFoundation.Python.3.11_qbz5n2kfra8p0\LocalCache\local-packages\Python311\site-packages\gradio_client\client.py", line 1514, in result
    return super().result(timeout=timeout)
  File "C:\Program Files\WindowsApps\PythonSoftwareFoundation.Python.3.11_3.11.2544.0_x64__qbz5n2kfra8p0\Lib\concurrent\futures\_base.py", line 451, in result
    self._condition.wait(timeout)
  File "C:\Program Files\WindowsApps\PythonSoftwareFoundation.Python.3.11_3.11.2544.0_x64__qbz5n2kfra8p0\Lib\threading.py", line 327, in wait
    waiter.acquire()

2024-12-21 16:23:02,554 - INFO - API Response: ('C:\\Users\\MSI\\AppData\\Local\\Temp\\gradio\\96a6d70376aaebdd1187487e5bf90afb9da962fbd86bcb565f6e51208e0550ad\\output_image.png', 'C:\\Users\\MSI\\AppData\\Local\\Temp\\gradio\\96a6d70376aaebdd1187487e5bf90afb9da962fbd86bcb565f6e51208e0550ad\\output_image.png', 'Processing complete! Download the image below.')
2024-12-21 16:23:02,556 - ERROR - Attempting a reconnect in 0.54s
Traceback (most recent call last):
  File "C:\Users\MSI\AppData\Local\Packages\PythonSoftwareFoundation.Python.3.11_qbz5n2kfra8p0\LocalCache\local-packages\Python311\site-packages\discord\client.py", line 667, in connect
    await self.ws.poll_event()
  File "C:\Users\MSI\AppData\Local\Packages\PythonSoftwareFoundation.Python.3.11_qbz5n2kfra8p0\LocalCache\local-packages\Python311\site-packages\discord\gateway.py", line 625, in poll_event
    await self.received_message(msg.data)
  File "C:\Users\MSI\AppData\Local\Packages\PythonSoftwareFoundation.Python.3.11_qbz5n2kfra8p0\LocalCache\local-packages\Python311\site-packages\discord\gateway.py", line 533, in received_message
    await self.send_as_json(beat)
  File "C:\Users\MSI\AppData\Local\Packages\PythonSoftwareFoundation.Python.3.11_qbz5n2kfra8p0\LocalCache\local-packages\Python311\site-packages\discord\gateway.py", line 661, in send_as_json
    await self.send(utils._to_json(data))
  File "C:\Users\MSI\AppData\Local\Packages\PythonSoftwareFoundation.Python.3.11_qbz5n2kfra8p0\LocalCache\local-packages\Python311\site-packages\discord\gateway.py", line 657, in send
    await self.socket.send_str(data)
  File "C:\Users\MSI\AppData\Local\Packages\PythonSoftwareFoundation.Python.3.11_qbz5n2kfra8p0\LocalCache\local-packages\Python311\site-packages\aiohttp\client_ws.py", line 243, in send_str
    await self._writer.send_frame(
  File "C:\Users\MSI\AppData\Local\Packages\PythonSoftwareFoundation.Python.3.11_qbz5n2kfra8p0\LocalCache\local-packages\Python311\site-packages\aiohttp\_websocket\writer.py", line 125, in send_frame
    raise ClientConnectionResetError("Cannot write to closing transport")
aiohttp.client_exceptions.ClientConnectionResetError: Cannot write to closing transport
2024-12-21 16:23:04,049 - INFO - Shard ID None has successfully RESUMED session 18584d05d41b90b3e7d5771b67e7db2a.
2024-12-21 16:25:21,687 - WARNING - Can't keep up, shard ID None websocket is 14.1s behind.
2024-12-21 16:31:06,482 - INFO - Image saved temporarily to: temp_photo_12_2024-12-14_11-00-21.jpg
2024-12-21 16:31:06,483 - INFO - Overlay text: HEY MICHAEL I AM REAL DO YOU BELIEVE ME NOW , the date is 21/12/2024
2024-12-21 16:31:06,483 - INFO - Payload being sent to API: {'image': {'path': 'temp_photo_12_2024-12-14_11-00-21.jpg', 'meta': {'_type': 'gradio.FileData'}, 'orig_name': 'temp_photo_12_2024-12-14_11-00-21.jpg'}, 'text': 'HEY MICHAEL I AM REAL DO YOU BELIEVE ME NOW , the date is 21/12/2024'}
2024-12-21 16:31:08,089 - INFO - HTTP Request: POST https://3morrrrr-of-verification-bot.hf.space/gradio_api/upload "HTTP/1.1 200 OK"
2024-12-21 16:31:08,833 - INFO - HTTP Request: POST https://3morrrrr-of-verification-bot.hf.space/gradio_api/queue/join "HTTP/1.1 200 OK"
2024-12-21 16:31:09,539 - INFO - HTTP Request: GET https://3morrrrr-of-verification-bot.hf.space/gradio_api/queue/data?session_hash=dbe122a6-bcd3-4e39-869b-853832621614 "HTTP/1.1 200 OK"
2024-12-21 16:31:13,260 - INFO - HTTP Request: GET https://3morrrrr-of-verification-bot.hf.space/gradio_api/file=/tmp/gradio/889ae7439c7d0a6a2cce5c5f808c6ee45e00f1d5c8528ba8723a98e9e13b0dfb/output_image.png "HTTP/1.1 200 OK"
2024-12-21 16:31:19,360 - INFO - HTTP Request: GET https://3morrrrr-of-verification-bot.hf.space/gradio_api/file=/tmp/gradio/889ae7439c7d0a6a2cce5c5f808c6ee45e00f1d5c8528ba8723a98e9e13b0dfb/output_image.png "HTTP/1.1 200 OK"
2024-12-21 16:31:25,956 - INFO - API Response: ('C:\\Users\\MSI\\AppData\\Local\\Temp\\gradio\\96a6d70376aaebdd1187487e5bf90afb9da962fbd86bcb565f6e51208e0550ad\\output_image.png', 'C:\\Users\\MSI\\AppData\\Local\\Temp\\gradio\\96a6d70376aaebdd1187487e5bf90afb9da962fbd86bcb565f6e51208e0550ad\\output_image.png', 'Processing complete! Download the image below.')
2024-12-21 16:39:39,029 - INFO - Image saved temporarily to: temp_photo_12_2024-12-14_11-00-21.jpg
2024-12-21 16:39:39,029 - INFO - Overlay text: HEY MICHAEL I AM REAL DO YOU BELIEVE ME NOW , the date is 21/12/2024
2024-12-21 16:39:39,030 - INFO - Payload being sent to API: {'image': {'path': 'temp_photo_12_2024-12-14_11-00-21.jpg', 'meta': {'_type': 'gradio.FileData'}, 'orig_name': 'temp_photo_12_2024-12-14_11-00-21.jpg'}, 'text': 'HEY MICHAEL I AM REAL DO YOU BELIEVE ME NOW , the date is 21/12/2024'}
2024-12-21 16:39:40,797 - INFO - HTTP Request: POST https://3morrrrr-of-verification-bot.hf.space/gradio_api/upload "HTTP/1.1 200 OK"
2024-12-21 16:39:41,628 - INFO - HTTP Request: POST https://3morrrrr-of-verification-bot.hf.space/gradio_api/queue/join "HTTP/1.1 200 OK"
2024-12-21 16:39:42,500 - INFO - HTTP Request: GET https://3morrrrr-of-verification-bot.hf.space/gradio_api/queue/data?session_hash=dbe122a6-bcd3-4e39-869b-853832621614 "HTTP/1.1 200 OK"
2024-12-21 16:39:46,867 - INFO - HTTP Request: GET https://3morrrrr-of-verification-bot.hf.space/gradio_api/file=/tmp/gradio/b6a458d0aaa27a6357c391986600eaf267bcbeb4cce438791df92be8fc7dc626/output_image.png "HTTP/1.1 200 OK"
2024-12-21 16:39:51,019 - WARNING - Shard ID None heartbeat blocked for more than 10 seconds.
Loop thread traceback (most recent call last):
  File "d:\OF Bot\bot.py", line 111, in <module>
    bot.run(config.BOT_TOKEN)  # Token is imported securely from the configuration file
  File "C:\Users\MSI\AppData\Local\Packages\PythonSoftwareFoundation.Python.3.11_qbz5n2kfra8p0\LocalCache\local-packages\Python311\site-packages\discord\client.py", line 869, in run
    asyncio.run(runner())
  File "C:\Program Files\WindowsApps\PythonSoftwareFoundation.Python.3.11_3.11.2544.0_x64__qbz5n2kfra8p0\Lib\asyncio\runners.py", line 190, in run
    return runner.run(main)
  File "C:\Program Files\WindowsApps\PythonSoftwareFoundation.Python.3.11_3.11.2544.0_x64__qbz5n2kfra8p0\Lib\asyncio\runners.py", line 118, in run
    return self._loop.run_until_complete(task)
  File "C:\Program Files\WindowsApps\PythonSoftwareFoundation.Python.3.11_3.11.2544.0_x64__qbz5n2kfra8p0\Lib\asyncio\base_events.py", line 641, in run_until_complete
    self.run_forever()
  File "C:\Program Files\WindowsApps\PythonSoftwareFoundation.Python.3.11_3.11.2544.0_x64__qbz5n2kfra8p0\Lib\asyncio\windows_events.py", line 321, in run_forever
    super().run_forever()
  File "C:\Program Files\WindowsApps\PythonSoftwareFoundation.Python.3.11_3.11.2544.0_x64__qbz5n2kfra8p0\Lib\asyncio\base_events.py", line 608, in run_forever
    self._run_once()
  File "C:\Program Files\WindowsApps\PythonSoftwareFoundation.Python.3.11_3.11.2544.0_x64__qbz5n2kfra8p0\Lib\asyncio\base_events.py", line 1936, in _run_once
    handle._run()
  File "C:\Program Files\WindowsApps\PythonSoftwareFoundation.Python.3.11_3.11.2544.0_x64__qbz5n2kfra8p0\Lib\asyncio\events.py", line 84, in _run
    self._context.run(self._callback, *self._args)
  File "C:\Users\MSI\AppData\Local\Packages\PythonSoftwareFoundation.Python.3.11_qbz5n2kfra8p0\LocalCache\local-packages\Python311\site-packages\discord\client.py", line 449, in _run_event
    await coro(*args, **kwargs)
  File "d:\OF Bot\bot.py", line 52, in on_message
    await bot.process_commands(message)
  File "C:\Users\MSI\AppData\Local\Packages\PythonSoftwareFoundation.Python.3.11_qbz5n2kfra8p0\LocalCache\local-packages\Python311\site-packages\discord\ext\commands\bot.py", line 1408, in process_commands
    await self.invoke(ctx)  # type: ignore
  File "C:\Users\MSI\AppData\Local\Packages\PythonSoftwareFoundation.Python.3.11_qbz5n2kfra8p0\LocalCache\local-packages\Python311\site-packages\discord\ext\commands\bot.py", line 1366, in invoke
    await ctx.command.invoke(ctx)
  File "C:\Users\MSI\AppData\Local\Packages\PythonSoftwareFoundation.Python.3.11_qbz5n2kfra8p0\LocalCache\local-packages\Python311\site-packages\discord\ext\commands\core.py", line 1029, in invoke
    await injected(*ctx.args, **ctx.kwargs)  # type: ignore
  File "C:\Users\MSI\AppData\Local\Packages\PythonSoftwareFoundation.Python.3.11_qbz5n2kfra8p0\LocalCache\local-packages\Python311\site-packages\discord\ext\commands\core.py", line 235, in wrapped
    ret = await coro(*args, **kwargs)
  File "d:\OF Bot\bot.py", line 91, in upload
    result = client.predict(
  File "C:\Users\MSI\AppData\Local\Packages\PythonSoftwareFoundation.Python.3.11_qbz5n2kfra8p0\LocalCache\local-packages\Python311\site-packages\gradio_client\client.py", line 477, in predict
    ).result()
  File "C:\Users\MSI\AppData\Local\Packages\PythonSoftwareFoundation.Python.3.11_qbz5n2kfra8p0\LocalCache\local-packages\Python311\site-packages\gradio_client\client.py", line 1514, in result
    return super().result(timeout=timeout)
  File "C:\Program Files\WindowsApps\PythonSoftwareFoundation.Python.3.11_3.11.2544.0_x64__qbz5n2kfra8p0\Lib\concurrent\futures\_base.py", line 451, in result
    self._condition.wait(timeout)
  File "C:\Program Files\WindowsApps\PythonSoftwareFoundation.Python.3.11_3.11.2544.0_x64__qbz5n2kfra8p0\Lib\threading.py", line 327, in wait
    waiter.acquire()

2024-12-21 16:39:53,370 - INFO - HTTP Request: GET https://3morrrrr-of-verification-bot.hf.space/gradio_api/file=/tmp/gradio/b6a458d0aaa27a6357c391986600eaf267bcbeb4cce438791df92be8fc7dc626/output_image.png "HTTP/1.1 200 OK"
2024-12-21 16:40:01,026 - WARNING - Shard ID None heartbeat blocked for more than 20 seconds.
Loop thread traceback (most recent call last):
  File "d:\OF Bot\bot.py", line 111, in <module>
    bot.run(config.BOT_TOKEN)  # Token is imported securely from the configuration file
  File "C:\Users\MSI\AppData\Local\Packages\PythonSoftwareFoundation.Python.3.11_qbz5n2kfra8p0\LocalCache\local-packages\Python311\site-packages\discord\client.py", line 869, in run
    asyncio.run(runner())
  File "C:\Program Files\WindowsApps\PythonSoftwareFoundation.Python.3.11_3.11.2544.0_x64__qbz5n2kfra8p0\Lib\asyncio\runners.py", line 190, in run
    return runner.run(main)
  File "C:\Program Files\WindowsApps\PythonSoftwareFoundation.Python.3.11_3.11.2544.0_x64__qbz5n2kfra8p0\Lib\asyncio\runners.py", line 118, in run
    return self._loop.run_until_complete(task)
  File "C:\Program Files\WindowsApps\PythonSoftwareFoundation.Python.3.11_3.11.2544.0_x64__qbz5n2kfra8p0\Lib\asyncio\base_events.py", line 641, in run_until_complete
    self.run_forever()
  File "C:\Program Files\WindowsApps\PythonSoftwareFoundation.Python.3.11_3.11.2544.0_x64__qbz5n2kfra8p0\Lib\asyncio\windows_events.py", line 321, in run_forever
    super().run_forever()
  File "C:\Program Files\WindowsApps\PythonSoftwareFoundation.Python.3.11_3.11.2544.0_x64__qbz5n2kfra8p0\Lib\asyncio\base_events.py", line 608, in run_forever
    self._run_once()
  File "C:\Program Files\WindowsApps\PythonSoftwareFoundation.Python.3.11_3.11.2544.0_x64__qbz5n2kfra8p0\Lib\asyncio\base_events.py", line 1936, in _run_once
    handle._run()
  File "C:\Program Files\WindowsApps\PythonSoftwareFoundation.Python.3.11_3.11.2544.0_x64__qbz5n2kfra8p0\Lib\asyncio\events.py", line 84, in _run
    self._context.run(self._callback, *self._args)
  File "C:\Users\MSI\AppData\Local\Packages\PythonSoftwareFoundation.Python.3.11_qbz5n2kfra8p0\LocalCache\local-packages\Python311\site-packages\discord\client.py", line 449, in _run_event
    await coro(*args, **kwargs)
  File "d:\OF Bot\bot.py", line 52, in on_message
    await bot.process_commands(message)
  File "C:\Users\MSI\AppData\Local\Packages\PythonSoftwareFoundation.Python.3.11_qbz5n2kfra8p0\LocalCache\local-packages\Python311\site-packages\discord\ext\commands\bot.py", line 1408, in process_commands
    await self.invoke(ctx)  # type: ignore
  File "C:\Users\MSI\AppData\Local\Packages\PythonSoftwareFoundation.Python.3.11_qbz5n2kfra8p0\LocalCache\local-packages\Python311\site-packages\discord\ext\commands\bot.py", line 1366, in invoke
    await ctx.command.invoke(ctx)
  File "C:\Users\MSI\AppData\Local\Packages\PythonSoftwareFoundation.Python.3.11_qbz5n2kfra8p0\LocalCache\local-packages\Python311\site-packages\discord\ext\commands\core.py", line 1029, in invoke
    await injected(*ctx.args, **ctx.kwargs)  # type: ignore
  File "C:\Users\MSI\AppData\Local\Packages\PythonSoftwareFoundation.Python.3.11_qbz5n2kfra8p0\LocalCache\local-packages\Python311\site-packages\discord\ext\commands\core.py", line 235, in wrapped
    ret = await coro(*args, **kwargs)
  File "d:\OF Bot\bot.py", line 91, in upload
    result = client.predict(
  File "C:\Users\MSI\AppData\Local\Packages\PythonSoftwareFoundation.Python.3.11_qbz5n2kfra8p0\LocalCache\local-packages\Python311\site-packages\gradio_client\client.py", line 477, in predict
    ).result()
  File "C:\Users\MSI\AppData\Local\Packages\PythonSoftwareFoundation.Python.3.11_qbz5n2kfra8p0\LocalCache\local-packages\Python311\site-packages\gradio_client\client.py", line 1514, in result
    return super().result(timeout=timeout)
  File "C:\Program Files\WindowsApps\PythonSoftwareFoundation.Python.3.11_3.11.2544.0_x64__qbz5n2kfra8p0\Lib\concurrent\futures\_base.py", line 451, in result
    self._condition.wait(timeout)
  File "C:\Program Files\WindowsApps\PythonSoftwareFoundation.Python.3.11_3.11.2544.0_x64__qbz5n2kfra8p0\Lib\threading.py", line 327, in wait
    waiter.acquire()

2024-12-21 16:40:01,411 - INFO - API Response: ('C:\\Users\\MSI\\AppData\\Local\\Temp\\gradio\\594927e45e251e6897e0d46e1b7d540b21d865e66bccdef4b44288e7171d46c1\\output_image.png', 'C:\\Users\\MSI\\AppData\\Local\\Temp\\gradio\\594927e45e251e6897e0d46e1b7d540b21d865e66bccdef4b44288e7171d46c1\\output_image.png', 'Processing complete! Download the image below.')
2024-12-21 16:40:01,413 - ERROR - Attempting a reconnect in 0.89s
Traceback (most recent call last):
  File "C:\Users\MSI\AppData\Local\Packages\PythonSoftwareFoundation.Python.3.11_qbz5n2kfra8p0\LocalCache\local-packages\Python311\site-packages\discord\client.py", line 667, in connect
    await self.ws.poll_event()
  File "C:\Users\MSI\AppData\Local\Packages\PythonSoftwareFoundation.Python.3.11_qbz5n2kfra8p0\LocalCache\local-packages\Python311\site-packages\discord\gateway.py", line 648, in poll_event
    raise ConnectionClosed(self.socket, shard_id=self.shard_id, code=code) from None
discord.errors.ConnectionClosed: Shard ID None WebSocket closed with 1000
2024-12-21 16:40:03,368 - INFO - Shard ID None has successfully RESUMED session 18584d05d41b90b3e7d5771b67e7db2a.
2024-12-21 16:42:36,397 - INFO - Image saved temporarily to: temp_photo_3_2024-12-14_11-00-21.jpg
2024-12-21 16:42:36,398 - INFO - Overlay text: HEY MICHAEL I AM REAL DO YOU BELIEVE ME NOW , the date is 21/12/2024
2024-12-21 16:42:36,399 - INFO - Payload being sent to API: {'image': {'path': 'temp_photo_3_2024-12-14_11-00-21.jpg', 'meta': {'_type': 'gradio.FileData'}, 'orig_name': 'temp_photo_3_2024-12-14_11-00-21.jpg'}, 'text': 'HEY MICHAEL I AM REAL DO YOU BELIEVE ME NOW , the date is 21/12/2024'}
2024-12-21 16:42:38,180 - INFO - HTTP Request: POST https://3morrrrr-of-verification-bot.hf.space/gradio_api/upload "HTTP/1.1 200 OK"
2024-12-21 16:42:39,036 - INFO - HTTP Request: POST https://3morrrrr-of-verification-bot.hf.space/gradio_api/queue/join "HTTP/1.1 200 OK"
2024-12-21 16:42:39,800 - INFO - HTTP Request: GET https://3morrrrr-of-verification-bot.hf.space/gradio_api/queue/data?session_hash=dbe122a6-bcd3-4e39-869b-853832621614 "HTTP/1.1 200 OK"
2024-12-21 16:42:42,597 - INFO - HTTP Request: GET https://3morrrrr-of-verification-bot.hf.space/gradio_api/file=/tmp/gradio/ddaed7f34aee09468a09d72414f1b08781e069ba67a4a6716205962219a7624f/output_image.png "HTTP/1.1 200 OK"
2024-12-21 16:42:50,458 - INFO - HTTP Request: GET https://3morrrrr-of-verification-bot.hf.space/gradio_api/file=/tmp/gradio/ddaed7f34aee09468a09d72414f1b08781e069ba67a4a6716205962219a7624f/output_image.png "HTTP/1.1 200 OK"
2024-12-21 16:42:57,078 - INFO - API Response: ('C:\\Users\\MSI\\AppData\\Local\\Temp\\gradio\\0d621f307792488fdb963e10a72700047e6ad7a4e4fbf2e12f1bea23808a8325\\output_image.png', 'C:\\Users\\MSI\\AppData\\Local\\Temp\\gradio\\0d621f307792488fdb963e10a72700047e6ad7a4e4fbf2e12f1bea23808a8325\\output_image.png', 'Processing complete! Download the image below.')
2024-12-21 16:44:40,381 - INFO - Image saved temporarily to: temp_photo_12_2024-12-14_11-00-21.jpg
2024-12-21 16:44:40,383 - INFO - Overlay text: HEY MICHAEL I AM REAL DO YOU BELIEVE ME NOW , the date is 21/12/2024
2024-12-21 16:44:40,383 - INFO - Payload being sent to API: {'image': {'path': 'temp_photo_12_2024-12-14_11-00-21.jpg', 'meta': {'_type': 'gradio.FileData'}, 'orig_name': 'temp_photo_12_2024-12-14_11-00-21.jpg'}, 'text': 'HEY MICHAEL I AM REAL DO YOU BELIEVE ME NOW , the date is 21/12/2024'}
2024-12-21 16:44:43,680 - INFO - HTTP Request: POST https://3morrrrr-of-verification-bot.hf.space/gradio_api/upload "HTTP/1.1 200 OK"
2024-12-21 16:44:44,519 - INFO - HTTP Request: POST https://3morrrrr-of-verification-bot.hf.space/gradio_api/queue/join "HTTP/1.1 200 OK"
2024-12-21 16:44:45,291 - INFO - HTTP Request: GET https://3morrrrr-of-verification-bot.hf.space/gradio_api/queue/data?session_hash=dbe122a6-bcd3-4e39-869b-853832621614 "HTTP/1.1 200 OK"
2024-12-21 16:44:48,526 - INFO - HTTP Request: GET https://3morrrrr-of-verification-bot.hf.space/gradio_api/file=/tmp/gradio/3dfa025c7c2ae2f35ae17008af74b3fdb2391c277cd980097185e2147fe27f6b/output_image.png "HTTP/1.1 200 OK"
2024-12-21 16:44:54,783 - INFO - HTTP Request: GET https://3morrrrr-of-verification-bot.hf.space/gradio_api/file=/tmp/gradio/3dfa025c7c2ae2f35ae17008af74b3fdb2391c277cd980097185e2147fe27f6b/output_image.png "HTTP/1.1 200 OK"
2024-12-21 16:45:01,909 - INFO - API Response: ('C:\\Users\\MSI\\AppData\\Local\\Temp\\gradio\\594927e45e251e6897e0d46e1b7d540b21d865e66bccdef4b44288e7171d46c1\\output_image.png', 'C:\\Users\\MSI\\AppData\\Local\\Temp\\gradio\\594927e45e251e6897e0d46e1b7d540b21d865e66bccdef4b44288e7171d46c1\\output_image.png', 'Processing complete! Download the image below.')
2024-12-21 16:47:28,767 - INFO - Image saved temporarily to: temp_photo_12_2024-12-14_11-00-21.jpg
2024-12-21 16:47:28,767 - INFO - Overlay text: HEY MICHAEL I AM REAL DO YOU BELIEVE ME NOW , the date is 21/12/2024
2024-12-21 16:47:28,769 - INFO - Payload being sent to API: {'image': {'path': 'temp_photo_12_2024-12-14_11-00-21.jpg', 'meta': {'_type': 'gradio.FileData'}, 'orig_name': 'temp_photo_12_2024-12-14_11-00-21.jpg'}, 'text': 'HEY MICHAEL I AM REAL DO YOU BELIEVE ME NOW , the date is 21/12/2024'}
2024-12-21 16:47:30,446 - INFO - HTTP Request: POST https://3morrrrr-of-verification-bot.hf.space/gradio_api/upload "HTTP/1.1 200 OK"
2024-12-21 16:47:31,177 - INFO - HTTP Request: POST https://3morrrrr-of-verification-bot.hf.space/gradio_api/queue/join "HTTP/1.1 200 OK"
2024-12-21 16:47:31,949 - INFO - HTTP Request: GET https://3morrrrr-of-verification-bot.hf.space/gradio_api/queue/data?session_hash=dbe122a6-bcd3-4e39-869b-853832621614 "HTTP/1.1 200 OK"
2024-12-21 16:47:35,744 - INFO - HTTP Request: GET https://3morrrrr-of-verification-bot.hf.space/gradio_api/file=/tmp/gradio/83791d677c23f947f4348f2477176c8865067718bd6056edc8ed7b1b022a1bb2/output_image.png "HTTP/1.1 200 OK"
2024-12-21 16:47:43,329 - INFO - HTTP Request: GET https://3morrrrr-of-verification-bot.hf.space/gradio_api/file=/tmp/gradio/83791d677c23f947f4348f2477176c8865067718bd6056edc8ed7b1b022a1bb2/output_image.png "HTTP/1.1 200 OK"
2024-12-21 16:47:50,715 - INFO - API Response: ('C:\\Users\\MSI\\AppData\\Local\\Temp\\gradio\\96a6d70376aaebdd1187487e5bf90afb9da962fbd86bcb565f6e51208e0550ad\\output_image.png', 'C:\\Users\\MSI\\AppData\\Local\\Temp\\gradio\\96a6d70376aaebdd1187487e5bf90afb9da962fbd86bcb565f6e51208e0550ad\\output_image.png', 'Processing complete! Download the image below.')
2024-12-21 16:51:19,718 - INFO - Image saved temporarily to: temp_IMG_2617_Oriana.jpeg
2024-12-21 16:51:19,722 - INFO - Overlay text: HEY MICHAEL I AM REAL DO YOU BELIEVE ME NOW , the date is 21/12/2024
2024-12-21 16:51:19,723 - INFO - Payload being sent to API: {'image': {'path': 'temp_IMG_2617_Oriana.jpeg', 'meta': {'_type': 'gradio.FileData'}, 'orig_name': 'temp_IMG_2617_Oriana.jpeg'}, 'text': 'HEY MICHAEL I AM REAL DO YOU BELIEVE ME NOW , the date is 21/12/2024'}
2024-12-21 16:51:37,208 - INFO - HTTP Request: POST https://3morrrrr-of-verification-bot.hf.space/gradio_api/upload "HTTP/1.1 200 OK"
2024-12-21 16:51:37,941 - INFO - HTTP Request: POST https://3morrrrr-of-verification-bot.hf.space/gradio_api/queue/join "HTTP/1.1 200 OK"
2024-12-21 16:51:38,858 - INFO - HTTP Request: GET https://3morrrrr-of-verification-bot.hf.space/gradio_api/queue/data?session_hash=dbe122a6-bcd3-4e39-869b-853832621614 "HTTP/1.1 200 OK"
2024-12-21 16:51:44,011 - INFO - HTTP Request: GET https://3morrrrr-of-verification-bot.hf.space/gradio_api/file=/tmp/gradio/78168d33955525cb27878618940fdf1ad092dff33b2d306820f8a48e603e70f0/output_image.png "HTTP/1.1 200 OK"
2024-12-21 16:52:08,256 - WARNING - Shard ID None heartbeat blocked for more than 10 seconds.
Loop thread traceback (most recent call last):
  File "d:\OF Bot\bot.py", line 111, in <module>
    bot.run(config.BOT_TOKEN)  # Token is imported securely from the configuration file
  File "C:\Users\MSI\AppData\Local\Packages\PythonSoftwareFoundation.Python.3.11_qbz5n2kfra8p0\LocalCache\local-packages\Python311\site-packages\discord\client.py", line 869, in run
    asyncio.run(runner())
  File "C:\Program Files\WindowsApps\PythonSoftwareFoundation.Python.3.11_3.11.2544.0_x64__qbz5n2kfra8p0\Lib\asyncio\runners.py", line 190, in run
    return runner.run(main)
  File "C:\Program Files\WindowsApps\PythonSoftwareFoundation.Python.3.11_3.11.2544.0_x64__qbz5n2kfra8p0\Lib\asyncio\runners.py", line 118, in run
    return self._loop.run_until_complete(task)
  File "C:\Program Files\WindowsApps\PythonSoftwareFoundation.Python.3.11_3.11.2544.0_x64__qbz5n2kfra8p0\Lib\asyncio\base_events.py", line 641, in run_until_complete
    self.run_forever()
  File "C:\Program Files\WindowsApps\PythonSoftwareFoundation.Python.3.11_3.11.2544.0_x64__qbz5n2kfra8p0\Lib\asyncio\windows_events.py", line 321, in run_forever
    super().run_forever()
  File "C:\Program Files\WindowsApps\PythonSoftwareFoundation.Python.3.11_3.11.2544.0_x64__qbz5n2kfra8p0\Lib\asyncio\base_events.py", line 608, in run_forever
    self._run_once()
  File "C:\Program Files\WindowsApps\PythonSoftwareFoundation.Python.3.11_3.11.2544.0_x64__qbz5n2kfra8p0\Lib\asyncio\base_events.py", line 1936, in _run_once
    handle._run()
  File "C:\Program Files\WindowsApps\PythonSoftwareFoundation.Python.3.11_3.11.2544.0_x64__qbz5n2kfra8p0\Lib\asyncio\events.py", line 84, in _run
    self._context.run(self._callback, *self._args)
  File "C:\Users\MSI\AppData\Local\Packages\PythonSoftwareFoundation.Python.3.11_qbz5n2kfra8p0\LocalCache\local-packages\Python311\site-packages\discord\client.py", line 449, in _run_event
    await coro(*args, **kwargs)
  File "d:\OF Bot\bot.py", line 52, in on_message
    await bot.process_commands(message)
  File "C:\Users\MSI\AppData\Local\Packages\PythonSoftwareFoundation.Python.3.11_qbz5n2kfra8p0\LocalCache\local-packages\Python311\site-packages\discord\ext\commands\bot.py", line 1408, in process_commands
    await self.invoke(ctx)  # type: ignore
  File "C:\Users\MSI\AppData\Local\Packages\PythonSoftwareFoundation.Python.3.11_qbz5n2kfra8p0\LocalCache\local-packages\Python311\site-packages\discord\ext\commands\bot.py", line 1366, in invoke
    await ctx.command.invoke(ctx)
  File "C:\Users\MSI\AppData\Local\Packages\PythonSoftwareFoundation.Python.3.11_qbz5n2kfra8p0\LocalCache\local-packages\Python311\site-packages\discord\ext\commands\core.py", line 1029, in invoke
    await injected(*ctx.args, **ctx.kwargs)  # type: ignore
  File "C:\Users\MSI\AppData\Local\Packages\PythonSoftwareFoundation.Python.3.11_qbz5n2kfra8p0\LocalCache\local-packages\Python311\site-packages\discord\ext\commands\core.py", line 235, in wrapped
    ret = await coro(*args, **kwargs)
  File "d:\OF Bot\bot.py", line 91, in upload
    result = client.predict(
  File "C:\Users\MSI\AppData\Local\Packages\PythonSoftwareFoundation.Python.3.11_qbz5n2kfra8p0\LocalCache\local-packages\Python311\site-packages\gradio_client\client.py", line 477, in predict
    ).result()
  File "C:\Users\MSI\AppData\Local\Packages\PythonSoftwareFoundation.Python.3.11_qbz5n2kfra8p0\LocalCache\local-packages\Python311\site-packages\gradio_client\client.py", line 1514, in result
    return super().result(timeout=timeout)
  File "C:\Program Files\WindowsApps\PythonSoftwareFoundation.Python.3.11_3.11.2544.0_x64__qbz5n2kfra8p0\Lib\concurrent\futures\_base.py", line 451, in result
    self._condition.wait(timeout)
  File "C:\Program Files\WindowsApps\PythonSoftwareFoundation.Python.3.11_3.11.2544.0_x64__qbz5n2kfra8p0\Lib\threading.py", line 327, in wait
    waiter.acquire()

2024-12-21 16:52:18,269 - WARNING - Shard ID None heartbeat blocked for more than 20 seconds.
Loop thread traceback (most recent call last):
  File "d:\OF Bot\bot.py", line 111, in <module>
    bot.run(config.BOT_TOKEN)  # Token is imported securely from the configuration file
  File "C:\Users\MSI\AppData\Local\Packages\PythonSoftwareFoundation.Python.3.11_qbz5n2kfra8p0\LocalCache\local-packages\Python311\site-packages\discord\client.py", line 869, in run
    asyncio.run(runner())
  File "C:\Program Files\WindowsApps\PythonSoftwareFoundation.Python.3.11_3.11.2544.0_x64__qbz5n2kfra8p0\Lib\asyncio\runners.py", line 190, in run
    return runner.run(main)
  File "C:\Program Files\WindowsApps\PythonSoftwareFoundation.Python.3.11_3.11.2544.0_x64__qbz5n2kfra8p0\Lib\asyncio\runners.py", line 118, in run
    return self._loop.run_until_complete(task)
  File "C:\Program Files\WindowsApps\PythonSoftwareFoundation.Python.3.11_3.11.2544.0_x64__qbz5n2kfra8p0\Lib\asyncio\base_events.py", line 641, in run_until_complete
    self.run_forever()
  File "C:\Program Files\WindowsApps\PythonSoftwareFoundation.Python.3.11_3.11.2544.0_x64__qbz5n2kfra8p0\Lib\asyncio\windows_events.py", line 321, in run_forever
    super().run_forever()
  File "C:\Program Files\WindowsApps\PythonSoftwareFoundation.Python.3.11_3.11.2544.0_x64__qbz5n2kfra8p0\Lib\asyncio\base_events.py", line 608, in run_forever
    self._run_once()
  File "C:\Program Files\WindowsApps\PythonSoftwareFoundation.Python.3.11_3.11.2544.0_x64__qbz5n2kfra8p0\Lib\asyncio\base_events.py", line 1936, in _run_once
    handle._run()
  File "C:\Program Files\WindowsApps\PythonSoftwareFoundation.Python.3.11_3.11.2544.0_x64__qbz5n2kfra8p0\Lib\asyncio\events.py", line 84, in _run
    self._context.run(self._callback, *self._args)
  File "C:\Users\MSI\AppData\Local\Packages\PythonSoftwareFoundation.Python.3.11_qbz5n2kfra8p0\LocalCache\local-packages\Python311\site-packages\discord\client.py", line 449, in _run_event
    await coro(*args, **kwargs)
  File "d:\OF Bot\bot.py", line 52, in on_message
    await bot.process_commands(message)
  File "C:\Users\MSI\AppData\Local\Packages\PythonSoftwareFoundation.Python.3.11_qbz5n2kfra8p0\LocalCache\local-packages\Python311\site-packages\discord\ext\commands\bot.py", line 1408, in process_commands
    await self.invoke(ctx)  # type: ignore
  File "C:\Users\MSI\AppData\Local\Packages\PythonSoftwareFoundation.Python.3.11_qbz5n2kfra8p0\LocalCache\local-packages\Python311\site-packages\discord\ext\commands\bot.py", line 1366, in invoke
    await ctx.command.invoke(ctx)
  File "C:\Users\MSI\AppData\Local\Packages\PythonSoftwareFoundation.Python.3.11_qbz5n2kfra8p0\LocalCache\local-packages\Python311\site-packages\discord\ext\commands\core.py", line 1029, in invoke
    await injected(*ctx.args, **ctx.kwargs)  # type: ignore
  File "C:\Users\MSI\AppData\Local\Packages\PythonSoftwareFoundation.Python.3.11_qbz5n2kfra8p0\LocalCache\local-packages\Python311\site-packages\discord\ext\commands\core.py", line 235, in wrapped
    ret = await coro(*args, **kwargs)
  File "d:\OF Bot\bot.py", line 91, in upload
    result = client.predict(
  File "C:\Users\MSI\AppData\Local\Packages\PythonSoftwareFoundation.Python.3.11_qbz5n2kfra8p0\LocalCache\local-packages\Python311\site-packages\gradio_client\client.py", line 477, in predict
    ).result()
  File "C:\Users\MSI\AppData\Local\Packages\PythonSoftwareFoundation.Python.3.11_qbz5n2kfra8p0\LocalCache\local-packages\Python311\site-packages\gradio_client\client.py", line 1514, in result
    return super().result(timeout=timeout)
  File "C:\Program Files\WindowsApps\PythonSoftwareFoundation.Python.3.11_3.11.2544.0_x64__qbz5n2kfra8p0\Lib\concurrent\futures\_base.py", line 451, in result
    self._condition.wait(timeout)
  File "C:\Program Files\WindowsApps\PythonSoftwareFoundation.Python.3.11_3.11.2544.0_x64__qbz5n2kfra8p0\Lib\threading.py", line 327, in wait
    waiter.acquire()

2024-12-21 16:52:27,017 - INFO - HTTP Request: GET https://3morrrrr-of-verification-bot.hf.space/gradio_api/file=/tmp/gradio/78168d33955525cb27878618940fdf1ad092dff33b2d306820f8a48e603e70f0/output_image.png "HTTP/1.1 200 OK"
2024-12-21 16:52:28,276 - WARNING - Shard ID None heartbeat blocked for more than 30 seconds.
Loop thread traceback (most recent call last):
  File "d:\OF Bot\bot.py", line 111, in <module>
    bot.run(config.BOT_TOKEN)  # Token is imported securely from the configuration file
  File "C:\Users\MSI\AppData\Local\Packages\PythonSoftwareFoundation.Python.3.11_qbz5n2kfra8p0\LocalCache\local-packages\Python311\site-packages\discord\client.py", line 869, in run
    asyncio.run(runner())
  File "C:\Program Files\WindowsApps\PythonSoftwareFoundation.Python.3.11_3.11.2544.0_x64__qbz5n2kfra8p0\Lib\asyncio\runners.py", line 190, in run
    return runner.run(main)
  File "C:\Program Files\WindowsApps\PythonSoftwareFoundation.Python.3.11_3.11.2544.0_x64__qbz5n2kfra8p0\Lib\asyncio\runners.py", line 118, in run
    return self._loop.run_until_complete(task)
  File "C:\Program Files\WindowsApps\PythonSoftwareFoundation.Python.3.11_3.11.2544.0_x64__qbz5n2kfra8p0\Lib\asyncio\base_events.py", line 641, in run_until_complete
    self.run_forever()
  File "C:\Program Files\WindowsApps\PythonSoftwareFoundation.Python.3.11_3.11.2544.0_x64__qbz5n2kfra8p0\Lib\asyncio\windows_events.py", line 321, in run_forever
    super().run_forever()
  File "C:\Program Files\WindowsApps\PythonSoftwareFoundation.Python.3.11_3.11.2544.0_x64__qbz5n2kfra8p0\Lib\asyncio\base_events.py", line 608, in run_forever
    self._run_once()
  File "C:\Program Files\WindowsApps\PythonSoftwareFoundation.Python.3.11_3.11.2544.0_x64__qbz5n2kfra8p0\Lib\asyncio\base_events.py", line 1936, in _run_once
    handle._run()
  File "C:\Program Files\WindowsApps\PythonSoftwareFoundation.Python.3.11_3.11.2544.0_x64__qbz5n2kfra8p0\Lib\asyncio\events.py", line 84, in _run
    self._context.run(self._callback, *self._args)
  File "C:\Users\MSI\AppData\Local\Packages\PythonSoftwareFoundation.Python.3.11_qbz5n2kfra8p0\LocalCache\local-packages\Python311\site-packages\discord\client.py", line 449, in _run_event
    await coro(*args, **kwargs)
  File "d:\OF Bot\bot.py", line 52, in on_message
    await bot.process_commands(message)
  File "C:\Users\MSI\AppData\Local\Packages\PythonSoftwareFoundation.Python.3.11_qbz5n2kfra8p0\LocalCache\local-packages\Python311\site-packages\discord\ext\commands\bot.py", line 1408, in process_commands
    await self.invoke(ctx)  # type: ignore
  File "C:\Users\MSI\AppData\Local\Packages\PythonSoftwareFoundation.Python.3.11_qbz5n2kfra8p0\LocalCache\local-packages\Python311\site-packages\discord\ext\commands\bot.py", line 1366, in invoke
    await ctx.command.invoke(ctx)
  File "C:\Users\MSI\AppData\Local\Packages\PythonSoftwareFoundation.Python.3.11_qbz5n2kfra8p0\LocalCache\local-packages\Python311\site-packages\discord\ext\commands\core.py", line 1029, in invoke
    await injected(*ctx.args, **ctx.kwargs)  # type: ignore
  File "C:\Users\MSI\AppData\Local\Packages\PythonSoftwareFoundation.Python.3.11_qbz5n2kfra8p0\LocalCache\local-packages\Python311\site-packages\discord\ext\commands\core.py", line 235, in wrapped
    ret = await coro(*args, **kwargs)
  File "d:\OF Bot\bot.py", line 91, in upload
    result = client.predict(
  File "C:\Users\MSI\AppData\Local\Packages\PythonSoftwareFoundation.Python.3.11_qbz5n2kfra8p0\LocalCache\local-packages\Python311\site-packages\gradio_client\client.py", line 477, in predict
    ).result()
  File "C:\Users\MSI\AppData\Local\Packages\PythonSoftwareFoundation.Python.3.11_qbz5n2kfra8p0\LocalCache\local-packages\Python311\site-packages\gradio_client\client.py", line 1514, in result
    return super().result(timeout=timeout)
  File "C:\Program Files\WindowsApps\PythonSoftwareFoundation.Python.3.11_3.11.2544.0_x64__qbz5n2kfra8p0\Lib\concurrent\futures\_base.py", line 451, in result
    self._condition.wait(timeout)
  File "C:\Program Files\WindowsApps\PythonSoftwareFoundation.Python.3.11_3.11.2544.0_x64__qbz5n2kfra8p0\Lib\threading.py", line 327, in wait
    waiter.acquire()

2024-12-21 16:52:38,284 - WARNING - Shard ID None heartbeat blocked for more than 40 seconds.
Loop thread traceback (most recent call last):
  File "d:\OF Bot\bot.py", line 111, in <module>
    bot.run(config.BOT_TOKEN)  # Token is imported securely from the configuration file
  File "C:\Users\MSI\AppData\Local\Packages\PythonSoftwareFoundation.Python.3.11_qbz5n2kfra8p0\LocalCache\local-packages\Python311\site-packages\discord\client.py", line 869, in run
    asyncio.run(runner())
  File "C:\Program Files\WindowsApps\PythonSoftwareFoundation.Python.3.11_3.11.2544.0_x64__qbz5n2kfra8p0\Lib\asyncio\runners.py", line 190, in run
    return runner.run(main)
  File "C:\Program Files\WindowsApps\PythonSoftwareFoundation.Python.3.11_3.11.2544.0_x64__qbz5n2kfra8p0\Lib\asyncio\runners.py", line 118, in run
    return self._loop.run_until_complete(task)
  File "C:\Program Files\WindowsApps\PythonSoftwareFoundation.Python.3.11_3.11.2544.0_x64__qbz5n2kfra8p0\Lib\asyncio\base_events.py", line 641, in run_until_complete
    self.run_forever()
  File "C:\Program Files\WindowsApps\PythonSoftwareFoundation.Python.3.11_3.11.2544.0_x64__qbz5n2kfra8p0\Lib\asyncio\windows_events.py", line 321, in run_forever
    super().run_forever()
  File "C:\Program Files\WindowsApps\PythonSoftwareFoundation.Python.3.11_3.11.2544.0_x64__qbz5n2kfra8p0\Lib\asyncio\base_events.py", line 608, in run_forever
    self._run_once()
  File "C:\Program Files\WindowsApps\PythonSoftwareFoundation.Python.3.11_3.11.2544.0_x64__qbz5n2kfra8p0\Lib\asyncio\base_events.py", line 1936, in _run_once
    handle._run()
  File "C:\Program Files\WindowsApps\PythonSoftwareFoundation.Python.3.11_3.11.2544.0_x64__qbz5n2kfra8p0\Lib\asyncio\events.py", line 84, in _run
    self._context.run(self._callback, *self._args)
  File "C:\Users\MSI\AppData\Local\Packages\PythonSoftwareFoundation.Python.3.11_qbz5n2kfra8p0\LocalCache\local-packages\Python311\site-packages\discord\client.py", line 449, in _run_event
    await coro(*args, **kwargs)
  File "d:\OF Bot\bot.py", line 52, in on_message
    await bot.process_commands(message)
  File "C:\Users\MSI\AppData\Local\Packages\PythonSoftwareFoundation.Python.3.11_qbz5n2kfra8p0\LocalCache\local-packages\Python311\site-packages\discord\ext\commands\bot.py", line 1408, in process_commands
    await self.invoke(ctx)  # type: ignore
  File "C:\Users\MSI\AppData\Local\Packages\PythonSoftwareFoundation.Python.3.11_qbz5n2kfra8p0\LocalCache\local-packages\Python311\site-packages\discord\ext\commands\bot.py", line 1366, in invoke
    await ctx.command.invoke(ctx)
  File "C:\Users\MSI\AppData\Local\Packages\PythonSoftwareFoundation.Python.3.11_qbz5n2kfra8p0\LocalCache\local-packages\Python311\site-packages\discord\ext\commands\core.py", line 1029, in invoke
    await injected(*ctx.args, **ctx.kwargs)  # type: ignore
  File "C:\Users\MSI\AppData\Local\Packages\PythonSoftwareFoundation.Python.3.11_qbz5n2kfra8p0\LocalCache\local-packages\Python311\site-packages\discord\ext\commands\core.py", line 235, in wrapped
    ret = await coro(*args, **kwargs)
  File "d:\OF Bot\bot.py", line 91, in upload
    result = client.predict(
  File "C:\Users\MSI\AppData\Local\Packages\PythonSoftwareFoundation.Python.3.11_qbz5n2kfra8p0\LocalCache\local-packages\Python311\site-packages\gradio_client\client.py", line 477, in predict
    ).result()
  File "C:\Users\MSI\AppData\Local\Packages\PythonSoftwareFoundation.Python.3.11_qbz5n2kfra8p0\LocalCache\local-packages\Python311\site-packages\gradio_client\client.py", line 1514, in result
    return super().result(timeout=timeout)
  File "C:\Program Files\WindowsApps\PythonSoftwareFoundation.Python.3.11_3.11.2544.0_x64__qbz5n2kfra8p0\Lib\concurrent\futures\_base.py", line 451, in result
    self._condition.wait(timeout)
  File "C:\Program Files\WindowsApps\PythonSoftwareFoundation.Python.3.11_3.11.2544.0_x64__qbz5n2kfra8p0\Lib\threading.py", line 327, in wait
    waiter.acquire()

2024-12-21 16:52:48,288 - WARNING - Shard ID None heartbeat blocked for more than 50 seconds.
Loop thread traceback (most recent call last):
  File "d:\OF Bot\bot.py", line 111, in <module>
    bot.run(config.BOT_TOKEN)  # Token is imported securely from the configuration file
  File "C:\Users\MSI\AppData\Local\Packages\PythonSoftwareFoundation.Python.3.11_qbz5n2kfra8p0\LocalCache\local-packages\Python311\site-packages\discord\client.py", line 869, in run
    asyncio.run(runner())
  File "C:\Program Files\WindowsApps\PythonSoftwareFoundation.Python.3.11_3.11.2544.0_x64__qbz5n2kfra8p0\Lib\asyncio\runners.py", line 190, in run
    return runner.run(main)
  File "C:\Program Files\WindowsApps\PythonSoftwareFoundation.Python.3.11_3.11.2544.0_x64__qbz5n2kfra8p0\Lib\asyncio\runners.py", line 118, in run
    return self._loop.run_until_complete(task)
  File "C:\Program Files\WindowsApps\PythonSoftwareFoundation.Python.3.11_3.11.2544.0_x64__qbz5n2kfra8p0\Lib\asyncio\base_events.py", line 641, in run_until_complete
    self.run_forever()
  File "C:\Program Files\WindowsApps\PythonSoftwareFoundation.Python.3.11_3.11.2544.0_x64__qbz5n2kfra8p0\Lib\asyncio\windows_events.py", line 321, in run_forever
    super().run_forever()
  File "C:\Program Files\WindowsApps\PythonSoftwareFoundation.Python.3.11_3.11.2544.0_x64__qbz5n2kfra8p0\Lib\asyncio\base_events.py", line 608, in run_forever
    self._run_once()
  File "C:\Program Files\WindowsApps\PythonSoftwareFoundation.Python.3.11_3.11.2544.0_x64__qbz5n2kfra8p0\Lib\asyncio\base_events.py", line 1936, in _run_once
    handle._run()
  File "C:\Program Files\WindowsApps\PythonSoftwareFoundation.Python.3.11_3.11.2544.0_x64__qbz5n2kfra8p0\Lib\asyncio\events.py", line 84, in _run
    self._context.run(self._callback, *self._args)
  File "C:\Users\MSI\AppData\Local\Packages\PythonSoftwareFoundation.Python.3.11_qbz5n2kfra8p0\LocalCache\local-packages\Python311\site-packages\discord\client.py", line 449, in _run_event
    await coro(*args, **kwargs)
  File "d:\OF Bot\bot.py", line 52, in on_message
    await bot.process_commands(message)
  File "C:\Users\MSI\AppData\Local\Packages\PythonSoftwareFoundation.Python.3.11_qbz5n2kfra8p0\LocalCache\local-packages\Python311\site-packages\discord\ext\commands\bot.py", line 1408, in process_commands
    await self.invoke(ctx)  # type: ignore
  File "C:\Users\MSI\AppData\Local\Packages\PythonSoftwareFoundation.Python.3.11_qbz5n2kfra8p0\LocalCache\local-packages\Python311\site-packages\discord\ext\commands\bot.py", line 1366, in invoke
    await ctx.command.invoke(ctx)
  File "C:\Users\MSI\AppData\Local\Packages\PythonSoftwareFoundation.Python.3.11_qbz5n2kfra8p0\LocalCache\local-packages\Python311\site-packages\discord\ext\commands\core.py", line 1029, in invoke
    await injected(*ctx.args, **ctx.kwargs)  # type: ignore
  File "C:\Users\MSI\AppData\Local\Packages\PythonSoftwareFoundation.Python.3.11_qbz5n2kfra8p0\LocalCache\local-packages\Python311\site-packages\discord\ext\commands\core.py", line 235, in wrapped
    ret = await coro(*args, **kwargs)
  File "d:\OF Bot\bot.py", line 91, in upload
    result = client.predict(
  File "C:\Users\MSI\AppData\Local\Packages\PythonSoftwareFoundation.Python.3.11_qbz5n2kfra8p0\LocalCache\local-packages\Python311\site-packages\gradio_client\client.py", line 477, in predict
    ).result()
  File "C:\Users\MSI\AppData\Local\Packages\PythonSoftwareFoundation.Python.3.11_qbz5n2kfra8p0\LocalCache\local-packages\Python311\site-packages\gradio_client\client.py", line 1514, in result
    return super().result(timeout=timeout)
  File "C:\Program Files\WindowsApps\PythonSoftwareFoundation.Python.3.11_3.11.2544.0_x64__qbz5n2kfra8p0\Lib\concurrent\futures\_base.py", line 451, in result
    self._condition.wait(timeout)
  File "C:\Program Files\WindowsApps\PythonSoftwareFoundation.Python.3.11_3.11.2544.0_x64__qbz5n2kfra8p0\Lib\threading.py", line 327, in wait
    waiter.acquire()

2024-12-21 16:52:58,294 - WARNING - Shard ID None heartbeat blocked for more than 60 seconds.
Loop thread traceback (most recent call last):
  File "d:\OF Bot\bot.py", line 111, in <module>
    bot.run(config.BOT_TOKEN)  # Token is imported securely from the configuration file
  File "C:\Users\MSI\AppData\Local\Packages\PythonSoftwareFoundation.Python.3.11_qbz5n2kfra8p0\LocalCache\local-packages\Python311\site-packages\discord\client.py", line 869, in run
    asyncio.run(runner())
  File "C:\Program Files\WindowsApps\PythonSoftwareFoundation.Python.3.11_3.11.2544.0_x64__qbz5n2kfra8p0\Lib\asyncio\runners.py", line 190, in run
    return runner.run(main)
  File "C:\Program Files\WindowsApps\PythonSoftwareFoundation.Python.3.11_3.11.2544.0_x64__qbz5n2kfra8p0\Lib\asyncio\runners.py", line 118, in run
    return self._loop.run_until_complete(task)
  File "C:\Program Files\WindowsApps\PythonSoftwareFoundation.Python.3.11_3.11.2544.0_x64__qbz5n2kfra8p0\Lib\asyncio\base_events.py", line 641, in run_until_complete
    self.run_forever()
  File "C:\Program Files\WindowsApps\PythonSoftwareFoundation.Python.3.11_3.11.2544.0_x64__qbz5n2kfra8p0\Lib\asyncio\windows_events.py", line 321, in run_forever
    super().run_forever()
  File "C:\Program Files\WindowsApps\PythonSoftwareFoundation.Python.3.11_3.11.2544.0_x64__qbz5n2kfra8p0\Lib\asyncio\base_events.py", line 608, in run_forever
    self._run_once()
  File "C:\Program Files\WindowsApps\PythonSoftwareFoundation.Python.3.11_3.11.2544.0_x64__qbz5n2kfra8p0\Lib\asyncio\base_events.py", line 1936, in _run_once
    handle._run()
  File "C:\Program Files\WindowsApps\PythonSoftwareFoundation.Python.3.11_3.11.2544.0_x64__qbz5n2kfra8p0\Lib\asyncio\events.py", line 84, in _run
    self._context.run(self._callback, *self._args)
  File "C:\Users\MSI\AppData\Local\Packages\PythonSoftwareFoundation.Python.3.11_qbz5n2kfra8p0\LocalCache\local-packages\Python311\site-packages\discord\client.py", line 449, in _run_event
    await coro(*args, **kwargs)
  File "d:\OF Bot\bot.py", line 52, in on_message
    await bot.process_commands(message)
  File "C:\Users\MSI\AppData\Local\Packages\PythonSoftwareFoundation.Python.3.11_qbz5n2kfra8p0\LocalCache\local-packages\Python311\site-packages\discord\ext\commands\bot.py", line 1408, in process_commands
    await self.invoke(ctx)  # type: ignore
  File "C:\Users\MSI\AppData\Local\Packages\PythonSoftwareFoundation.Python.3.11_qbz5n2kfra8p0\LocalCache\local-packages\Python311\site-packages\discord\ext\commands\bot.py", line 1366, in invoke
    await ctx.command.invoke(ctx)
  File "C:\Users\MSI\AppData\Local\Packages\PythonSoftwareFoundation.Python.3.11_qbz5n2kfra8p0\LocalCache\local-packages\Python311\site-packages\discord\ext\commands\core.py", line 1029, in invoke
    await injected(*ctx.args, **ctx.kwargs)  # type: ignore
  File "C:\Users\MSI\AppData\Local\Packages\PythonSoftwareFoundation.Python.3.11_qbz5n2kfra8p0\LocalCache\local-packages\Python311\site-packages\discord\ext\commands\core.py", line 235, in wrapped
    ret = await coro(*args, **kwargs)
  File "d:\OF Bot\bot.py", line 91, in upload
    result = client.predict(
  File "C:\Users\MSI\AppData\Local\Packages\PythonSoftwareFoundation.Python.3.11_qbz5n2kfra8p0\LocalCache\local-packages\Python311\site-packages\gradio_client\client.py", line 477, in predict
    ).result()
  File "C:\Users\MSI\AppData\Local\Packages\PythonSoftwareFoundation.Python.3.11_qbz5n2kfra8p0\LocalCache\local-packages\Python311\site-packages\gradio_client\client.py", line 1514, in result
    return super().result(timeout=timeout)
  File "C:\Program Files\WindowsApps\PythonSoftwareFoundation.Python.3.11_3.11.2544.0_x64__qbz5n2kfra8p0\Lib\concurrent\futures\_base.py", line 451, in result
    self._condition.wait(timeout)
  File "C:\Program Files\WindowsApps\PythonSoftwareFoundation.Python.3.11_3.11.2544.0_x64__qbz5n2kfra8p0\Lib\threading.py", line 327, in wait
    waiter.acquire()

2024-12-21 16:53:08,307 - WARNING - Shard ID None heartbeat blocked for more than 70 seconds.
Loop thread traceback (most recent call last):
  File "d:\OF Bot\bot.py", line 111, in <module>
    bot.run(config.BOT_TOKEN)  # Token is imported securely from the configuration file
  File "C:\Users\MSI\AppData\Local\Packages\PythonSoftwareFoundation.Python.3.11_qbz5n2kfra8p0\LocalCache\local-packages\Python311\site-packages\discord\client.py", line 869, in run
    asyncio.run(runner())
  File "C:\Program Files\WindowsApps\PythonSoftwareFoundation.Python.3.11_3.11.2544.0_x64__qbz5n2kfra8p0\Lib\asyncio\runners.py", line 190, in run
    return runner.run(main)
  File "C:\Program Files\WindowsApps\PythonSoftwareFoundation.Python.3.11_3.11.2544.0_x64__qbz5n2kfra8p0\Lib\asyncio\runners.py", line 118, in run
    return self._loop.run_until_complete(task)
  File "C:\Program Files\WindowsApps\PythonSoftwareFoundation.Python.3.11_3.11.2544.0_x64__qbz5n2kfra8p0\Lib\asyncio\base_events.py", line 641, in run_until_complete
    self.run_forever()
  File "C:\Program Files\WindowsApps\PythonSoftwareFoundation.Python.3.11_3.11.2544.0_x64__qbz5n2kfra8p0\Lib\asyncio\windows_events.py", line 321, in run_forever
    super().run_forever()
  File "C:\Program Files\WindowsApps\PythonSoftwareFoundation.Python.3.11_3.11.2544.0_x64__qbz5n2kfra8p0\Lib\asyncio\base_events.py", line 608, in run_forever
    self._run_once()
  File "C:\Program Files\WindowsApps\PythonSoftwareFoundation.Python.3.11_3.11.2544.0_x64__qbz5n2kfra8p0\Lib\asyncio\base_events.py", line 1936, in _run_once
    handle._run()
  File "C:\Program Files\WindowsApps\PythonSoftwareFoundation.Python.3.11_3.11.2544.0_x64__qbz5n2kfra8p0\Lib\asyncio\events.py", line 84, in _run
    self._context.run(self._callback, *self._args)
  File "C:\Users\MSI\AppData\Local\Packages\PythonSoftwareFoundation.Python.3.11_qbz5n2kfra8p0\LocalCache\local-packages\Python311\site-packages\discord\client.py", line 449, in _run_event
    await coro(*args, **kwargs)
  File "d:\OF Bot\bot.py", line 52, in on_message
    await bot.process_commands(message)
  File "C:\Users\MSI\AppData\Local\Packages\PythonSoftwareFoundation.Python.3.11_qbz5n2kfra8p0\LocalCache\local-packages\Python311\site-packages\discord\ext\commands\bot.py", line 1408, in process_commands
    await self.invoke(ctx)  # type: ignore
  File "C:\Users\MSI\AppData\Local\Packages\PythonSoftwareFoundation.Python.3.11_qbz5n2kfra8p0\LocalCache\local-packages\Python311\site-packages\discord\ext\commands\bot.py", line 1366, in invoke
    await ctx.command.invoke(ctx)
  File "C:\Users\MSI\AppData\Local\Packages\PythonSoftwareFoundation.Python.3.11_qbz5n2kfra8p0\LocalCache\local-packages\Python311\site-packages\discord\ext\commands\core.py", line 1029, in invoke
    await injected(*ctx.args, **ctx.kwargs)  # type: ignore
  File "C:\Users\MSI\AppData\Local\Packages\PythonSoftwareFoundation.Python.3.11_qbz5n2kfra8p0\LocalCache\local-packages\Python311\site-packages\discord\ext\commands\core.py", line 235, in wrapped
    ret = await coro(*args, **kwargs)
  File "d:\OF Bot\bot.py", line 91, in upload
    result = client.predict(
  File "C:\Users\MSI\AppData\Local\Packages\PythonSoftwareFoundation.Python.3.11_qbz5n2kfra8p0\LocalCache\local-packages\Python311\site-packages\gradio_client\client.py", line 477, in predict
    ).result()
  File "C:\Users\MSI\AppData\Local\Packages\PythonSoftwareFoundation.Python.3.11_qbz5n2kfra8p0\LocalCache\local-packages\Python311\site-packages\gradio_client\client.py", line 1514, in result
    return super().result(timeout=timeout)
  File "C:\Program Files\WindowsApps\PythonSoftwareFoundation.Python.3.11_3.11.2544.0_x64__qbz5n2kfra8p0\Lib\concurrent\futures\_base.py", line 451, in result
    self._condition.wait(timeout)
  File "C:\Program Files\WindowsApps\PythonSoftwareFoundation.Python.3.11_3.11.2544.0_x64__qbz5n2kfra8p0\Lib\threading.py", line 327, in wait
    waiter.acquire()

2024-12-21 16:53:16,948 - INFO - API Response: ('C:\\Users\\MSI\\AppData\\Local\\Temp\\gradio\\7cf68cf6d438e78f4bfcefd75dda09204d75adeb2f45baa6f48e68450c2ad221\\output_image.png', 'C:\\Users\\MSI\\AppData\\Local\\Temp\\gradio\\7cf68cf6d438e78f4bfcefd75dda09204d75adeb2f45baa6f48e68450c2ad221\\output_image.png', 'Processing complete! Download the image below.')
2024-12-21 16:53:33,380 - WARNING - PyNaCl is not installed, voice will NOT be supported
2024-12-21 16:53:35,881 - INFO - HTTP Request: GET https://3morrrrr-of-verification-bot.hf.space/config "HTTP/1.1 200 OK"
2024-12-21 16:53:36,790 - INFO - HTTP Request: GET https://3morrrrr-of-verification-bot.hf.space/gradio_api/info?serialize=False "HTTP/1.1 200 OK"
2024-12-21 16:53:36,793 - INFO - logging in using static token
2024-12-21 16:53:37,847 - INFO - HTTP Request: GET https://3morrrrr-of-verification-bot.hf.space/gradio_api/heartbeat/914a57b3-24aa-4277-bd6c-9858b2069e54 "HTTP/1.1 200 OK"
2024-12-21 16:53:38,742 - INFO - Shard ID None has connected to Gateway (Session ID: 5410cff8ad245e0ae785539c64a1f4a3).
2024-12-21 16:53:40,831 - INFO - Bot is online as OF verification#6016
2024-12-21 16:54:35,159 - INFO - Image saved temporarily to: temp_IMG_2750_Oriana.jpeg
2024-12-21 16:54:35,160 - INFO - Overlay text: HEY MICHAEL I AM REAL DO YOU BELIEVE ME NOW , the date is 21/12/2024
2024-12-21 16:54:35,160 - INFO - Payload being sent to API: {'image': {'path': 'temp_IMG_2750_Oriana.jpeg', 'meta': {'_type': 'gradio.FileData'}, 'orig_name': 'temp_IMG_2750_Oriana.jpeg'}, 'text': 'HEY MICHAEL I AM REAL DO YOU BELIEVE ME NOW , the date is 21/12/2024'}
2024-12-21 16:54:49,246 - INFO - HTTP Request: POST https://3morrrrr-of-verification-bot.hf.space/gradio_api/upload "HTTP/1.1 200 OK"
2024-12-21 16:54:50,196 - INFO - HTTP Request: POST https://3morrrrr-of-verification-bot.hf.space/gradio_api/queue/join "HTTP/1.1 200 OK"
2024-12-21 16:54:51,098 - INFO - HTTP Request: GET https://3morrrrr-of-verification-bot.hf.space/gradio_api/queue/data?session_hash=914a57b3-24aa-4277-bd6c-9858b2069e54 "HTTP/1.1 200 OK"
2024-12-21 16:55:00,276 - INFO - HTTP Request: GET https://3morrrrr-of-verification-bot.hf.space/gradio_api/file=/tmp/gradio/b98a989ea1c26750582cf4ea418c338e48f5d2bce1b457d5b9ea63b3dbe6c6dd/output_image.png "HTTP/1.1 200 OK"
2024-12-21 16:55:10,969 - WARNING - Shard ID None heartbeat blocked for more than 10 seconds.
Loop thread traceback (most recent call last):
  File "d:\OF Bot\bot.py", line 111, in <module>
    bot.run(config.BOT_TOKEN)  # Token is imported securely from the configuration file
  File "C:\Users\MSI\AppData\Local\Packages\PythonSoftwareFoundation.Python.3.11_qbz5n2kfra8p0\LocalCache\local-packages\Python311\site-packages\discord\client.py", line 869, in run
    asyncio.run(runner())
  File "C:\Program Files\WindowsApps\PythonSoftwareFoundation.Python.3.11_3.11.2544.0_x64__qbz5n2kfra8p0\Lib\asyncio\runners.py", line 190, in run
    return runner.run(main)
  File "C:\Program Files\WindowsApps\PythonSoftwareFoundation.Python.3.11_3.11.2544.0_x64__qbz5n2kfra8p0\Lib\asyncio\runners.py", line 118, in run
    return self._loop.run_until_complete(task)
  File "C:\Program Files\WindowsApps\PythonSoftwareFoundation.Python.3.11_3.11.2544.0_x64__qbz5n2kfra8p0\Lib\asyncio\base_events.py", line 641, in run_until_complete
    self.run_forever()
  File "C:\Program Files\WindowsApps\PythonSoftwareFoundation.Python.3.11_3.11.2544.0_x64__qbz5n2kfra8p0\Lib\asyncio\windows_events.py", line 321, in run_forever
    super().run_forever()
  File "C:\Program Files\WindowsApps\PythonSoftwareFoundation.Python.3.11_3.11.2544.0_x64__qbz5n2kfra8p0\Lib\asyncio\base_events.py", line 608, in run_forever
    self._run_once()
  File "C:\Program Files\WindowsApps\PythonSoftwareFoundation.Python.3.11_3.11.2544.0_x64__qbz5n2kfra8p0\Lib\asyncio\base_events.py", line 1936, in _run_once
    handle._run()
  File "C:\Program Files\WindowsApps\PythonSoftwareFoundation.Python.3.11_3.11.2544.0_x64__qbz5n2kfra8p0\Lib\asyncio\events.py", line 84, in _run
    self._context.run(self._callback, *self._args)
  File "C:\Users\MSI\AppData\Local\Packages\PythonSoftwareFoundation.Python.3.11_qbz5n2kfra8p0\LocalCache\local-packages\Python311\site-packages\discord\client.py", line 449, in _run_event
    await coro(*args, **kwargs)
  File "d:\OF Bot\bot.py", line 52, in on_message
    await bot.process_commands(message)
  File "C:\Users\MSI\AppData\Local\Packages\PythonSoftwareFoundation.Python.3.11_qbz5n2kfra8p0\LocalCache\local-packages\Python311\site-packages\discord\ext\commands\bot.py", line 1408, in process_commands
    await self.invoke(ctx)  # type: ignore
  File "C:\Users\MSI\AppData\Local\Packages\PythonSoftwareFoundation.Python.3.11_qbz5n2kfra8p0\LocalCache\local-packages\Python311\site-packages\discord\ext\commands\bot.py", line 1366, in invoke
    await ctx.command.invoke(ctx)
  File "C:\Users\MSI\AppData\Local\Packages\PythonSoftwareFoundation.Python.3.11_qbz5n2kfra8p0\LocalCache\local-packages\Python311\site-packages\discord\ext\commands\core.py", line 1029, in invoke
    await injected(*ctx.args, **ctx.kwargs)  # type: ignore
  File "C:\Users\MSI\AppData\Local\Packages\PythonSoftwareFoundation.Python.3.11_qbz5n2kfra8p0\LocalCache\local-packages\Python311\site-packages\discord\ext\commands\core.py", line 235, in wrapped
    ret = await coro(*args, **kwargs)
  File "d:\OF Bot\bot.py", line 91, in upload
    result = client.predict(
  File "C:\Users\MSI\AppData\Local\Packages\PythonSoftwareFoundation.Python.3.11_qbz5n2kfra8p0\LocalCache\local-packages\Python311\site-packages\gradio_client\client.py", line 477, in predict
    ).result()
  File "C:\Users\MSI\AppData\Local\Packages\PythonSoftwareFoundation.Python.3.11_qbz5n2kfra8p0\LocalCache\local-packages\Python311\site-packages\gradio_client\client.py", line 1514, in result
    return super().result(timeout=timeout)
  File "C:\Program Files\WindowsApps\PythonSoftwareFoundation.Python.3.11_3.11.2544.0_x64__qbz5n2kfra8p0\Lib\concurrent\futures\_base.py", line 451, in result
    self._condition.wait(timeout)
  File "C:\Program Files\WindowsApps\PythonSoftwareFoundation.Python.3.11_3.11.2544.0_x64__qbz5n2kfra8p0\Lib\threading.py", line 327, in wait
    waiter.acquire()

2024-12-21 16:55:20,975 - WARNING - Shard ID None heartbeat blocked for more than 20 seconds.
Loop thread traceback (most recent call last):
  File "d:\OF Bot\bot.py", line 111, in <module>
    bot.run(config.BOT_TOKEN)  # Token is imported securely from the configuration file
  File "C:\Users\MSI\AppData\Local\Packages\PythonSoftwareFoundation.Python.3.11_qbz5n2kfra8p0\LocalCache\local-packages\Python311\site-packages\discord\client.py", line 869, in run
    asyncio.run(runner())
  File "C:\Program Files\WindowsApps\PythonSoftwareFoundation.Python.3.11_3.11.2544.0_x64__qbz5n2kfra8p0\Lib\asyncio\runners.py", line 190, in run
    return runner.run(main)
  File "C:\Program Files\WindowsApps\PythonSoftwareFoundation.Python.3.11_3.11.2544.0_x64__qbz5n2kfra8p0\Lib\asyncio\runners.py", line 118, in run
    return self._loop.run_until_complete(task)
  File "C:\Program Files\WindowsApps\PythonSoftwareFoundation.Python.3.11_3.11.2544.0_x64__qbz5n2kfra8p0\Lib\asyncio\base_events.py", line 641, in run_until_complete
    self.run_forever()
  File "C:\Program Files\WindowsApps\PythonSoftwareFoundation.Python.3.11_3.11.2544.0_x64__qbz5n2kfra8p0\Lib\asyncio\windows_events.py", line 321, in run_forever
    super().run_forever()
  File "C:\Program Files\WindowsApps\PythonSoftwareFoundation.Python.3.11_3.11.2544.0_x64__qbz5n2kfra8p0\Lib\asyncio\base_events.py", line 608, in run_forever
    self._run_once()
  File "C:\Program Files\WindowsApps\PythonSoftwareFoundation.Python.3.11_3.11.2544.0_x64__qbz5n2kfra8p0\Lib\asyncio\base_events.py", line 1936, in _run_once
    handle._run()
  File "C:\Program Files\WindowsApps\PythonSoftwareFoundation.Python.3.11_3.11.2544.0_x64__qbz5n2kfra8p0\Lib\asyncio\events.py", line 84, in _run
    self._context.run(self._callback, *self._args)
  File "C:\Users\MSI\AppData\Local\Packages\PythonSoftwareFoundation.Python.3.11_qbz5n2kfra8p0\LocalCache\local-packages\Python311\site-packages\discord\client.py", line 449, in _run_event
    await coro(*args, **kwargs)
  File "d:\OF Bot\bot.py", line 52, in on_message
    await bot.process_commands(message)
  File "C:\Users\MSI\AppData\Local\Packages\PythonSoftwareFoundation.Python.3.11_qbz5n2kfra8p0\LocalCache\local-packages\Python311\site-packages\discord\ext\commands\bot.py", line 1408, in process_commands
    await self.invoke(ctx)  # type: ignore
  File "C:\Users\MSI\AppData\Local\Packages\PythonSoftwareFoundation.Python.3.11_qbz5n2kfra8p0\LocalCache\local-packages\Python311\site-packages\discord\ext\commands\bot.py", line 1366, in invoke
    await ctx.command.invoke(ctx)
  File "C:\Users\MSI\AppData\Local\Packages\PythonSoftwareFoundation.Python.3.11_qbz5n2kfra8p0\LocalCache\local-packages\Python311\site-packages\discord\ext\commands\core.py", line 1029, in invoke
    await injected(*ctx.args, **ctx.kwargs)  # type: ignore
  File "C:\Users\MSI\AppData\Local\Packages\PythonSoftwareFoundation.Python.3.11_qbz5n2kfra8p0\LocalCache\local-packages\Python311\site-packages\discord\ext\commands\core.py", line 235, in wrapped
    ret = await coro(*args, **kwargs)
  File "d:\OF Bot\bot.py", line 91, in upload
    result = client.predict(
  File "C:\Users\MSI\AppData\Local\Packages\PythonSoftwareFoundation.Python.3.11_qbz5n2kfra8p0\LocalCache\local-packages\Python311\site-packages\gradio_client\client.py", line 477, in predict
    ).result()
  File "C:\Users\MSI\AppData\Local\Packages\PythonSoftwareFoundation.Python.3.11_qbz5n2kfra8p0\LocalCache\local-packages\Python311\site-packages\gradio_client\client.py", line 1514, in result
    return super().result(timeout=timeout)
  File "C:\Program Files\WindowsApps\PythonSoftwareFoundation.Python.3.11_3.11.2544.0_x64__qbz5n2kfra8p0\Lib\concurrent\futures\_base.py", line 451, in result
    self._condition.wait(timeout)
  File "C:\Program Files\WindowsApps\PythonSoftwareFoundation.Python.3.11_3.11.2544.0_x64__qbz5n2kfra8p0\Lib\threading.py", line 327, in wait
    waiter.acquire()

2024-12-21 16:55:30,981 - WARNING - Shard ID None heartbeat blocked for more than 30 seconds.
Loop thread traceback (most recent call last):
  File "d:\OF Bot\bot.py", line 111, in <module>
    bot.run(config.BOT_TOKEN)  # Token is imported securely from the configuration file
  File "C:\Users\MSI\AppData\Local\Packages\PythonSoftwareFoundation.Python.3.11_qbz5n2kfra8p0\LocalCache\local-packages\Python311\site-packages\discord\client.py", line 869, in run
    asyncio.run(runner())
  File "C:\Program Files\WindowsApps\PythonSoftwareFoundation.Python.3.11_3.11.2544.0_x64__qbz5n2kfra8p0\Lib\asyncio\runners.py", line 190, in run
    return runner.run(main)
  File "C:\Program Files\WindowsApps\PythonSoftwareFoundation.Python.3.11_3.11.2544.0_x64__qbz5n2kfra8p0\Lib\asyncio\runners.py", line 118, in run
    return self._loop.run_until_complete(task)
  File "C:\Program Files\WindowsApps\PythonSoftwareFoundation.Python.3.11_3.11.2544.0_x64__qbz5n2kfra8p0\Lib\asyncio\base_events.py", line 641, in run_until_complete
    self.run_forever()
  File "C:\Program Files\WindowsApps\PythonSoftwareFoundation.Python.3.11_3.11.2544.0_x64__qbz5n2kfra8p0\Lib\asyncio\windows_events.py", line 321, in run_forever
    super().run_forever()
  File "C:\Program Files\WindowsApps\PythonSoftwareFoundation.Python.3.11_3.11.2544.0_x64__qbz5n2kfra8p0\Lib\asyncio\base_events.py", line 608, in run_forever
    self._run_once()
  File "C:\Program Files\WindowsApps\PythonSoftwareFoundation.Python.3.11_3.11.2544.0_x64__qbz5n2kfra8p0\Lib\asyncio\base_events.py", line 1936, in _run_once
    handle._run()
  File "C:\Program Files\WindowsApps\PythonSoftwareFoundation.Python.3.11_3.11.2544.0_x64__qbz5n2kfra8p0\Lib\asyncio\events.py", line 84, in _run
    self._context.run(self._callback, *self._args)
  File "C:\Users\MSI\AppData\Local\Packages\PythonSoftwareFoundation.Python.3.11_qbz5n2kfra8p0\LocalCache\local-packages\Python311\site-packages\discord\client.py", line 449, in _run_event
    await coro(*args, **kwargs)
  File "d:\OF Bot\bot.py", line 52, in on_message
    await bot.process_commands(message)
  File "C:\Users\MSI\AppData\Local\Packages\PythonSoftwareFoundation.Python.3.11_qbz5n2kfra8p0\LocalCache\local-packages\Python311\site-packages\discord\ext\commands\bot.py", line 1408, in process_commands
    await self.invoke(ctx)  # type: ignore
  File "C:\Users\MSI\AppData\Local\Packages\PythonSoftwareFoundation.Python.3.11_qbz5n2kfra8p0\LocalCache\local-packages\Python311\site-packages\discord\ext\commands\bot.py", line 1366, in invoke
    await ctx.command.invoke(ctx)
  File "C:\Users\MSI\AppData\Local\Packages\PythonSoftwareFoundation.Python.3.11_qbz5n2kfra8p0\LocalCache\local-packages\Python311\site-packages\discord\ext\commands\core.py", line 1029, in invoke
    await injected(*ctx.args, **ctx.kwargs)  # type: ignore
  File "C:\Users\MSI\AppData\Local\Packages\PythonSoftwareFoundation.Python.3.11_qbz5n2kfra8p0\LocalCache\local-packages\Python311\site-packages\discord\ext\commands\core.py", line 235, in wrapped
    ret = await coro(*args, **kwargs)
  File "d:\OF Bot\bot.py", line 91, in upload
    result = client.predict(
  File "C:\Users\MSI\AppData\Local\Packages\PythonSoftwareFoundation.Python.3.11_qbz5n2kfra8p0\LocalCache\local-packages\Python311\site-packages\gradio_client\client.py", line 477, in predict
    ).result()
  File "C:\Users\MSI\AppData\Local\Packages\PythonSoftwareFoundation.Python.3.11_qbz5n2kfra8p0\LocalCache\local-packages\Python311\site-packages\gradio_client\client.py", line 1514, in result
    return super().result(timeout=timeout)
  File "C:\Program Files\WindowsApps\PythonSoftwareFoundation.Python.3.11_3.11.2544.0_x64__qbz5n2kfra8p0\Lib\concurrent\futures\_base.py", line 451, in result
    self._condition.wait(timeout)
  File "C:\Program Files\WindowsApps\PythonSoftwareFoundation.Python.3.11_3.11.2544.0_x64__qbz5n2kfra8p0\Lib\threading.py", line 327, in wait
    waiter.acquire()

2024-12-21 16:55:33,585 - ERROR - Error processing ?upload command: The read operation timed out
2024-12-21 16:55:34,091 - INFO - Shard ID None has successfully RESUMED session 5410cff8ad245e0ae785539c64a1f4a3.
2024-12-21 17:39:09,606 - INFO - Image saved temporarily to: temp_photo_22_2024-12-14_11-00-21.jpg
2024-12-21 17:39:09,610 - INFO - Overlay text: if this doesn't work i will offer my resignation papers by tonight at 9pm est please work
2024-12-21 17:39:09,611 - INFO - Payload being sent to API: {'image': {'path': 'temp_photo_22_2024-12-14_11-00-21.jpg', 'meta': {'_type': 'gradio.FileData'}, 'orig_name': 'temp_photo_22_2024-12-14_11-00-21.jpg'}, 'text': "if this doesn't work i will offer my resignation papers by tonight at 9pm est please work"}
2024-12-21 17:39:10,993 - INFO - HTTP Request: POST https://3morrrrr-of-verification-bot.hf.space/gradio_api/upload "HTTP/1.1 200 OK"
2024-12-21 17:39:11,838 - INFO - HTTP Request: POST https://3morrrrr-of-verification-bot.hf.space/gradio_api/queue/join "HTTP/1.1 200 OK"
2024-12-21 17:39:12,698 - INFO - HTTP Request: GET https://3morrrrr-of-verification-bot.hf.space/gradio_api/queue/data?session_hash=914a57b3-24aa-4277-bd6c-9858b2069e54 "HTTP/1.1 200 OK"
2024-12-21 17:39:15,695 - INFO - HTTP Request: GET https://3morrrrr-of-verification-bot.hf.space/gradio_api/file=/tmp/gradio/66ae815f3086ae50db399758b811687b11672a66e4c0d36160fe43de28ee8007/output_image.png "HTTP/1.1 200 OK"
2024-12-21 17:39:18,511 - INFO - HTTP Request: GET https://3morrrrr-of-verification-bot.hf.space/gradio_api/file=/tmp/gradio/66ae815f3086ae50db399758b811687b11672a66e4c0d36160fe43de28ee8007/output_image.png "HTTP/1.1 200 OK"
2024-12-21 17:39:21,197 - INFO - API Response: ('C:\\Users\\MSI\\AppData\\Local\\Temp\\gradio\\0d8ed7c130b5b013ca150848cc94716f2589af144fb422945e7e6b078f0a5029\\output_image.png', 'C:\\Users\\MSI\\AppData\\Local\\Temp\\gradio\\0d8ed7c130b5b013ca150848cc94716f2589af144fb422945e7e6b078f0a5029\\output_image.png', 'Processing complete! Download the image below.')
2024-12-21 17:59:45,565 - WARNING - PyNaCl is not installed, voice will NOT be supported
2024-12-21 17:59:47,196 - INFO - HTTP Request: GET https://3morrrrr-of-verification-bot.hf.space/config "HTTP/1.1 200 OK"
2024-12-21 17:59:48,051 - INFO - HTTP Request: GET https://3morrrrr-of-verification-bot.hf.space/gradio_api/info?serialize=False "HTTP/1.1 200 OK"
2024-12-21 17:59:48,051 - INFO - logging in using static token
2024-12-21 17:59:48,781 - INFO - HTTP Request: GET https://3morrrrr-of-verification-bot.hf.space/gradio_api/heartbeat/1570045a-5cdc-4c16-a477-b3343d5063f6 "HTTP/1.1 200 OK"
2024-12-21 17:59:49,382 - INFO - Shard ID None has connected to Gateway (Session ID: a6a7cac2ef680174522338de15ad7b6b).
2024-12-21 17:59:51,546 - INFO - Bot is online as OF verification#6016
2024-12-21 18:00:41,035 - INFO - Image saved temporarily to: temp_output_image.png
2024-12-21 18:00:44,491 - INFO - HTTP Request: POST https://3morrrrr-of-verification-bot.hf.space/gradio_api/upload "HTTP/1.1 200 OK"
2024-12-21 18:00:45,315 - INFO - HTTP Request: POST https://3morrrrr-of-verification-bot.hf.space/gradio_api/queue/join "HTTP/1.1 200 OK"
2024-12-21 18:00:46,225 - INFO - HTTP Request: GET https://3morrrrr-of-verification-bot.hf.space/gradio_api/queue/data?session_hash=1570045a-5cdc-4c16-a477-b3343d5063f6 "HTTP/1.1 200 OK"
2024-12-21 18:00:48,925 - INFO - HTTP Request: GET https://3morrrrr-of-verification-bot.hf.space/gradio_api/file=/tmp/gradio/86e799670676ddb2dc63e9aa8bd249a2bd7bc5959ea7dc8186f80016b687c12d/output_image.png "HTTP/1.1 200 OK"
2024-12-21 18:00:52,682 - INFO - HTTP Request: GET https://3morrrrr-of-verification-bot.hf.space/gradio_api/file=/tmp/gradio/86e799670676ddb2dc63e9aa8bd249a2bd7bc5959ea7dc8186f80016b687c12d/output_image.png "HTTP/1.1 200 OK"
2024-12-21 18:00:54,923 - INFO - API Response: ('C:\\Users\\MSI\\AppData\\Local\\Temp\\gradio\\0d8ed7c130b5b013ca150848cc94716f2589af144fb422945e7e6b078f0a5029\\output_image.png', 'C:\\Users\\MSI\\AppData\\Local\\Temp\\gradio\\0d8ed7c130b5b013ca150848cc94716f2589af144fb422945e7e6b078f0a5029\\output_image.png', 'Processing complete! Download the image below.')
2024-12-21 18:01:22,079 - INFO - Image saved temporarily to: temp_photo_8_2024-12-14_14-26-18.jpg
2024-12-21 18:01:23,409 - INFO - HTTP Request: POST https://3morrrrr-of-verification-bot.hf.space/gradio_api/upload "HTTP/1.1 200 OK"
2024-12-21 18:01:24,244 - INFO - HTTP Request: POST https://3morrrrr-of-verification-bot.hf.space/gradio_api/queue/join "HTTP/1.1 200 OK"
2024-12-21 18:01:25,078 - INFO - HTTP Request: GET https://3morrrrr-of-verification-bot.hf.space/gradio_api/queue/data?session_hash=1570045a-5cdc-4c16-a477-b3343d5063f6 "HTTP/1.1 200 OK"
2024-12-21 18:01:27,959 - INFO - HTTP Request: GET https://3morrrrr-of-verification-bot.hf.space/gradio_api/file=/tmp/gradio/b5fa88237963f67dd2e01ff95a4b01594f4fb97a4c042e75ace7ce8a4aa93d77/output_image.png "HTTP/1.1 200 OK"
2024-12-21 18:01:30,729 - INFO - HTTP Request: GET https://3morrrrr-of-verification-bot.hf.space/gradio_api/file=/tmp/gradio/b5fa88237963f67dd2e01ff95a4b01594f4fb97a4c042e75ace7ce8a4aa93d77/output_image.png "HTTP/1.1 200 OK"
2024-12-21 18:01:33,809 - INFO - API Response: ('C:\\Users\\MSI\\AppData\\Local\\Temp\\gradio\\c6ad76eb711446f7884029bfe4c8edbf7b4d58a6611414d6a2a72973cc09d9eb\\output_image.png', 'C:\\Users\\MSI\\AppData\\Local\\Temp\\gradio\\c6ad76eb711446f7884029bfe4c8edbf7b4d58a6611414d6a2a72973cc09d9eb\\output_image.png', 'Processing complete! Download the image below.')
2024-12-21 18:03:33,264 - WARNING - PyNaCl is not installed, voice will NOT be supported
2024-12-21 18:03:35,131 - INFO - HTTP Request: GET https://3morrrrr-of-verification-bot.hf.space/config "HTTP/1.1 200 OK"
2024-12-21 18:03:36,001 - INFO - HTTP Request: GET https://3morrrrr-of-verification-bot.hf.space/gradio_api/info?serialize=False "HTTP/1.1 200 OK"
2024-12-21 18:03:36,003 - INFO - logging in using static token
2024-12-21 18:03:36,974 - INFO - HTTP Request: GET https://3morrrrr-of-verification-bot.hf.space/gradio_api/heartbeat/3a817834-c3de-48bd-9e59-1793a270a5f2 "HTTP/1.1 200 OK"
2024-12-21 18:03:37,162 - INFO - Shard ID None has connected to Gateway (Session ID: d50446c53d2d1fb340c23cd3f53d147c).
2024-12-21 18:03:39,202 - INFO - Bot is online as OF verification#6016
2024-12-21 18:04:41,959 - INFO - Image saved temporarily to: temp_photo_8_2024-12-14_14-26-18.jpg
2024-12-21 18:04:43,465 - INFO - HTTP Request: POST https://3morrrrr-of-verification-bot.hf.space/gradio_api/upload "HTTP/1.1 200 OK"
2024-12-21 18:04:44,263 - INFO - HTTP Request: POST https://3morrrrr-of-verification-bot.hf.space/gradio_api/queue/join "HTTP/1.1 200 OK"
2024-12-21 18:04:45,110 - INFO - HTTP Request: GET https://3morrrrr-of-verification-bot.hf.space/gradio_api/queue/data?session_hash=3a817834-c3de-48bd-9e59-1793a270a5f2 "HTTP/1.1 200 OK"
2024-12-21 18:04:48,133 - INFO - HTTP Request: GET https://3morrrrr-of-verification-bot.hf.space/gradio_api/file=/tmp/gradio/b5fa88237963f67dd2e01ff95a4b01594f4fb97a4c042e75ace7ce8a4aa93d77/output_image.png "HTTP/1.1 200 OK"
2024-12-21 18:04:50,793 - INFO - HTTP Request: GET https://3morrrrr-of-verification-bot.hf.space/gradio_api/file=/tmp/gradio/b5fa88237963f67dd2e01ff95a4b01594f4fb97a4c042e75ace7ce8a4aa93d77/output_image.png "HTTP/1.1 200 OK"
2024-12-21 18:04:52,553 - INFO - API Response: ('C:\\Users\\MSI\\AppData\\Local\\Temp\\gradio\\c6ad76eb711446f7884029bfe4c8edbf7b4d58a6611414d6a2a72973cc09d9eb\\output_image.png', 'C:\\Users\\MSI\\AppData\\Local\\Temp\\gradio\\c6ad76eb711446f7884029bfe4c8edbf7b4d58a6611414d6a2a72973cc09d9eb\\output_image.png', 'Processing complete! Download the image below.')
2024-12-21 18:17:38,481 - INFO - Image saved temporarily to: temp_53e0ec8d-d636-48d1-9733-f913a1807679.jpg
2024-12-21 18:17:38,482 - INFO - Overlay text: rabi kbir w rahmtiu wes3a 29/06/2002
2024-12-21 18:17:38,482 - INFO - Payload being sent to API: {'image': {'path': 'temp_53e0ec8d-d636-48d1-9733-f913a1807679.jpg', 'meta': {'_type': 'gradio.FileData'}, 'orig_name': 'temp_53e0ec8d-d636-48d1-9733-f913a1807679.jpg'}, 'text': 'rabi kbir w rahmtiu wes3a 29/06/2002'}
2024-12-21 18:17:40,120 - INFO - HTTP Request: POST https://3morrrrr-of-verification-bot.hf.space/gradio_api/upload "HTTP/1.1 200 OK"
2024-12-21 18:17:40,887 - INFO - HTTP Request: POST https://3morrrrr-of-verification-bot.hf.space/gradio_api/queue/join "HTTP/1.1 200 OK"
2024-12-21 18:17:41,748 - INFO - HTTP Request: GET https://3morrrrr-of-verification-bot.hf.space/gradio_api/queue/data?session_hash=3a817834-c3de-48bd-9e59-1793a270a5f2 "HTTP/1.1 200 OK"
2024-12-21 18:17:50,036 - INFO - HTTP Request: GET https://3morrrrr-of-verification-bot.hf.space/gradio_api/file=/tmp/gradio/a5d8a55a897387dfe968e0654517eeead74556065e80ceb3042d0b0afe321a9b/output_image.png "HTTP/1.1 200 OK"
2024-12-21 18:17:58,820 - INFO - HTTP Request: GET https://3morrrrr-of-verification-bot.hf.space/gradio_api/file=/tmp/gradio/a5d8a55a897387dfe968e0654517eeead74556065e80ceb3042d0b0afe321a9b/output_image.png "HTTP/1.1 200 OK"
2024-12-21 18:18:08,327 - INFO - API Response: ('C:\\Users\\MSI\\AppData\\Local\\Temp\\gradio\\6160f3ce8c65e0922fb9ad15ebe56c33225121925f5435c9f6c56f3dbeebb9b7\\output_image.png', 'C:\\Users\\MSI\\AppData\\Local\\Temp\\gradio\\6160f3ce8c65e0922fb9ad15ebe56c33225121925f5435c9f6c56f3dbeebb9b7\\output_image.png', 'Processing complete! Download the image below.')
2024-12-21 18:25:52,598 - WARNING - Can't keep up, shard ID None websocket is 10.5s behind.
2024-12-21 18:30:59,478 - INFO - Image saved temporarily to: temp_53e0ec8d-d636-48d1-9733-f913a1807679.jpg
2024-12-21 18:30:59,483 - INFO - Overlay text: you might think I'm not real but sike you thought 
21/12/2024
2024-12-21 18:30:59,483 - INFO - Payload being sent to API: {'image': {'path': 'temp_53e0ec8d-d636-48d1-9733-f913a1807679.jpg', 'meta': {'_type': 'gradio.FileData'}, 'orig_name': 'temp_53e0ec8d-d636-48d1-9733-f913a1807679.jpg'}, 'text': "you might think I'm not real but sike you thought \n21/12/2024"}
2024-12-21 18:31:01,023 - INFO - HTTP Request: POST https://3morrrrr-of-verification-bot.hf.space/gradio_api/upload "HTTP/1.1 200 OK"
2024-12-21 18:31:01,735 - INFO - HTTP Request: POST https://3morrrrr-of-verification-bot.hf.space/gradio_api/queue/join "HTTP/1.1 200 OK"
2024-12-21 18:31:02,509 - INFO - HTTP Request: GET https://3morrrrr-of-verification-bot.hf.space/gradio_api/queue/data?session_hash=3a817834-c3de-48bd-9e59-1793a270a5f2 "HTTP/1.1 200 OK"
2024-12-21 18:31:10,367 - INFO - HTTP Request: GET https://3morrrrr-of-verification-bot.hf.space/gradio_api/file=/tmp/gradio/2295b2bc34cb919e7499b38ffd51ef6538e459c32ed55c81667ed627093e5b5d/output_image.png "HTTP/1.1 200 OK"
2024-12-21 18:31:16,004 - INFO - HTTP Request: GET https://3morrrrr-of-verification-bot.hf.space/gradio_api/file=/tmp/gradio/2295b2bc34cb919e7499b38ffd51ef6538e459c32ed55c81667ed627093e5b5d/output_image.png "HTTP/1.1 200 OK"
2024-12-21 18:31:22,227 - WARNING - Shard ID None heartbeat blocked for more than 10 seconds.
Loop thread traceback (most recent call last):
  File "d:\OF Bot\bot.py", line 132, in <module>
    bot.run(config.BOT_TOKEN)  # Token is imported securely from the configuration file
  File "C:\Users\MSI\AppData\Local\Packages\PythonSoftwareFoundation.Python.3.11_qbz5n2kfra8p0\LocalCache\local-packages\Python311\site-packages\discord\client.py", line 869, in run
    asyncio.run(runner())
  File "C:\Program Files\WindowsApps\PythonSoftwareFoundation.Python.3.11_3.11.2544.0_x64__qbz5n2kfra8p0\Lib\asyncio\runners.py", line 190, in run
    return runner.run(main)
  File "C:\Program Files\WindowsApps\PythonSoftwareFoundation.Python.3.11_3.11.2544.0_x64__qbz5n2kfra8p0\Lib\asyncio\runners.py", line 118, in run
    return self._loop.run_until_complete(task)
  File "C:\Program Files\WindowsApps\PythonSoftwareFoundation.Python.3.11_3.11.2544.0_x64__qbz5n2kfra8p0\Lib\asyncio\base_events.py", line 641, in run_until_complete
    self.run_forever()
  File "C:\Program Files\WindowsApps\PythonSoftwareFoundation.Python.3.11_3.11.2544.0_x64__qbz5n2kfra8p0\Lib\asyncio\windows_events.py", line 321, in run_forever
    super().run_forever()
  File "C:\Program Files\WindowsApps\PythonSoftwareFoundation.Python.3.11_3.11.2544.0_x64__qbz5n2kfra8p0\Lib\asyncio\base_events.py", line 608, in run_forever
    self._run_once()
  File "C:\Program Files\WindowsApps\PythonSoftwareFoundation.Python.3.11_3.11.2544.0_x64__qbz5n2kfra8p0\Lib\asyncio\base_events.py", line 1936, in _run_once
    handle._run()
  File "C:\Program Files\WindowsApps\PythonSoftwareFoundation.Python.3.11_3.11.2544.0_x64__qbz5n2kfra8p0\Lib\asyncio\events.py", line 84, in _run
    self._context.run(self._callback, *self._args)
  File "C:\Users\MSI\AppData\Local\Packages\PythonSoftwareFoundation.Python.3.11_qbz5n2kfra8p0\LocalCache\local-packages\Python311\site-packages\discord\client.py", line 449, in _run_event
    await coro(*args, **kwargs)
  File "d:\OF Bot\bot.py", line 57, in on_message
    await bot.process_commands(message)
  File "C:\Users\MSI\AppData\Local\Packages\PythonSoftwareFoundation.Python.3.11_qbz5n2kfra8p0\LocalCache\local-packages\Python311\site-packages\discord\ext\commands\bot.py", line 1408, in process_commands
    await self.invoke(ctx)  # type: ignore
  File "C:\Users\MSI\AppData\Local\Packages\PythonSoftwareFoundation.Python.3.11_qbz5n2kfra8p0\LocalCache\local-packages\Python311\site-packages\discord\ext\commands\bot.py", line 1366, in invoke
    await ctx.command.invoke(ctx)
  File "C:\Users\MSI\AppData\Local\Packages\PythonSoftwareFoundation.Python.3.11_qbz5n2kfra8p0\LocalCache\local-packages\Python311\site-packages\discord\ext\commands\core.py", line 1029, in invoke
    await injected(*ctx.args, **ctx.kwargs)  # type: ignore
  File "C:\Users\MSI\AppData\Local\Packages\PythonSoftwareFoundation.Python.3.11_qbz5n2kfra8p0\LocalCache\local-packages\Python311\site-packages\discord\ext\commands\core.py", line 235, in wrapped
    ret = await coro(*args, **kwargs)
  File "d:\OF Bot\bot.py", line 112, in upload
    result = client.predict(
  File "C:\Users\MSI\AppData\Local\Packages\PythonSoftwareFoundation.Python.3.11_qbz5n2kfra8p0\LocalCache\local-packages\Python311\site-packages\gradio_client\client.py", line 477, in predict
    ).result()
  File "C:\Users\MSI\AppData\Local\Packages\PythonSoftwareFoundation.Python.3.11_qbz5n2kfra8p0\LocalCache\local-packages\Python311\site-packages\gradio_client\client.py", line 1514, in result
    return super().result(timeout=timeout)
  File "C:\Program Files\WindowsApps\PythonSoftwareFoundation.Python.3.11_3.11.2544.0_x64__qbz5n2kfra8p0\Lib\concurrent\futures\_base.py", line 451, in result
    self._condition.wait(timeout)
  File "C:\Program Files\WindowsApps\PythonSoftwareFoundation.Python.3.11_3.11.2544.0_x64__qbz5n2kfra8p0\Lib\threading.py", line 327, in wait
    waiter.acquire()

2024-12-21 18:31:22,898 - INFO - API Response: ('C:\\Users\\MSI\\AppData\\Local\\Temp\\gradio\\d624a24d4cb3b040bb33f479d41a095b9f9b334f6bf02694af6686230a5e5dbf\\output_image.png', 'C:\\Users\\MSI\\AppData\\Local\\Temp\\gradio\\d624a24d4cb3b040bb33f479d41a095b9f9b334f6bf02694af6686230a5e5dbf\\output_image.png', 'Processing complete! Download the image below.')
2024-12-21 18:37:06,024 - WARNING - Can't keep up, shard ID None websocket is 13.1s behind.
2024-12-21 18:39:08,734 - WARNING - Can't keep up, shard ID None websocket is 53.3s behind.
2024-12-21 18:42:02,534 - ERROR - Attempting a reconnect in 0.17s
Traceback (most recent call last):
  File "C:\Users\MSI\AppData\Local\Packages\PythonSoftwareFoundation.Python.3.11_qbz5n2kfra8p0\LocalCache\local-packages\Python311\site-packages\aiohttp\connector.py", line 1345, in _create_direct_connection
    hosts = await self._resolve_host(host, port, traces=traces)
            ^^^^^^^^^^^^^^^^^^^^^^^^^^^^^^^^^^^^^^^^^^^^^^^^^^^
  File "C:\Users\MSI\AppData\Local\Packages\PythonSoftwareFoundation.Python.3.11_qbz5n2kfra8p0\LocalCache\local-packages\Python311\site-packages\aiohttp\connector.py", line 989, in _resolve_host
    return await asyncio.shield(resolved_host_task)
           ^^^^^^^^^^^^^^^^^^^^^^^^^^^^^^^^^^^^^^^^
  File "C:\Users\MSI\AppData\Local\Packages\PythonSoftwareFoundation.Python.3.11_qbz5n2kfra8p0\LocalCache\local-packages\Python311\site-packages\aiohttp\connector.py", line 1020, in _resolve_host_with_throttle
    addrs = await self._resolver.resolve(host, port, family=self._family)
            ^^^^^^^^^^^^^^^^^^^^^^^^^^^^^^^^^^^^^^^^^^^^^^^^^^^^^^^^^^^^^
  File "C:\Users\MSI\AppData\Local\Packages\PythonSoftwareFoundation.Python.3.11_qbz5n2kfra8p0\LocalCache\local-packages\Python311\site-packages\aiohttp\resolver.py", line 36, in resolve
    infos = await self._loop.getaddrinfo(
            ^^^^^^^^^^^^^^^^^^^^^^^^^^^^^
  File "C:\Program Files\WindowsApps\PythonSoftwareFoundation.Python.3.11_3.11.2544.0_x64__qbz5n2kfra8p0\Lib\asyncio\base_events.py", line 868, in getaddrinfo
    return await self.run_in_executor(
           ^^^^^^^^^^^^^^^^^^^^^^^^^^^
  File "C:\Program Files\WindowsApps\PythonSoftwareFoundation.Python.3.11_3.11.2544.0_x64__qbz5n2kfra8p0\Lib\concurrent\futures\thread.py", line 58, in run
    result = self.fn(*self.args, **self.kwargs)
             ^^^^^^^^^^^^^^^^^^^^^^^^^^^^^^^^^^
  File "C:\Program Files\WindowsApps\PythonSoftwareFoundation.Python.3.11_3.11.2544.0_x64__qbz5n2kfra8p0\Lib\socket.py", line 962, in getaddrinfo
    for res in _socket.getaddrinfo(host, port, family, type, proto, flags):
               ^^^^^^^^^^^^^^^^^^^^^^^^^^^^^^^^^^^^^^^^^^^^^^^^^^^^^^^^^^^
socket.gaierror: [Errno 11001] getaddrinfo failed

The above exception was the direct cause of the following exception:

Traceback (most recent call last):
  File "C:\Users\MSI\AppData\Local\Packages\PythonSoftwareFoundation.Python.3.11_qbz5n2kfra8p0\LocalCache\local-packages\Python311\site-packages\discord\client.py", line 664, in connect
    self.ws = await asyncio.wait_for(coro, timeout=60.0)
              ^^^^^^^^^^^^^^^^^^^^^^^^^^^^^^^^^^^^^^^^^^
  File "C:\Program Files\WindowsApps\PythonSoftwareFoundation.Python.3.11_3.11.2544.0_x64__qbz5n2kfra8p0\Lib\asyncio\tasks.py", line 489, in wait_for
    return fut.result()
           ^^^^^^^^^^^^
  File "C:\Users\MSI\AppData\Local\Packages\PythonSoftwareFoundation.Python.3.11_qbz5n2kfra8p0\LocalCache\local-packages\Python311\site-packages\discord\gateway.py", line 374, in from_client
    socket = await client.http.ws_connect(str(url))
             ^^^^^^^^^^^^^^^^^^^^^^^^^^^^^^^^^^^^^^
  File "C:\Users\MSI\AppData\Local\Packages\PythonSoftwareFoundation.Python.3.11_qbz5n2kfra8p0\LocalCache\local-packages\Python311\site-packages\discord\http.py", line 550, in ws_connect
    return await self.__session.ws_connect(url, **kwargs)
           ^^^^^^^^^^^^^^^^^^^^^^^^^^^^^^^^^^^^^^^^^^^^^^
  File "C:\Users\MSI\AppData\Local\Packages\PythonSoftwareFoundation.Python.3.11_qbz5n2kfra8p0\LocalCache\local-packages\Python311\site-packages\aiohttp\client.py", line 1002, in _ws_connect
    resp = await self.request(
           ^^^^^^^^^^^^^^^^^^^
  File "C:\Users\MSI\AppData\Local\Packages\PythonSoftwareFoundation.Python.3.11_qbz5n2kfra8p0\LocalCache\local-packages\Python311\site-packages\aiohttp\client.py", line 701, in _request
    conn = await self._connector.connect(
           ^^^^^^^^^^^^^^^^^^^^^^^^^^^^^^
  File "C:\Users\MSI\AppData\Local\Packages\PythonSoftwareFoundation.Python.3.11_qbz5n2kfra8p0\LocalCache\local-packages\Python311\site-packages\aiohttp\connector.py", line 544, in connect
    proto = await self._create_connection(req, traces, timeout)
            ^^^^^^^^^^^^^^^^^^^^^^^^^^^^^^^^^^^^^^^^^^^^^^^^^^^
  File "C:\Users\MSI\AppData\Local\Packages\PythonSoftwareFoundation.Python.3.11_qbz5n2kfra8p0\LocalCache\local-packages\Python311\site-packages\aiohttp\connector.py", line 1050, in _create_connection
    _, proto = await self._create_direct_connection(req, traces, timeout)
               ^^^^^^^^^^^^^^^^^^^^^^^^^^^^^^^^^^^^^^^^^^^^^^^^^^^^^^^^^^
  File "C:\Users\MSI\AppData\Local\Packages\PythonSoftwareFoundation.Python.3.11_qbz5n2kfra8p0\LocalCache\local-packages\Python311\site-packages\aiohttp\connector.py", line 1351, in _create_direct_connection
    raise ClientConnectorDNSError(req.connection_key, exc) from exc
aiohttp.client_exceptions.ClientConnectorDNSError: Cannot connect to host gateway-us-east1-d.discord.gg:443 ssl:default [getaddrinfo failed]
2024-12-21 18:42:03,011 - ERROR - Attempting a reconnect in 0.86s
Traceback (most recent call last):
  File "C:\Users\MSI\AppData\Local\Packages\PythonSoftwareFoundation.Python.3.11_qbz5n2kfra8p0\LocalCache\local-packages\Python311\site-packages\aiohttp\connector.py", line 1345, in _create_direct_connection
    hosts = await self._resolve_host(host, port, traces=traces)
            ^^^^^^^^^^^^^^^^^^^^^^^^^^^^^^^^^^^^^^^^^^^^^^^^^^^
  File "C:\Users\MSI\AppData\Local\Packages\PythonSoftwareFoundation.Python.3.11_qbz5n2kfra8p0\LocalCache\local-packages\Python311\site-packages\aiohttp\connector.py", line 989, in _resolve_host
    return await asyncio.shield(resolved_host_task)
           ^^^^^^^^^^^^^^^^^^^^^^^^^^^^^^^^^^^^^^^^
  File "C:\Users\MSI\AppData\Local\Packages\PythonSoftwareFoundation.Python.3.11_qbz5n2kfra8p0\LocalCache\local-packages\Python311\site-packages\aiohttp\connector.py", line 1020, in _resolve_host_with_throttle
    addrs = await self._resolver.resolve(host, port, family=self._family)
            ^^^^^^^^^^^^^^^^^^^^^^^^^^^^^^^^^^^^^^^^^^^^^^^^^^^^^^^^^^^^^
  File "C:\Users\MSI\AppData\Local\Packages\PythonSoftwareFoundation.Python.3.11_qbz5n2kfra8p0\LocalCache\local-packages\Python311\site-packages\aiohttp\resolver.py", line 36, in resolve
    infos = await self._loop.getaddrinfo(
            ^^^^^^^^^^^^^^^^^^^^^^^^^^^^^
  File "C:\Program Files\WindowsApps\PythonSoftwareFoundation.Python.3.11_3.11.2544.0_x64__qbz5n2kfra8p0\Lib\asyncio\base_events.py", line 868, in getaddrinfo
    return await self.run_in_executor(
           ^^^^^^^^^^^^^^^^^^^^^^^^^^^
  File "C:\Program Files\WindowsApps\PythonSoftwareFoundation.Python.3.11_3.11.2544.0_x64__qbz5n2kfra8p0\Lib\concurrent\futures\thread.py", line 58, in run
    result = self.fn(*self.args, **self.kwargs)
             ^^^^^^^^^^^^^^^^^^^^^^^^^^^^^^^^^^
  File "C:\Program Files\WindowsApps\PythonSoftwareFoundation.Python.3.11_3.11.2544.0_x64__qbz5n2kfra8p0\Lib\socket.py", line 962, in getaddrinfo
    for res in _socket.getaddrinfo(host, port, family, type, proto, flags):
               ^^^^^^^^^^^^^^^^^^^^^^^^^^^^^^^^^^^^^^^^^^^^^^^^^^^^^^^^^^^
socket.gaierror: [Errno 11001] getaddrinfo failed

The above exception was the direct cause of the following exception:

Traceback (most recent call last):
  File "C:\Users\MSI\AppData\Local\Packages\PythonSoftwareFoundation.Python.3.11_qbz5n2kfra8p0\LocalCache\local-packages\Python311\site-packages\discord\client.py", line 664, in connect
    self.ws = await asyncio.wait_for(coro, timeout=60.0)
              ^^^^^^^^^^^^^^^^^^^^^^^^^^^^^^^^^^^^^^^^^^
  File "C:\Program Files\WindowsApps\PythonSoftwareFoundation.Python.3.11_3.11.2544.0_x64__qbz5n2kfra8p0\Lib\asyncio\tasks.py", line 489, in wait_for
    return fut.result()
           ^^^^^^^^^^^^
  File "C:\Users\MSI\AppData\Local\Packages\PythonSoftwareFoundation.Python.3.11_qbz5n2kfra8p0\LocalCache\local-packages\Python311\site-packages\discord\gateway.py", line 374, in from_client
    socket = await client.http.ws_connect(str(url))
             ^^^^^^^^^^^^^^^^^^^^^^^^^^^^^^^^^^^^^^
  File "C:\Users\MSI\AppData\Local\Packages\PythonSoftwareFoundation.Python.3.11_qbz5n2kfra8p0\LocalCache\local-packages\Python311\site-packages\discord\http.py", line 550, in ws_connect
    return await self.__session.ws_connect(url, **kwargs)
           ^^^^^^^^^^^^^^^^^^^^^^^^^^^^^^^^^^^^^^^^^^^^^^
  File "C:\Users\MSI\AppData\Local\Packages\PythonSoftwareFoundation.Python.3.11_qbz5n2kfra8p0\LocalCache\local-packages\Python311\site-packages\aiohttp\client.py", line 1002, in _ws_connect
    resp = await self.request(
           ^^^^^^^^^^^^^^^^^^^
  File "C:\Users\MSI\AppData\Local\Packages\PythonSoftwareFoundation.Python.3.11_qbz5n2kfra8p0\LocalCache\local-packages\Python311\site-packages\aiohttp\client.py", line 701, in _request
    conn = await self._connector.connect(
           ^^^^^^^^^^^^^^^^^^^^^^^^^^^^^^
  File "C:\Users\MSI\AppData\Local\Packages\PythonSoftwareFoundation.Python.3.11_qbz5n2kfra8p0\LocalCache\local-packages\Python311\site-packages\aiohttp\connector.py", line 544, in connect
    proto = await self._create_connection(req, traces, timeout)
            ^^^^^^^^^^^^^^^^^^^^^^^^^^^^^^^^^^^^^^^^^^^^^^^^^^^
  File "C:\Users\MSI\AppData\Local\Packages\PythonSoftwareFoundation.Python.3.11_qbz5n2kfra8p0\LocalCache\local-packages\Python311\site-packages\aiohttp\connector.py", line 1050, in _create_connection
    _, proto = await self._create_direct_connection(req, traces, timeout)
               ^^^^^^^^^^^^^^^^^^^^^^^^^^^^^^^^^^^^^^^^^^^^^^^^^^^^^^^^^^
  File "C:\Users\MSI\AppData\Local\Packages\PythonSoftwareFoundation.Python.3.11_qbz5n2kfra8p0\LocalCache\local-packages\Python311\site-packages\aiohttp\connector.py", line 1351, in _create_direct_connection
    raise ClientConnectorDNSError(req.connection_key, exc) from exc
aiohttp.client_exceptions.ClientConnectorDNSError: Cannot connect to host gateway-us-east1-d.discord.gg:443 ssl:default [getaddrinfo failed]
2024-12-21 18:42:03,894 - ERROR - Attempting a reconnect in 7.17s
Traceback (most recent call last):
  File "C:\Users\MSI\AppData\Local\Packages\PythonSoftwareFoundation.Python.3.11_qbz5n2kfra8p0\LocalCache\local-packages\Python311\site-packages\aiohttp\connector.py", line 1345, in _create_direct_connection
    hosts = await self._resolve_host(host, port, traces=traces)
            ^^^^^^^^^^^^^^^^^^^^^^^^^^^^^^^^^^^^^^^^^^^^^^^^^^^
  File "C:\Users\MSI\AppData\Local\Packages\PythonSoftwareFoundation.Python.3.11_qbz5n2kfra8p0\LocalCache\local-packages\Python311\site-packages\aiohttp\connector.py", line 989, in _resolve_host
    return await asyncio.shield(resolved_host_task)
           ^^^^^^^^^^^^^^^^^^^^^^^^^^^^^^^^^^^^^^^^
  File "C:\Users\MSI\AppData\Local\Packages\PythonSoftwareFoundation.Python.3.11_qbz5n2kfra8p0\LocalCache\local-packages\Python311\site-packages\aiohttp\connector.py", line 1020, in _resolve_host_with_throttle
    addrs = await self._resolver.resolve(host, port, family=self._family)
            ^^^^^^^^^^^^^^^^^^^^^^^^^^^^^^^^^^^^^^^^^^^^^^^^^^^^^^^^^^^^^
  File "C:\Users\MSI\AppData\Local\Packages\PythonSoftwareFoundation.Python.3.11_qbz5n2kfra8p0\LocalCache\local-packages\Python311\site-packages\aiohttp\resolver.py", line 36, in resolve
    infos = await self._loop.getaddrinfo(
            ^^^^^^^^^^^^^^^^^^^^^^^^^^^^^
  File "C:\Program Files\WindowsApps\PythonSoftwareFoundation.Python.3.11_3.11.2544.0_x64__qbz5n2kfra8p0\Lib\asyncio\base_events.py", line 868, in getaddrinfo
    return await self.run_in_executor(
           ^^^^^^^^^^^^^^^^^^^^^^^^^^^
  File "C:\Program Files\WindowsApps\PythonSoftwareFoundation.Python.3.11_3.11.2544.0_x64__qbz5n2kfra8p0\Lib\concurrent\futures\thread.py", line 58, in run
    result = self.fn(*self.args, **self.kwargs)
             ^^^^^^^^^^^^^^^^^^^^^^^^^^^^^^^^^^
  File "C:\Program Files\WindowsApps\PythonSoftwareFoundation.Python.3.11_3.11.2544.0_x64__qbz5n2kfra8p0\Lib\socket.py", line 962, in getaddrinfo
    for res in _socket.getaddrinfo(host, port, family, type, proto, flags):
               ^^^^^^^^^^^^^^^^^^^^^^^^^^^^^^^^^^^^^^^^^^^^^^^^^^^^^^^^^^^
socket.gaierror: [Errno 11001] getaddrinfo failed

The above exception was the direct cause of the following exception:

Traceback (most recent call last):
  File "C:\Users\MSI\AppData\Local\Packages\PythonSoftwareFoundation.Python.3.11_qbz5n2kfra8p0\LocalCache\local-packages\Python311\site-packages\discord\client.py", line 664, in connect
    self.ws = await asyncio.wait_for(coro, timeout=60.0)
              ^^^^^^^^^^^^^^^^^^^^^^^^^^^^^^^^^^^^^^^^^^
  File "C:\Program Files\WindowsApps\PythonSoftwareFoundation.Python.3.11_3.11.2544.0_x64__qbz5n2kfra8p0\Lib\asyncio\tasks.py", line 489, in wait_for
    return fut.result()
           ^^^^^^^^^^^^
  File "C:\Users\MSI\AppData\Local\Packages\PythonSoftwareFoundation.Python.3.11_qbz5n2kfra8p0\LocalCache\local-packages\Python311\site-packages\discord\gateway.py", line 374, in from_client
    socket = await client.http.ws_connect(str(url))
             ^^^^^^^^^^^^^^^^^^^^^^^^^^^^^^^^^^^^^^
  File "C:\Users\MSI\AppData\Local\Packages\PythonSoftwareFoundation.Python.3.11_qbz5n2kfra8p0\LocalCache\local-packages\Python311\site-packages\discord\http.py", line 550, in ws_connect
    return await self.__session.ws_connect(url, **kwargs)
           ^^^^^^^^^^^^^^^^^^^^^^^^^^^^^^^^^^^^^^^^^^^^^^
  File "C:\Users\MSI\AppData\Local\Packages\PythonSoftwareFoundation.Python.3.11_qbz5n2kfra8p0\LocalCache\local-packages\Python311\site-packages\aiohttp\client.py", line 1002, in _ws_connect
    resp = await self.request(
           ^^^^^^^^^^^^^^^^^^^
  File "C:\Users\MSI\AppData\Local\Packages\PythonSoftwareFoundation.Python.3.11_qbz5n2kfra8p0\LocalCache\local-packages\Python311\site-packages\aiohttp\client.py", line 701, in _request
    conn = await self._connector.connect(
           ^^^^^^^^^^^^^^^^^^^^^^^^^^^^^^
  File "C:\Users\MSI\AppData\Local\Packages\PythonSoftwareFoundation.Python.3.11_qbz5n2kfra8p0\LocalCache\local-packages\Python311\site-packages\aiohttp\connector.py", line 544, in connect
    proto = await self._create_connection(req, traces, timeout)
            ^^^^^^^^^^^^^^^^^^^^^^^^^^^^^^^^^^^^^^^^^^^^^^^^^^^
  File "C:\Users\MSI\AppData\Local\Packages\PythonSoftwareFoundation.Python.3.11_qbz5n2kfra8p0\LocalCache\local-packages\Python311\site-packages\aiohttp\connector.py", line 1050, in _create_connection
    _, proto = await self._create_direct_connection(req, traces, timeout)
               ^^^^^^^^^^^^^^^^^^^^^^^^^^^^^^^^^^^^^^^^^^^^^^^^^^^^^^^^^^
  File "C:\Users\MSI\AppData\Local\Packages\PythonSoftwareFoundation.Python.3.11_qbz5n2kfra8p0\LocalCache\local-packages\Python311\site-packages\aiohttp\connector.py", line 1351, in _create_direct_connection
    raise ClientConnectorDNSError(req.connection_key, exc) from exc
aiohttp.client_exceptions.ClientConnectorDNSError: Cannot connect to host gateway-us-east1-d.discord.gg:443 ssl:default [getaddrinfo failed]
2024-12-21 18:42:11,075 - ERROR - Attempting a reconnect in 15.67s
Traceback (most recent call last):
  File "C:\Users\MSI\AppData\Local\Packages\PythonSoftwareFoundation.Python.3.11_qbz5n2kfra8p0\LocalCache\local-packages\Python311\site-packages\aiohttp\connector.py", line 1345, in _create_direct_connection
    hosts = await self._resolve_host(host, port, traces=traces)
            ^^^^^^^^^^^^^^^^^^^^^^^^^^^^^^^^^^^^^^^^^^^^^^^^^^^
  File "C:\Users\MSI\AppData\Local\Packages\PythonSoftwareFoundation.Python.3.11_qbz5n2kfra8p0\LocalCache\local-packages\Python311\site-packages\aiohttp\connector.py", line 989, in _resolve_host
    return await asyncio.shield(resolved_host_task)
           ^^^^^^^^^^^^^^^^^^^^^^^^^^^^^^^^^^^^^^^^
  File "C:\Users\MSI\AppData\Local\Packages\PythonSoftwareFoundation.Python.3.11_qbz5n2kfra8p0\LocalCache\local-packages\Python311\site-packages\aiohttp\connector.py", line 1020, in _resolve_host_with_throttle
    addrs = await self._resolver.resolve(host, port, family=self._family)
            ^^^^^^^^^^^^^^^^^^^^^^^^^^^^^^^^^^^^^^^^^^^^^^^^^^^^^^^^^^^^^
  File "C:\Users\MSI\AppData\Local\Packages\PythonSoftwareFoundation.Python.3.11_qbz5n2kfra8p0\LocalCache\local-packages\Python311\site-packages\aiohttp\resolver.py", line 36, in resolve
    infos = await self._loop.getaddrinfo(
            ^^^^^^^^^^^^^^^^^^^^^^^^^^^^^
  File "C:\Program Files\WindowsApps\PythonSoftwareFoundation.Python.3.11_3.11.2544.0_x64__qbz5n2kfra8p0\Lib\asyncio\base_events.py", line 868, in getaddrinfo
    return await self.run_in_executor(
           ^^^^^^^^^^^^^^^^^^^^^^^^^^^
  File "C:\Program Files\WindowsApps\PythonSoftwareFoundation.Python.3.11_3.11.2544.0_x64__qbz5n2kfra8p0\Lib\concurrent\futures\thread.py", line 58, in run
    result = self.fn(*self.args, **self.kwargs)
             ^^^^^^^^^^^^^^^^^^^^^^^^^^^^^^^^^^
  File "C:\Program Files\WindowsApps\PythonSoftwareFoundation.Python.3.11_3.11.2544.0_x64__qbz5n2kfra8p0\Lib\socket.py", line 962, in getaddrinfo
    for res in _socket.getaddrinfo(host, port, family, type, proto, flags):
               ^^^^^^^^^^^^^^^^^^^^^^^^^^^^^^^^^^^^^^^^^^^^^^^^^^^^^^^^^^^
socket.gaierror: [Errno 11001] getaddrinfo failed

The above exception was the direct cause of the following exception:

Traceback (most recent call last):
  File "C:\Users\MSI\AppData\Local\Packages\PythonSoftwareFoundation.Python.3.11_qbz5n2kfra8p0\LocalCache\local-packages\Python311\site-packages\discord\client.py", line 664, in connect
    self.ws = await asyncio.wait_for(coro, timeout=60.0)
              ^^^^^^^^^^^^^^^^^^^^^^^^^^^^^^^^^^^^^^^^^^
  File "C:\Program Files\WindowsApps\PythonSoftwareFoundation.Python.3.11_3.11.2544.0_x64__qbz5n2kfra8p0\Lib\asyncio\tasks.py", line 489, in wait_for
    return fut.result()
           ^^^^^^^^^^^^
  File "C:\Users\MSI\AppData\Local\Packages\PythonSoftwareFoundation.Python.3.11_qbz5n2kfra8p0\LocalCache\local-packages\Python311\site-packages\discord\gateway.py", line 374, in from_client
    socket = await client.http.ws_connect(str(url))
             ^^^^^^^^^^^^^^^^^^^^^^^^^^^^^^^^^^^^^^
  File "C:\Users\MSI\AppData\Local\Packages\PythonSoftwareFoundation.Python.3.11_qbz5n2kfra8p0\LocalCache\local-packages\Python311\site-packages\discord\http.py", line 550, in ws_connect
    return await self.__session.ws_connect(url, **kwargs)
           ^^^^^^^^^^^^^^^^^^^^^^^^^^^^^^^^^^^^^^^^^^^^^^
  File "C:\Users\MSI\AppData\Local\Packages\PythonSoftwareFoundation.Python.3.11_qbz5n2kfra8p0\LocalCache\local-packages\Python311\site-packages\aiohttp\client.py", line 1002, in _ws_connect
    resp = await self.request(
           ^^^^^^^^^^^^^^^^^^^
  File "C:\Users\MSI\AppData\Local\Packages\PythonSoftwareFoundation.Python.3.11_qbz5n2kfra8p0\LocalCache\local-packages\Python311\site-packages\aiohttp\client.py", line 701, in _request
    conn = await self._connector.connect(
           ^^^^^^^^^^^^^^^^^^^^^^^^^^^^^^
  File "C:\Users\MSI\AppData\Local\Packages\PythonSoftwareFoundation.Python.3.11_qbz5n2kfra8p0\LocalCache\local-packages\Python311\site-packages\aiohttp\connector.py", line 544, in connect
    proto = await self._create_connection(req, traces, timeout)
            ^^^^^^^^^^^^^^^^^^^^^^^^^^^^^^^^^^^^^^^^^^^^^^^^^^^
  File "C:\Users\MSI\AppData\Local\Packages\PythonSoftwareFoundation.Python.3.11_qbz5n2kfra8p0\LocalCache\local-packages\Python311\site-packages\aiohttp\connector.py", line 1050, in _create_connection
    _, proto = await self._create_direct_connection(req, traces, timeout)
               ^^^^^^^^^^^^^^^^^^^^^^^^^^^^^^^^^^^^^^^^^^^^^^^^^^^^^^^^^^
  File "C:\Users\MSI\AppData\Local\Packages\PythonSoftwareFoundation.Python.3.11_qbz5n2kfra8p0\LocalCache\local-packages\Python311\site-packages\aiohttp\connector.py", line 1351, in _create_direct_connection
    raise ClientConnectorDNSError(req.connection_key, exc) from exc
aiohttp.client_exceptions.ClientConnectorDNSError: Cannot connect to host gateway-us-east1-d.discord.gg:443 ssl:default [getaddrinfo failed]
2024-12-22 11:02:22,255 - INFO - Shard ID None session has been invalidated.
2024-12-22 11:02:28,085 - INFO - Shard ID None has connected to Gateway (Session ID: 16f89ee0210ea1cc05d5757355fae5a3).
2024-12-22 11:02:30,118 - INFO - Bot is online as OF verification#6016
2024-12-22 11:31:56,008 - ERROR - Attempting a reconnect in 0.08s
Traceback (most recent call last):
  File "C:\Users\MSI\AppData\Local\Packages\PythonSoftwareFoundation.Python.3.11_qbz5n2kfra8p0\LocalCache\local-packages\Python311\site-packages\aiohttp\connector.py", line 1345, in _create_direct_connection
    hosts = await self._resolve_host(host, port, traces=traces)
            ^^^^^^^^^^^^^^^^^^^^^^^^^^^^^^^^^^^^^^^^^^^^^^^^^^^
  File "C:\Users\MSI\AppData\Local\Packages\PythonSoftwareFoundation.Python.3.11_qbz5n2kfra8p0\LocalCache\local-packages\Python311\site-packages\aiohttp\connector.py", line 989, in _resolve_host
    return await asyncio.shield(resolved_host_task)
           ^^^^^^^^^^^^^^^^^^^^^^^^^^^^^^^^^^^^^^^^
  File "C:\Users\MSI\AppData\Local\Packages\PythonSoftwareFoundation.Python.3.11_qbz5n2kfra8p0\LocalCache\local-packages\Python311\site-packages\aiohttp\connector.py", line 1020, in _resolve_host_with_throttle
    addrs = await self._resolver.resolve(host, port, family=self._family)
            ^^^^^^^^^^^^^^^^^^^^^^^^^^^^^^^^^^^^^^^^^^^^^^^^^^^^^^^^^^^^^
  File "C:\Users\MSI\AppData\Local\Packages\PythonSoftwareFoundation.Python.3.11_qbz5n2kfra8p0\LocalCache\local-packages\Python311\site-packages\aiohttp\resolver.py", line 36, in resolve
    infos = await self._loop.getaddrinfo(
            ^^^^^^^^^^^^^^^^^^^^^^^^^^^^^
  File "C:\Program Files\WindowsApps\PythonSoftwareFoundation.Python.3.11_3.11.2544.0_x64__qbz5n2kfra8p0\Lib\asyncio\base_events.py", line 868, in getaddrinfo
    return await self.run_in_executor(
           ^^^^^^^^^^^^^^^^^^^^^^^^^^^
  File "C:\Program Files\WindowsApps\PythonSoftwareFoundation.Python.3.11_3.11.2544.0_x64__qbz5n2kfra8p0\Lib\concurrent\futures\thread.py", line 58, in run
    result = self.fn(*self.args, **self.kwargs)
             ^^^^^^^^^^^^^^^^^^^^^^^^^^^^^^^^^^
  File "C:\Program Files\WindowsApps\PythonSoftwareFoundation.Python.3.11_3.11.2544.0_x64__qbz5n2kfra8p0\Lib\socket.py", line 962, in getaddrinfo
    for res in _socket.getaddrinfo(host, port, family, type, proto, flags):
               ^^^^^^^^^^^^^^^^^^^^^^^^^^^^^^^^^^^^^^^^^^^^^^^^^^^^^^^^^^^
socket.gaierror: [Errno 11001] getaddrinfo failed

The above exception was the direct cause of the following exception:

Traceback (most recent call last):
  File "C:\Users\MSI\AppData\Local\Packages\PythonSoftwareFoundation.Python.3.11_qbz5n2kfra8p0\LocalCache\local-packages\Python311\site-packages\discord\client.py", line 664, in connect
    self.ws = await asyncio.wait_for(coro, timeout=60.0)
              ^^^^^^^^^^^^^^^^^^^^^^^^^^^^^^^^^^^^^^^^^^
  File "C:\Program Files\WindowsApps\PythonSoftwareFoundation.Python.3.11_3.11.2544.0_x64__qbz5n2kfra8p0\Lib\asyncio\tasks.py", line 489, in wait_for
    return fut.result()
           ^^^^^^^^^^^^
  File "C:\Users\MSI\AppData\Local\Packages\PythonSoftwareFoundation.Python.3.11_qbz5n2kfra8p0\LocalCache\local-packages\Python311\site-packages\discord\gateway.py", line 374, in from_client
    socket = await client.http.ws_connect(str(url))
             ^^^^^^^^^^^^^^^^^^^^^^^^^^^^^^^^^^^^^^
  File "C:\Users\MSI\AppData\Local\Packages\PythonSoftwareFoundation.Python.3.11_qbz5n2kfra8p0\LocalCache\local-packages\Python311\site-packages\discord\http.py", line 550, in ws_connect
    return await self.__session.ws_connect(url, **kwargs)
           ^^^^^^^^^^^^^^^^^^^^^^^^^^^^^^^^^^^^^^^^^^^^^^
  File "C:\Users\MSI\AppData\Local\Packages\PythonSoftwareFoundation.Python.3.11_qbz5n2kfra8p0\LocalCache\local-packages\Python311\site-packages\aiohttp\client.py", line 1002, in _ws_connect
    resp = await self.request(
           ^^^^^^^^^^^^^^^^^^^
  File "C:\Users\MSI\AppData\Local\Packages\PythonSoftwareFoundation.Python.3.11_qbz5n2kfra8p0\LocalCache\local-packages\Python311\site-packages\aiohttp\client.py", line 701, in _request
    conn = await self._connector.connect(
           ^^^^^^^^^^^^^^^^^^^^^^^^^^^^^^
  File "C:\Users\MSI\AppData\Local\Packages\PythonSoftwareFoundation.Python.3.11_qbz5n2kfra8p0\LocalCache\local-packages\Python311\site-packages\aiohttp\connector.py", line 544, in connect
    proto = await self._create_connection(req, traces, timeout)
            ^^^^^^^^^^^^^^^^^^^^^^^^^^^^^^^^^^^^^^^^^^^^^^^^^^^
  File "C:\Users\MSI\AppData\Local\Packages\PythonSoftwareFoundation.Python.3.11_qbz5n2kfra8p0\LocalCache\local-packages\Python311\site-packages\aiohttp\connector.py", line 1050, in _create_connection
    _, proto = await self._create_direct_connection(req, traces, timeout)
               ^^^^^^^^^^^^^^^^^^^^^^^^^^^^^^^^^^^^^^^^^^^^^^^^^^^^^^^^^^
  File "C:\Users\MSI\AppData\Local\Packages\PythonSoftwareFoundation.Python.3.11_qbz5n2kfra8p0\LocalCache\local-packages\Python311\site-packages\aiohttp\connector.py", line 1351, in _create_direct_connection
    raise ClientConnectorDNSError(req.connection_key, exc) from exc
aiohttp.client_exceptions.ClientConnectorDNSError: Cannot connect to host gateway-us-east1-d.discord.gg:443 ssl:default [getaddrinfo failed]
2024-12-22 11:31:56,147 - ERROR - Attempting a reconnect in 2.27s
Traceback (most recent call last):
  File "C:\Users\MSI\AppData\Local\Packages\PythonSoftwareFoundation.Python.3.11_qbz5n2kfra8p0\LocalCache\local-packages\Python311\site-packages\aiohttp\connector.py", line 1345, in _create_direct_connection
    hosts = await self._resolve_host(host, port, traces=traces)
            ^^^^^^^^^^^^^^^^^^^^^^^^^^^^^^^^^^^^^^^^^^^^^^^^^^^
  File "C:\Users\MSI\AppData\Local\Packages\PythonSoftwareFoundation.Python.3.11_qbz5n2kfra8p0\LocalCache\local-packages\Python311\site-packages\aiohttp\connector.py", line 989, in _resolve_host
    return await asyncio.shield(resolved_host_task)
           ^^^^^^^^^^^^^^^^^^^^^^^^^^^^^^^^^^^^^^^^
  File "C:\Users\MSI\AppData\Local\Packages\PythonSoftwareFoundation.Python.3.11_qbz5n2kfra8p0\LocalCache\local-packages\Python311\site-packages\aiohttp\connector.py", line 1020, in _resolve_host_with_throttle
    addrs = await self._resolver.resolve(host, port, family=self._family)
            ^^^^^^^^^^^^^^^^^^^^^^^^^^^^^^^^^^^^^^^^^^^^^^^^^^^^^^^^^^^^^
  File "C:\Users\MSI\AppData\Local\Packages\PythonSoftwareFoundation.Python.3.11_qbz5n2kfra8p0\LocalCache\local-packages\Python311\site-packages\aiohttp\resolver.py", line 36, in resolve
    infos = await self._loop.getaddrinfo(
            ^^^^^^^^^^^^^^^^^^^^^^^^^^^^^
  File "C:\Program Files\WindowsApps\PythonSoftwareFoundation.Python.3.11_3.11.2544.0_x64__qbz5n2kfra8p0\Lib\asyncio\base_events.py", line 868, in getaddrinfo
    return await self.run_in_executor(
           ^^^^^^^^^^^^^^^^^^^^^^^^^^^
  File "C:\Program Files\WindowsApps\PythonSoftwareFoundation.Python.3.11_3.11.2544.0_x64__qbz5n2kfra8p0\Lib\concurrent\futures\thread.py", line 58, in run
    result = self.fn(*self.args, **self.kwargs)
             ^^^^^^^^^^^^^^^^^^^^^^^^^^^^^^^^^^
  File "C:\Program Files\WindowsApps\PythonSoftwareFoundation.Python.3.11_3.11.2544.0_x64__qbz5n2kfra8p0\Lib\socket.py", line 962, in getaddrinfo
    for res in _socket.getaddrinfo(host, port, family, type, proto, flags):
               ^^^^^^^^^^^^^^^^^^^^^^^^^^^^^^^^^^^^^^^^^^^^^^^^^^^^^^^^^^^
socket.gaierror: [Errno 11001] getaddrinfo failed

The above exception was the direct cause of the following exception:

Traceback (most recent call last):
  File "C:\Users\MSI\AppData\Local\Packages\PythonSoftwareFoundation.Python.3.11_qbz5n2kfra8p0\LocalCache\local-packages\Python311\site-packages\discord\client.py", line 664, in connect
    self.ws = await asyncio.wait_for(coro, timeout=60.0)
              ^^^^^^^^^^^^^^^^^^^^^^^^^^^^^^^^^^^^^^^^^^
  File "C:\Program Files\WindowsApps\PythonSoftwareFoundation.Python.3.11_3.11.2544.0_x64__qbz5n2kfra8p0\Lib\asyncio\tasks.py", line 489, in wait_for
    return fut.result()
           ^^^^^^^^^^^^
  File "C:\Users\MSI\AppData\Local\Packages\PythonSoftwareFoundation.Python.3.11_qbz5n2kfra8p0\LocalCache\local-packages\Python311\site-packages\discord\gateway.py", line 374, in from_client
    socket = await client.http.ws_connect(str(url))
             ^^^^^^^^^^^^^^^^^^^^^^^^^^^^^^^^^^^^^^
  File "C:\Users\MSI\AppData\Local\Packages\PythonSoftwareFoundation.Python.3.11_qbz5n2kfra8p0\LocalCache\local-packages\Python311\site-packages\discord\http.py", line 550, in ws_connect
    return await self.__session.ws_connect(url, **kwargs)
           ^^^^^^^^^^^^^^^^^^^^^^^^^^^^^^^^^^^^^^^^^^^^^^
  File "C:\Users\MSI\AppData\Local\Packages\PythonSoftwareFoundation.Python.3.11_qbz5n2kfra8p0\LocalCache\local-packages\Python311\site-packages\aiohttp\client.py", line 1002, in _ws_connect
    resp = await self.request(
           ^^^^^^^^^^^^^^^^^^^
  File "C:\Users\MSI\AppData\Local\Packages\PythonSoftwareFoundation.Python.3.11_qbz5n2kfra8p0\LocalCache\local-packages\Python311\site-packages\aiohttp\client.py", line 701, in _request
    conn = await self._connector.connect(
           ^^^^^^^^^^^^^^^^^^^^^^^^^^^^^^
  File "C:\Users\MSI\AppData\Local\Packages\PythonSoftwareFoundation.Python.3.11_qbz5n2kfra8p0\LocalCache\local-packages\Python311\site-packages\aiohttp\connector.py", line 544, in connect
    proto = await self._create_connection(req, traces, timeout)
            ^^^^^^^^^^^^^^^^^^^^^^^^^^^^^^^^^^^^^^^^^^^^^^^^^^^
  File "C:\Users\MSI\AppData\Local\Packages\PythonSoftwareFoundation.Python.3.11_qbz5n2kfra8p0\LocalCache\local-packages\Python311\site-packages\aiohttp\connector.py", line 1050, in _create_connection
    _, proto = await self._create_direct_connection(req, traces, timeout)
               ^^^^^^^^^^^^^^^^^^^^^^^^^^^^^^^^^^^^^^^^^^^^^^^^^^^^^^^^^^
  File "C:\Users\MSI\AppData\Local\Packages\PythonSoftwareFoundation.Python.3.11_qbz5n2kfra8p0\LocalCache\local-packages\Python311\site-packages\aiohttp\connector.py", line 1351, in _create_direct_connection
    raise ClientConnectorDNSError(req.connection_key, exc) from exc
aiohttp.client_exceptions.ClientConnectorDNSError: Cannot connect to host gateway-us-east1-d.discord.gg:443 ssl:default [getaddrinfo failed]
2024-12-22 11:31:59,907 - INFO - Shard ID None session has been invalidated.
2024-12-22 11:32:05,834 - INFO - Shard ID None has connected to Gateway (Session ID: 344e05ce3ee68f3d54b402cbb83dfb40).
2024-12-22 11:32:07,883 - INFO - Bot is online as OF verification#6016
2024-12-22 14:32:11,514 - WARNING - Shard ID None has stopped responding to the gateway. Closing and restarting.
2024-12-22 14:32:12,196 - INFO - Shard ID None session has been invalidated.
2024-12-22 14:32:20,062 - INFO - Shard ID None has connected to Gateway (Session ID: 56e882d4d6d5848e55001f239cba0802).
2024-12-22 14:32:22,105 - INFO - Bot is online as OF verification#6016
2024-12-22 15:56:20,424 - WARNING - Shard ID None has stopped responding to the gateway. Closing and restarting.
2024-12-22 15:56:22,827 - INFO - Shard ID None session has been invalidated.
2024-12-22 16:08:32,694 - ERROR - Attempting a reconnect in 1.26s
Traceback (most recent call last):
  File "C:\Users\MSI\AppData\Local\Packages\PythonSoftwareFoundation.Python.3.11_qbz5n2kfra8p0\LocalCache\local-packages\Python311\site-packages\discord\client.py", line 664, in connect
    self.ws = await asyncio.wait_for(coro, timeout=60.0)
              ^^^^^^^^^^^^^^^^^^^^^^^^^^^^^^^^^^^^^^^^^^
  File "C:\Program Files\WindowsApps\PythonSoftwareFoundation.Python.3.11_3.11.2544.0_x64__qbz5n2kfra8p0\Lib\asyncio\tasks.py", line 489, in wait_for
    return fut.result()
           ^^^^^^^^^^^^
  File "C:\Users\MSI\AppData\Local\Packages\PythonSoftwareFoundation.Python.3.11_qbz5n2kfra8p0\LocalCache\local-packages\Python311\site-packages\discord\gateway.py", line 404, in from_client
    await ws.identify()
  File "C:\Users\MSI\AppData\Local\Packages\PythonSoftwareFoundation.Python.3.11_qbz5n2kfra8p0\LocalCache\local-packages\Python311\site-packages\discord\gateway.py", line 472, in identify
    await self.send_as_json(payload)
  File "C:\Users\MSI\AppData\Local\Packages\PythonSoftwareFoundation.Python.3.11_qbz5n2kfra8p0\LocalCache\local-packages\Python311\site-packages\discord\gateway.py", line 661, in send_as_json
    await self.send(utils._to_json(data))
  File "C:\Users\MSI\AppData\Local\Packages\PythonSoftwareFoundation.Python.3.11_qbz5n2kfra8p0\LocalCache\local-packages\Python311\site-packages\discord\gateway.py", line 657, in send
    await self.socket.send_str(data)
  File "C:\Users\MSI\AppData\Local\Packages\PythonSoftwareFoundation.Python.3.11_qbz5n2kfra8p0\LocalCache\local-packages\Python311\site-packages\aiohttp\client_ws.py", line 243, in send_str
    await self._writer.send_frame(
  File "C:\Users\MSI\AppData\Local\Packages\PythonSoftwareFoundation.Python.3.11_qbz5n2kfra8p0\LocalCache\local-packages\Python311\site-packages\aiohttp\_websocket\writer.py", line 125, in send_frame
    raise ClientConnectionResetError("Cannot write to closing transport")
aiohttp.client_exceptions.ClientConnectionResetError: Cannot write to closing transport
2024-12-22 16:08:34,041 - ERROR - Attempting a reconnect in 0.28s
Traceback (most recent call last):
  File "C:\Users\MSI\AppData\Local\Packages\PythonSoftwareFoundation.Python.3.11_qbz5n2kfra8p0\LocalCache\local-packages\Python311\site-packages\aiohttp\connector.py", line 1345, in _create_direct_connection
    hosts = await self._resolve_host(host, port, traces=traces)
            ^^^^^^^^^^^^^^^^^^^^^^^^^^^^^^^^^^^^^^^^^^^^^^^^^^^
  File "C:\Users\MSI\AppData\Local\Packages\PythonSoftwareFoundation.Python.3.11_qbz5n2kfra8p0\LocalCache\local-packages\Python311\site-packages\aiohttp\connector.py", line 989, in _resolve_host
    return await asyncio.shield(resolved_host_task)
           ^^^^^^^^^^^^^^^^^^^^^^^^^^^^^^^^^^^^^^^^
  File "C:\Users\MSI\AppData\Local\Packages\PythonSoftwareFoundation.Python.3.11_qbz5n2kfra8p0\LocalCache\local-packages\Python311\site-packages\aiohttp\connector.py", line 1020, in _resolve_host_with_throttle
    addrs = await self._resolver.resolve(host, port, family=self._family)
            ^^^^^^^^^^^^^^^^^^^^^^^^^^^^^^^^^^^^^^^^^^^^^^^^^^^^^^^^^^^^^
  File "C:\Users\MSI\AppData\Local\Packages\PythonSoftwareFoundation.Python.3.11_qbz5n2kfra8p0\LocalCache\local-packages\Python311\site-packages\aiohttp\resolver.py", line 36, in resolve
    infos = await self._loop.getaddrinfo(
            ^^^^^^^^^^^^^^^^^^^^^^^^^^^^^
  File "C:\Program Files\WindowsApps\PythonSoftwareFoundation.Python.3.11_3.11.2544.0_x64__qbz5n2kfra8p0\Lib\asyncio\base_events.py", line 868, in getaddrinfo
    return await self.run_in_executor(
           ^^^^^^^^^^^^^^^^^^^^^^^^^^^
  File "C:\Program Files\WindowsApps\PythonSoftwareFoundation.Python.3.11_3.11.2544.0_x64__qbz5n2kfra8p0\Lib\concurrent\futures\thread.py", line 58, in run
    result = self.fn(*self.args, **self.kwargs)
             ^^^^^^^^^^^^^^^^^^^^^^^^^^^^^^^^^^
  File "C:\Program Files\WindowsApps\PythonSoftwareFoundation.Python.3.11_3.11.2544.0_x64__qbz5n2kfra8p0\Lib\socket.py", line 962, in getaddrinfo
    for res in _socket.getaddrinfo(host, port, family, type, proto, flags):
               ^^^^^^^^^^^^^^^^^^^^^^^^^^^^^^^^^^^^^^^^^^^^^^^^^^^^^^^^^^^
socket.gaierror: [Errno 11001] getaddrinfo failed

The above exception was the direct cause of the following exception:

Traceback (most recent call last):
  File "C:\Users\MSI\AppData\Local\Packages\PythonSoftwareFoundation.Python.3.11_qbz5n2kfra8p0\LocalCache\local-packages\Python311\site-packages\discord\client.py", line 664, in connect
    self.ws = await asyncio.wait_for(coro, timeout=60.0)
              ^^^^^^^^^^^^^^^^^^^^^^^^^^^^^^^^^^^^^^^^^^
  File "C:\Program Files\WindowsApps\PythonSoftwareFoundation.Python.3.11_3.11.2544.0_x64__qbz5n2kfra8p0\Lib\asyncio\tasks.py", line 489, in wait_for
    return fut.result()
           ^^^^^^^^^^^^
  File "C:\Users\MSI\AppData\Local\Packages\PythonSoftwareFoundation.Python.3.11_qbz5n2kfra8p0\LocalCache\local-packages\Python311\site-packages\discord\gateway.py", line 374, in from_client
    socket = await client.http.ws_connect(str(url))
             ^^^^^^^^^^^^^^^^^^^^^^^^^^^^^^^^^^^^^^
  File "C:\Users\MSI\AppData\Local\Packages\PythonSoftwareFoundation.Python.3.11_qbz5n2kfra8p0\LocalCache\local-packages\Python311\site-packages\discord\http.py", line 550, in ws_connect
    return await self.__session.ws_connect(url, **kwargs)
           ^^^^^^^^^^^^^^^^^^^^^^^^^^^^^^^^^^^^^^^^^^^^^^
  File "C:\Users\MSI\AppData\Local\Packages\PythonSoftwareFoundation.Python.3.11_qbz5n2kfra8p0\LocalCache\local-packages\Python311\site-packages\aiohttp\client.py", line 1002, in _ws_connect
    resp = await self.request(
           ^^^^^^^^^^^^^^^^^^^
  File "C:\Users\MSI\AppData\Local\Packages\PythonSoftwareFoundation.Python.3.11_qbz5n2kfra8p0\LocalCache\local-packages\Python311\site-packages\aiohttp\client.py", line 701, in _request
    conn = await self._connector.connect(
           ^^^^^^^^^^^^^^^^^^^^^^^^^^^^^^
  File "C:\Users\MSI\AppData\Local\Packages\PythonSoftwareFoundation.Python.3.11_qbz5n2kfra8p0\LocalCache\local-packages\Python311\site-packages\aiohttp\connector.py", line 544, in connect
    proto = await self._create_connection(req, traces, timeout)
            ^^^^^^^^^^^^^^^^^^^^^^^^^^^^^^^^^^^^^^^^^^^^^^^^^^^
  File "C:\Users\MSI\AppData\Local\Packages\PythonSoftwareFoundation.Python.3.11_qbz5n2kfra8p0\LocalCache\local-packages\Python311\site-packages\aiohttp\connector.py", line 1050, in _create_connection
    _, proto = await self._create_direct_connection(req, traces, timeout)
               ^^^^^^^^^^^^^^^^^^^^^^^^^^^^^^^^^^^^^^^^^^^^^^^^^^^^^^^^^^
  File "C:\Users\MSI\AppData\Local\Packages\PythonSoftwareFoundation.Python.3.11_qbz5n2kfra8p0\LocalCache\local-packages\Python311\site-packages\aiohttp\connector.py", line 1351, in _create_direct_connection
    raise ClientConnectorDNSError(req.connection_key, exc) from exc
aiohttp.client_exceptions.ClientConnectorDNSError: Cannot connect to host gateway.discord.gg:443 ssl:default [getaddrinfo failed]
2024-12-22 16:08:34,335 - ERROR - Attempting a reconnect in 0.30s
Traceback (most recent call last):
  File "C:\Users\MSI\AppData\Local\Packages\PythonSoftwareFoundation.Python.3.11_qbz5n2kfra8p0\LocalCache\local-packages\Python311\site-packages\aiohttp\connector.py", line 1345, in _create_direct_connection
    hosts = await self._resolve_host(host, port, traces=traces)
            ^^^^^^^^^^^^^^^^^^^^^^^^^^^^^^^^^^^^^^^^^^^^^^^^^^^
  File "C:\Users\MSI\AppData\Local\Packages\PythonSoftwareFoundation.Python.3.11_qbz5n2kfra8p0\LocalCache\local-packages\Python311\site-packages\aiohttp\connector.py", line 989, in _resolve_host
    return await asyncio.shield(resolved_host_task)
           ^^^^^^^^^^^^^^^^^^^^^^^^^^^^^^^^^^^^^^^^
  File "C:\Users\MSI\AppData\Local\Packages\PythonSoftwareFoundation.Python.3.11_qbz5n2kfra8p0\LocalCache\local-packages\Python311\site-packages\aiohttp\connector.py", line 1020, in _resolve_host_with_throttle
    addrs = await self._resolver.resolve(host, port, family=self._family)
            ^^^^^^^^^^^^^^^^^^^^^^^^^^^^^^^^^^^^^^^^^^^^^^^^^^^^^^^^^^^^^
  File "C:\Users\MSI\AppData\Local\Packages\PythonSoftwareFoundation.Python.3.11_qbz5n2kfra8p0\LocalCache\local-packages\Python311\site-packages\aiohttp\resolver.py", line 36, in resolve
    infos = await self._loop.getaddrinfo(
            ^^^^^^^^^^^^^^^^^^^^^^^^^^^^^
  File "C:\Program Files\WindowsApps\PythonSoftwareFoundation.Python.3.11_3.11.2544.0_x64__qbz5n2kfra8p0\Lib\asyncio\base_events.py", line 868, in getaddrinfo
    return await self.run_in_executor(
           ^^^^^^^^^^^^^^^^^^^^^^^^^^^
  File "C:\Program Files\WindowsApps\PythonSoftwareFoundation.Python.3.11_3.11.2544.0_x64__qbz5n2kfra8p0\Lib\concurrent\futures\thread.py", line 58, in run
    result = self.fn(*self.args, **self.kwargs)
             ^^^^^^^^^^^^^^^^^^^^^^^^^^^^^^^^^^
  File "C:\Program Files\WindowsApps\PythonSoftwareFoundation.Python.3.11_3.11.2544.0_x64__qbz5n2kfra8p0\Lib\socket.py", line 962, in getaddrinfo
    for res in _socket.getaddrinfo(host, port, family, type, proto, flags):
               ^^^^^^^^^^^^^^^^^^^^^^^^^^^^^^^^^^^^^^^^^^^^^^^^^^^^^^^^^^^
socket.gaierror: [Errno 11001] getaddrinfo failed

The above exception was the direct cause of the following exception:

Traceback (most recent call last):
  File "C:\Users\MSI\AppData\Local\Packages\PythonSoftwareFoundation.Python.3.11_qbz5n2kfra8p0\LocalCache\local-packages\Python311\site-packages\discord\client.py", line 664, in connect
    self.ws = await asyncio.wait_for(coro, timeout=60.0)
              ^^^^^^^^^^^^^^^^^^^^^^^^^^^^^^^^^^^^^^^^^^
  File "C:\Program Files\WindowsApps\PythonSoftwareFoundation.Python.3.11_3.11.2544.0_x64__qbz5n2kfra8p0\Lib\asyncio\tasks.py", line 489, in wait_for
    return fut.result()
           ^^^^^^^^^^^^
  File "C:\Users\MSI\AppData\Local\Packages\PythonSoftwareFoundation.Python.3.11_qbz5n2kfra8p0\LocalCache\local-packages\Python311\site-packages\discord\gateway.py", line 374, in from_client
    socket = await client.http.ws_connect(str(url))
             ^^^^^^^^^^^^^^^^^^^^^^^^^^^^^^^^^^^^^^
  File "C:\Users\MSI\AppData\Local\Packages\PythonSoftwareFoundation.Python.3.11_qbz5n2kfra8p0\LocalCache\local-packages\Python311\site-packages\discord\http.py", line 550, in ws_connect
    return await self.__session.ws_connect(url, **kwargs)
           ^^^^^^^^^^^^^^^^^^^^^^^^^^^^^^^^^^^^^^^^^^^^^^
  File "C:\Users\MSI\AppData\Local\Packages\PythonSoftwareFoundation.Python.3.11_qbz5n2kfra8p0\LocalCache\local-packages\Python311\site-packages\aiohttp\client.py", line 1002, in _ws_connect
    resp = await self.request(
           ^^^^^^^^^^^^^^^^^^^
  File "C:\Users\MSI\AppData\Local\Packages\PythonSoftwareFoundation.Python.3.11_qbz5n2kfra8p0\LocalCache\local-packages\Python311\site-packages\aiohttp\client.py", line 701, in _request
    conn = await self._connector.connect(
           ^^^^^^^^^^^^^^^^^^^^^^^^^^^^^^
  File "C:\Users\MSI\AppData\Local\Packages\PythonSoftwareFoundation.Python.3.11_qbz5n2kfra8p0\LocalCache\local-packages\Python311\site-packages\aiohttp\connector.py", line 544, in connect
    proto = await self._create_connection(req, traces, timeout)
            ^^^^^^^^^^^^^^^^^^^^^^^^^^^^^^^^^^^^^^^^^^^^^^^^^^^
  File "C:\Users\MSI\AppData\Local\Packages\PythonSoftwareFoundation.Python.3.11_qbz5n2kfra8p0\LocalCache\local-packages\Python311\site-packages\aiohttp\connector.py", line 1050, in _create_connection
    _, proto = await self._create_direct_connection(req, traces, timeout)
               ^^^^^^^^^^^^^^^^^^^^^^^^^^^^^^^^^^^^^^^^^^^^^^^^^^^^^^^^^^
  File "C:\Users\MSI\AppData\Local\Packages\PythonSoftwareFoundation.Python.3.11_qbz5n2kfra8p0\LocalCache\local-packages\Python311\site-packages\aiohttp\connector.py", line 1351, in _create_direct_connection
    raise ClientConnectorDNSError(req.connection_key, exc) from exc
aiohttp.client_exceptions.ClientConnectorDNSError: Cannot connect to host gateway.discord.gg:443 ssl:default [getaddrinfo failed]
2024-12-22 16:08:34,637 - ERROR - Attempting a reconnect in 7.84s
Traceback (most recent call last):
  File "C:\Users\MSI\AppData\Local\Packages\PythonSoftwareFoundation.Python.3.11_qbz5n2kfra8p0\LocalCache\local-packages\Python311\site-packages\aiohttp\connector.py", line 1345, in _create_direct_connection
    hosts = await self._resolve_host(host, port, traces=traces)
            ^^^^^^^^^^^^^^^^^^^^^^^^^^^^^^^^^^^^^^^^^^^^^^^^^^^
  File "C:\Users\MSI\AppData\Local\Packages\PythonSoftwareFoundation.Python.3.11_qbz5n2kfra8p0\LocalCache\local-packages\Python311\site-packages\aiohttp\connector.py", line 989, in _resolve_host
    return await asyncio.shield(resolved_host_task)
           ^^^^^^^^^^^^^^^^^^^^^^^^^^^^^^^^^^^^^^^^
  File "C:\Users\MSI\AppData\Local\Packages\PythonSoftwareFoundation.Python.3.11_qbz5n2kfra8p0\LocalCache\local-packages\Python311\site-packages\aiohttp\connector.py", line 1020, in _resolve_host_with_throttle
    addrs = await self._resolver.resolve(host, port, family=self._family)
            ^^^^^^^^^^^^^^^^^^^^^^^^^^^^^^^^^^^^^^^^^^^^^^^^^^^^^^^^^^^^^
  File "C:\Users\MSI\AppData\Local\Packages\PythonSoftwareFoundation.Python.3.11_qbz5n2kfra8p0\LocalCache\local-packages\Python311\site-packages\aiohttp\resolver.py", line 36, in resolve
    infos = await self._loop.getaddrinfo(
            ^^^^^^^^^^^^^^^^^^^^^^^^^^^^^
  File "C:\Program Files\WindowsApps\PythonSoftwareFoundation.Python.3.11_3.11.2544.0_x64__qbz5n2kfra8p0\Lib\asyncio\base_events.py", line 868, in getaddrinfo
    return await self.run_in_executor(
           ^^^^^^^^^^^^^^^^^^^^^^^^^^^
  File "C:\Program Files\WindowsApps\PythonSoftwareFoundation.Python.3.11_3.11.2544.0_x64__qbz5n2kfra8p0\Lib\concurrent\futures\thread.py", line 58, in run
    result = self.fn(*self.args, **self.kwargs)
             ^^^^^^^^^^^^^^^^^^^^^^^^^^^^^^^^^^
  File "C:\Program Files\WindowsApps\PythonSoftwareFoundation.Python.3.11_3.11.2544.0_x64__qbz5n2kfra8p0\Lib\socket.py", line 962, in getaddrinfo
    for res in _socket.getaddrinfo(host, port, family, type, proto, flags):
               ^^^^^^^^^^^^^^^^^^^^^^^^^^^^^^^^^^^^^^^^^^^^^^^^^^^^^^^^^^^
socket.gaierror: [Errno 11001] getaddrinfo failed

The above exception was the direct cause of the following exception:

Traceback (most recent call last):
  File "C:\Users\MSI\AppData\Local\Packages\PythonSoftwareFoundation.Python.3.11_qbz5n2kfra8p0\LocalCache\local-packages\Python311\site-packages\discord\client.py", line 664, in connect
    self.ws = await asyncio.wait_for(coro, timeout=60.0)
              ^^^^^^^^^^^^^^^^^^^^^^^^^^^^^^^^^^^^^^^^^^
  File "C:\Program Files\WindowsApps\PythonSoftwareFoundation.Python.3.11_3.11.2544.0_x64__qbz5n2kfra8p0\Lib\asyncio\tasks.py", line 489, in wait_for
    return fut.result()
           ^^^^^^^^^^^^
  File "C:\Users\MSI\AppData\Local\Packages\PythonSoftwareFoundation.Python.3.11_qbz5n2kfra8p0\LocalCache\local-packages\Python311\site-packages\discord\gateway.py", line 374, in from_client
    socket = await client.http.ws_connect(str(url))
             ^^^^^^^^^^^^^^^^^^^^^^^^^^^^^^^^^^^^^^
  File "C:\Users\MSI\AppData\Local\Packages\PythonSoftwareFoundation.Python.3.11_qbz5n2kfra8p0\LocalCache\local-packages\Python311\site-packages\discord\http.py", line 550, in ws_connect
    return await self.__session.ws_connect(url, **kwargs)
           ^^^^^^^^^^^^^^^^^^^^^^^^^^^^^^^^^^^^^^^^^^^^^^
  File "C:\Users\MSI\AppData\Local\Packages\PythonSoftwareFoundation.Python.3.11_qbz5n2kfra8p0\LocalCache\local-packages\Python311\site-packages\aiohttp\client.py", line 1002, in _ws_connect
    resp = await self.request(
           ^^^^^^^^^^^^^^^^^^^
  File "C:\Users\MSI\AppData\Local\Packages\PythonSoftwareFoundation.Python.3.11_qbz5n2kfra8p0\LocalCache\local-packages\Python311\site-packages\aiohttp\client.py", line 701, in _request
    conn = await self._connector.connect(
           ^^^^^^^^^^^^^^^^^^^^^^^^^^^^^^
  File "C:\Users\MSI\AppData\Local\Packages\PythonSoftwareFoundation.Python.3.11_qbz5n2kfra8p0\LocalCache\local-packages\Python311\site-packages\aiohttp\connector.py", line 544, in connect
    proto = await self._create_connection(req, traces, timeout)
            ^^^^^^^^^^^^^^^^^^^^^^^^^^^^^^^^^^^^^^^^^^^^^^^^^^^
  File "C:\Users\MSI\AppData\Local\Packages\PythonSoftwareFoundation.Python.3.11_qbz5n2kfra8p0\LocalCache\local-packages\Python311\site-packages\aiohttp\connector.py", line 1050, in _create_connection
    _, proto = await self._create_direct_connection(req, traces, timeout)
               ^^^^^^^^^^^^^^^^^^^^^^^^^^^^^^^^^^^^^^^^^^^^^^^^^^^^^^^^^^
  File "C:\Users\MSI\AppData\Local\Packages\PythonSoftwareFoundation.Python.3.11_qbz5n2kfra8p0\LocalCache\local-packages\Python311\site-packages\aiohttp\connector.py", line 1351, in _create_direct_connection
    raise ClientConnectorDNSError(req.connection_key, exc) from exc
aiohttp.client_exceptions.ClientConnectorDNSError: Cannot connect to host gateway.discord.gg:443 ssl:default [getaddrinfo failed]
2024-12-22 16:08:42,479 - ERROR - Attempting a reconnect in 21.35s
Traceback (most recent call last):
  File "C:\Users\MSI\AppData\Local\Packages\PythonSoftwareFoundation.Python.3.11_qbz5n2kfra8p0\LocalCache\local-packages\Python311\site-packages\aiohttp\connector.py", line 1345, in _create_direct_connection
    hosts = await self._resolve_host(host, port, traces=traces)
            ^^^^^^^^^^^^^^^^^^^^^^^^^^^^^^^^^^^^^^^^^^^^^^^^^^^
  File "C:\Users\MSI\AppData\Local\Packages\PythonSoftwareFoundation.Python.3.11_qbz5n2kfra8p0\LocalCache\local-packages\Python311\site-packages\aiohttp\connector.py", line 989, in _resolve_host
    return await asyncio.shield(resolved_host_task)
           ^^^^^^^^^^^^^^^^^^^^^^^^^^^^^^^^^^^^^^^^
  File "C:\Users\MSI\AppData\Local\Packages\PythonSoftwareFoundation.Python.3.11_qbz5n2kfra8p0\LocalCache\local-packages\Python311\site-packages\aiohttp\connector.py", line 1020, in _resolve_host_with_throttle
    addrs = await self._resolver.resolve(host, port, family=self._family)
            ^^^^^^^^^^^^^^^^^^^^^^^^^^^^^^^^^^^^^^^^^^^^^^^^^^^^^^^^^^^^^
  File "C:\Users\MSI\AppData\Local\Packages\PythonSoftwareFoundation.Python.3.11_qbz5n2kfra8p0\LocalCache\local-packages\Python311\site-packages\aiohttp\resolver.py", line 36, in resolve
    infos = await self._loop.getaddrinfo(
            ^^^^^^^^^^^^^^^^^^^^^^^^^^^^^
  File "C:\Program Files\WindowsApps\PythonSoftwareFoundation.Python.3.11_3.11.2544.0_x64__qbz5n2kfra8p0\Lib\asyncio\base_events.py", line 868, in getaddrinfo
    return await self.run_in_executor(
           ^^^^^^^^^^^^^^^^^^^^^^^^^^^
  File "C:\Program Files\WindowsApps\PythonSoftwareFoundation.Python.3.11_3.11.2544.0_x64__qbz5n2kfra8p0\Lib\concurrent\futures\thread.py", line 58, in run
    result = self.fn(*self.args, **self.kwargs)
             ^^^^^^^^^^^^^^^^^^^^^^^^^^^^^^^^^^
  File "C:\Program Files\WindowsApps\PythonSoftwareFoundation.Python.3.11_3.11.2544.0_x64__qbz5n2kfra8p0\Lib\socket.py", line 962, in getaddrinfo
    for res in _socket.getaddrinfo(host, port, family, type, proto, flags):
               ^^^^^^^^^^^^^^^^^^^^^^^^^^^^^^^^^^^^^^^^^^^^^^^^^^^^^^^^^^^
socket.gaierror: [Errno 11001] getaddrinfo failed

The above exception was the direct cause of the following exception:

Traceback (most recent call last):
  File "C:\Users\MSI\AppData\Local\Packages\PythonSoftwareFoundation.Python.3.11_qbz5n2kfra8p0\LocalCache\local-packages\Python311\site-packages\discord\client.py", line 664, in connect
    self.ws = await asyncio.wait_for(coro, timeout=60.0)
              ^^^^^^^^^^^^^^^^^^^^^^^^^^^^^^^^^^^^^^^^^^
  File "C:\Program Files\WindowsApps\PythonSoftwareFoundation.Python.3.11_3.11.2544.0_x64__qbz5n2kfra8p0\Lib\asyncio\tasks.py", line 489, in wait_for
    return fut.result()
           ^^^^^^^^^^^^
  File "C:\Users\MSI\AppData\Local\Packages\PythonSoftwareFoundation.Python.3.11_qbz5n2kfra8p0\LocalCache\local-packages\Python311\site-packages\discord\gateway.py", line 374, in from_client
    socket = await client.http.ws_connect(str(url))
             ^^^^^^^^^^^^^^^^^^^^^^^^^^^^^^^^^^^^^^
  File "C:\Users\MSI\AppData\Local\Packages\PythonSoftwareFoundation.Python.3.11_qbz5n2kfra8p0\LocalCache\local-packages\Python311\site-packages\discord\http.py", line 550, in ws_connect
    return await self.__session.ws_connect(url, **kwargs)
           ^^^^^^^^^^^^^^^^^^^^^^^^^^^^^^^^^^^^^^^^^^^^^^
  File "C:\Users\MSI\AppData\Local\Packages\PythonSoftwareFoundation.Python.3.11_qbz5n2kfra8p0\LocalCache\local-packages\Python311\site-packages\aiohttp\client.py", line 1002, in _ws_connect
    resp = await self.request(
           ^^^^^^^^^^^^^^^^^^^
  File "C:\Users\MSI\AppData\Local\Packages\PythonSoftwareFoundation.Python.3.11_qbz5n2kfra8p0\LocalCache\local-packages\Python311\site-packages\aiohttp\client.py", line 701, in _request
    conn = await self._connector.connect(
           ^^^^^^^^^^^^^^^^^^^^^^^^^^^^^^
  File "C:\Users\MSI\AppData\Local\Packages\PythonSoftwareFoundation.Python.3.11_qbz5n2kfra8p0\LocalCache\local-packages\Python311\site-packages\aiohttp\connector.py", line 544, in connect
    proto = await self._create_connection(req, traces, timeout)
            ^^^^^^^^^^^^^^^^^^^^^^^^^^^^^^^^^^^^^^^^^^^^^^^^^^^
  File "C:\Users\MSI\AppData\Local\Packages\PythonSoftwareFoundation.Python.3.11_qbz5n2kfra8p0\LocalCache\local-packages\Python311\site-packages\aiohttp\connector.py", line 1050, in _create_connection
    _, proto = await self._create_direct_connection(req, traces, timeout)
               ^^^^^^^^^^^^^^^^^^^^^^^^^^^^^^^^^^^^^^^^^^^^^^^^^^^^^^^^^^
  File "C:\Users\MSI\AppData\Local\Packages\PythonSoftwareFoundation.Python.3.11_qbz5n2kfra8p0\LocalCache\local-packages\Python311\site-packages\aiohttp\connector.py", line 1351, in _create_direct_connection
    raise ClientConnectorDNSError(req.connection_key, exc) from exc
aiohttp.client_exceptions.ClientConnectorDNSError: Cannot connect to host gateway.discord.gg:443 ssl:default [getaddrinfo failed]
2024-12-22 16:28:46,327 - INFO - Shard ID None session has been invalidated.
2024-12-22 16:28:52,054 - WARNING - Shard ID None has stopped responding to the gateway. Closing and restarting.
2024-12-22 16:28:53,650 - INFO - Shard ID None has connected to Gateway (Session ID: 143ec40e90333583a1fc68e9a0a96ebc).
2024-12-22 16:28:55,760 - INFO - Bot is online as OF verification#6016
2024-12-22 16:29:48,634 - ERROR - Attempting a reconnect in 48.08s
Traceback (most recent call last):
  File "C:\Users\MSI\AppData\Local\Packages\PythonSoftwareFoundation.Python.3.11_qbz5n2kfra8p0\LocalCache\local-packages\Python311\site-packages\aiohttp\connector.py", line 1345, in _create_direct_connection
    hosts = await self._resolve_host(host, port, traces=traces)
            ^^^^^^^^^^^^^^^^^^^^^^^^^^^^^^^^^^^^^^^^^^^^^^^^^^^
  File "C:\Users\MSI\AppData\Local\Packages\PythonSoftwareFoundation.Python.3.11_qbz5n2kfra8p0\LocalCache\local-packages\Python311\site-packages\aiohttp\connector.py", line 989, in _resolve_host
    return await asyncio.shield(resolved_host_task)
           ^^^^^^^^^^^^^^^^^^^^^^^^^^^^^^^^^^^^^^^^
  File "C:\Users\MSI\AppData\Local\Packages\PythonSoftwareFoundation.Python.3.11_qbz5n2kfra8p0\LocalCache\local-packages\Python311\site-packages\aiohttp\connector.py", line 1020, in _resolve_host_with_throttle
    addrs = await self._resolver.resolve(host, port, family=self._family)
            ^^^^^^^^^^^^^^^^^^^^^^^^^^^^^^^^^^^^^^^^^^^^^^^^^^^^^^^^^^^^^
  File "C:\Users\MSI\AppData\Local\Packages\PythonSoftwareFoundation.Python.3.11_qbz5n2kfra8p0\LocalCache\local-packages\Python311\site-packages\aiohttp\resolver.py", line 36, in resolve
    infos = await self._loop.getaddrinfo(
            ^^^^^^^^^^^^^^^^^^^^^^^^^^^^^
  File "C:\Program Files\WindowsApps\PythonSoftwareFoundation.Python.3.11_3.11.2544.0_x64__qbz5n2kfra8p0\Lib\asyncio\base_events.py", line 868, in getaddrinfo
    return await self.run_in_executor(
           ^^^^^^^^^^^^^^^^^^^^^^^^^^^
  File "C:\Program Files\WindowsApps\PythonSoftwareFoundation.Python.3.11_3.11.2544.0_x64__qbz5n2kfra8p0\Lib\concurrent\futures\thread.py", line 58, in run
    result = self.fn(*self.args, **self.kwargs)
             ^^^^^^^^^^^^^^^^^^^^^^^^^^^^^^^^^^
  File "C:\Program Files\WindowsApps\PythonSoftwareFoundation.Python.3.11_3.11.2544.0_x64__qbz5n2kfra8p0\Lib\socket.py", line 962, in getaddrinfo
    for res in _socket.getaddrinfo(host, port, family, type, proto, flags):
               ^^^^^^^^^^^^^^^^^^^^^^^^^^^^^^^^^^^^^^^^^^^^^^^^^^^^^^^^^^^
socket.gaierror: [Errno 11001] getaddrinfo failed

The above exception was the direct cause of the following exception:

Traceback (most recent call last):
  File "C:\Users\MSI\AppData\Local\Packages\PythonSoftwareFoundation.Python.3.11_qbz5n2kfra8p0\LocalCache\local-packages\Python311\site-packages\discord\client.py", line 664, in connect
    self.ws = await asyncio.wait_for(coro, timeout=60.0)
              ^^^^^^^^^^^^^^^^^^^^^^^^^^^^^^^^^^^^^^^^^^
  File "C:\Program Files\WindowsApps\PythonSoftwareFoundation.Python.3.11_3.11.2544.0_x64__qbz5n2kfra8p0\Lib\asyncio\tasks.py", line 489, in wait_for
    return fut.result()
           ^^^^^^^^^^^^
  File "C:\Users\MSI\AppData\Local\Packages\PythonSoftwareFoundation.Python.3.11_qbz5n2kfra8p0\LocalCache\local-packages\Python311\site-packages\discord\gateway.py", line 374, in from_client
    socket = await client.http.ws_connect(str(url))
             ^^^^^^^^^^^^^^^^^^^^^^^^^^^^^^^^^^^^^^
  File "C:\Users\MSI\AppData\Local\Packages\PythonSoftwareFoundation.Python.3.11_qbz5n2kfra8p0\LocalCache\local-packages\Python311\site-packages\discord\http.py", line 550, in ws_connect
    return await self.__session.ws_connect(url, **kwargs)
           ^^^^^^^^^^^^^^^^^^^^^^^^^^^^^^^^^^^^^^^^^^^^^^
  File "C:\Users\MSI\AppData\Local\Packages\PythonSoftwareFoundation.Python.3.11_qbz5n2kfra8p0\LocalCache\local-packages\Python311\site-packages\aiohttp\client.py", line 1002, in _ws_connect
    resp = await self.request(
           ^^^^^^^^^^^^^^^^^^^
  File "C:\Users\MSI\AppData\Local\Packages\PythonSoftwareFoundation.Python.3.11_qbz5n2kfra8p0\LocalCache\local-packages\Python311\site-packages\aiohttp\client.py", line 701, in _request
    conn = await self._connector.connect(
           ^^^^^^^^^^^^^^^^^^^^^^^^^^^^^^
  File "C:\Users\MSI\AppData\Local\Packages\PythonSoftwareFoundation.Python.3.11_qbz5n2kfra8p0\LocalCache\local-packages\Python311\site-packages\aiohttp\connector.py", line 544, in connect
    proto = await self._create_connection(req, traces, timeout)
            ^^^^^^^^^^^^^^^^^^^^^^^^^^^^^^^^^^^^^^^^^^^^^^^^^^^
  File "C:\Users\MSI\AppData\Local\Packages\PythonSoftwareFoundation.Python.3.11_qbz5n2kfra8p0\LocalCache\local-packages\Python311\site-packages\aiohttp\connector.py", line 1050, in _create_connection
    _, proto = await self._create_direct_connection(req, traces, timeout)
               ^^^^^^^^^^^^^^^^^^^^^^^^^^^^^^^^^^^^^^^^^^^^^^^^^^^^^^^^^^
  File "C:\Users\MSI\AppData\Local\Packages\PythonSoftwareFoundation.Python.3.11_qbz5n2kfra8p0\LocalCache\local-packages\Python311\site-packages\aiohttp\connector.py", line 1351, in _create_direct_connection
    raise ClientConnectorDNSError(req.connection_key, exc) from exc
aiohttp.client_exceptions.ClientConnectorDNSError: Cannot connect to host gateway-us-east1-d.discord.gg:443 ssl:default [getaddrinfo failed]
2024-12-22 16:30:38,386 - INFO - Shard ID None has successfully RESUMED session 143ec40e90333583a1fc68e9a0a96ebc.
2024-12-22 18:23:52,233 - INFO - Shard ID None has successfully RESUMED session 143ec40e90333583a1fc68e9a0a96ebc.
2024-12-22 20:29:54,155 - ERROR - Attempting a reconnect in 0.88s
Traceback (most recent call last):
  File "C:\Users\MSI\AppData\Local\Packages\PythonSoftwareFoundation.Python.3.11_qbz5n2kfra8p0\LocalCache\local-packages\Python311\site-packages\aiohttp\connector.py", line 1345, in _create_direct_connection
    hosts = await self._resolve_host(host, port, traces=traces)
            ^^^^^^^^^^^^^^^^^^^^^^^^^^^^^^^^^^^^^^^^^^^^^^^^^^^
  File "C:\Users\MSI\AppData\Local\Packages\PythonSoftwareFoundation.Python.3.11_qbz5n2kfra8p0\LocalCache\local-packages\Python311\site-packages\aiohttp\connector.py", line 989, in _resolve_host
    return await asyncio.shield(resolved_host_task)
           ^^^^^^^^^^^^^^^^^^^^^^^^^^^^^^^^^^^^^^^^
  File "C:\Users\MSI\AppData\Local\Packages\PythonSoftwareFoundation.Python.3.11_qbz5n2kfra8p0\LocalCache\local-packages\Python311\site-packages\aiohttp\connector.py", line 1020, in _resolve_host_with_throttle
    addrs = await self._resolver.resolve(host, port, family=self._family)
            ^^^^^^^^^^^^^^^^^^^^^^^^^^^^^^^^^^^^^^^^^^^^^^^^^^^^^^^^^^^^^
  File "C:\Users\MSI\AppData\Local\Packages\PythonSoftwareFoundation.Python.3.11_qbz5n2kfra8p0\LocalCache\local-packages\Python311\site-packages\aiohttp\resolver.py", line 36, in resolve
    infos = await self._loop.getaddrinfo(
            ^^^^^^^^^^^^^^^^^^^^^^^^^^^^^
  File "C:\Program Files\WindowsApps\PythonSoftwareFoundation.Python.3.11_3.11.2544.0_x64__qbz5n2kfra8p0\Lib\asyncio\base_events.py", line 868, in getaddrinfo
    return await self.run_in_executor(
           ^^^^^^^^^^^^^^^^^^^^^^^^^^^
  File "C:\Program Files\WindowsApps\PythonSoftwareFoundation.Python.3.11_3.11.2544.0_x64__qbz5n2kfra8p0\Lib\concurrent\futures\thread.py", line 58, in run
    result = self.fn(*self.args, **self.kwargs)
             ^^^^^^^^^^^^^^^^^^^^^^^^^^^^^^^^^^
  File "C:\Program Files\WindowsApps\PythonSoftwareFoundation.Python.3.11_3.11.2544.0_x64__qbz5n2kfra8p0\Lib\socket.py", line 962, in getaddrinfo
    for res in _socket.getaddrinfo(host, port, family, type, proto, flags):
               ^^^^^^^^^^^^^^^^^^^^^^^^^^^^^^^^^^^^^^^^^^^^^^^^^^^^^^^^^^^
socket.gaierror: [Errno 11001] getaddrinfo failed

The above exception was the direct cause of the following exception:

Traceback (most recent call last):
  File "C:\Users\MSI\AppData\Local\Packages\PythonSoftwareFoundation.Python.3.11_qbz5n2kfra8p0\LocalCache\local-packages\Python311\site-packages\discord\client.py", line 664, in connect
    self.ws = await asyncio.wait_for(coro, timeout=60.0)
              ^^^^^^^^^^^^^^^^^^^^^^^^^^^^^^^^^^^^^^^^^^
  File "C:\Program Files\WindowsApps\PythonSoftwareFoundation.Python.3.11_3.11.2544.0_x64__qbz5n2kfra8p0\Lib\asyncio\tasks.py", line 489, in wait_for
    return fut.result()
           ^^^^^^^^^^^^
  File "C:\Users\MSI\AppData\Local\Packages\PythonSoftwareFoundation.Python.3.11_qbz5n2kfra8p0\LocalCache\local-packages\Python311\site-packages\discord\gateway.py", line 374, in from_client
    socket = await client.http.ws_connect(str(url))
             ^^^^^^^^^^^^^^^^^^^^^^^^^^^^^^^^^^^^^^
  File "C:\Users\MSI\AppData\Local\Packages\PythonSoftwareFoundation.Python.3.11_qbz5n2kfra8p0\LocalCache\local-packages\Python311\site-packages\discord\http.py", line 550, in ws_connect
    return await self.__session.ws_connect(url, **kwargs)
           ^^^^^^^^^^^^^^^^^^^^^^^^^^^^^^^^^^^^^^^^^^^^^^
  File "C:\Users\MSI\AppData\Local\Packages\PythonSoftwareFoundation.Python.3.11_qbz5n2kfra8p0\LocalCache\local-packages\Python311\site-packages\aiohttp\client.py", line 1002, in _ws_connect
    resp = await self.request(
           ^^^^^^^^^^^^^^^^^^^
  File "C:\Users\MSI\AppData\Local\Packages\PythonSoftwareFoundation.Python.3.11_qbz5n2kfra8p0\LocalCache\local-packages\Python311\site-packages\aiohttp\client.py", line 701, in _request
    conn = await self._connector.connect(
           ^^^^^^^^^^^^^^^^^^^^^^^^^^^^^^
  File "C:\Users\MSI\AppData\Local\Packages\PythonSoftwareFoundation.Python.3.11_qbz5n2kfra8p0\LocalCache\local-packages\Python311\site-packages\aiohttp\connector.py", line 544, in connect
    proto = await self._create_connection(req, traces, timeout)
            ^^^^^^^^^^^^^^^^^^^^^^^^^^^^^^^^^^^^^^^^^^^^^^^^^^^
  File "C:\Users\MSI\AppData\Local\Packages\PythonSoftwareFoundation.Python.3.11_qbz5n2kfra8p0\LocalCache\local-packages\Python311\site-packages\aiohttp\connector.py", line 1050, in _create_connection
    _, proto = await self._create_direct_connection(req, traces, timeout)
               ^^^^^^^^^^^^^^^^^^^^^^^^^^^^^^^^^^^^^^^^^^^^^^^^^^^^^^^^^^
  File "C:\Users\MSI\AppData\Local\Packages\PythonSoftwareFoundation.Python.3.11_qbz5n2kfra8p0\LocalCache\local-packages\Python311\site-packages\aiohttp\connector.py", line 1351, in _create_direct_connection
    raise ClientConnectorDNSError(req.connection_key, exc) from exc
aiohttp.client_exceptions.ClientConnectorDNSError: Cannot connect to host gateway-us-east1-d.discord.gg:443 ssl:default [getaddrinfo failed]
2024-12-22 20:29:55,158 - ERROR - Attempting a reconnect in 2.29s
Traceback (most recent call last):
  File "C:\Users\MSI\AppData\Local\Packages\PythonSoftwareFoundation.Python.3.11_qbz5n2kfra8p0\LocalCache\local-packages\Python311\site-packages\aiohttp\connector.py", line 1345, in _create_direct_connection
    hosts = await self._resolve_host(host, port, traces=traces)
            ^^^^^^^^^^^^^^^^^^^^^^^^^^^^^^^^^^^^^^^^^^^^^^^^^^^
  File "C:\Users\MSI\AppData\Local\Packages\PythonSoftwareFoundation.Python.3.11_qbz5n2kfra8p0\LocalCache\local-packages\Python311\site-packages\aiohttp\connector.py", line 989, in _resolve_host
    return await asyncio.shield(resolved_host_task)
           ^^^^^^^^^^^^^^^^^^^^^^^^^^^^^^^^^^^^^^^^
  File "C:\Users\MSI\AppData\Local\Packages\PythonSoftwareFoundation.Python.3.11_qbz5n2kfra8p0\LocalCache\local-packages\Python311\site-packages\aiohttp\connector.py", line 1020, in _resolve_host_with_throttle
    addrs = await self._resolver.resolve(host, port, family=self._family)
            ^^^^^^^^^^^^^^^^^^^^^^^^^^^^^^^^^^^^^^^^^^^^^^^^^^^^^^^^^^^^^
  File "C:\Users\MSI\AppData\Local\Packages\PythonSoftwareFoundation.Python.3.11_qbz5n2kfra8p0\LocalCache\local-packages\Python311\site-packages\aiohttp\resolver.py", line 36, in resolve
    infos = await self._loop.getaddrinfo(
            ^^^^^^^^^^^^^^^^^^^^^^^^^^^^^
  File "C:\Program Files\WindowsApps\PythonSoftwareFoundation.Python.3.11_3.11.2544.0_x64__qbz5n2kfra8p0\Lib\asyncio\base_events.py", line 868, in getaddrinfo
    return await self.run_in_executor(
           ^^^^^^^^^^^^^^^^^^^^^^^^^^^
  File "C:\Program Files\WindowsApps\PythonSoftwareFoundation.Python.3.11_3.11.2544.0_x64__qbz5n2kfra8p0\Lib\concurrent\futures\thread.py", line 58, in run
    result = self.fn(*self.args, **self.kwargs)
             ^^^^^^^^^^^^^^^^^^^^^^^^^^^^^^^^^^
  File "C:\Program Files\WindowsApps\PythonSoftwareFoundation.Python.3.11_3.11.2544.0_x64__qbz5n2kfra8p0\Lib\socket.py", line 962, in getaddrinfo
    for res in _socket.getaddrinfo(host, port, family, type, proto, flags):
               ^^^^^^^^^^^^^^^^^^^^^^^^^^^^^^^^^^^^^^^^^^^^^^^^^^^^^^^^^^^
socket.gaierror: [Errno 11001] getaddrinfo failed

The above exception was the direct cause of the following exception:

Traceback (most recent call last):
  File "C:\Users\MSI\AppData\Local\Packages\PythonSoftwareFoundation.Python.3.11_qbz5n2kfra8p0\LocalCache\local-packages\Python311\site-packages\discord\client.py", line 664, in connect
    self.ws = await asyncio.wait_for(coro, timeout=60.0)
              ^^^^^^^^^^^^^^^^^^^^^^^^^^^^^^^^^^^^^^^^^^
  File "C:\Program Files\WindowsApps\PythonSoftwareFoundation.Python.3.11_3.11.2544.0_x64__qbz5n2kfra8p0\Lib\asyncio\tasks.py", line 489, in wait_for
    return fut.result()
           ^^^^^^^^^^^^
  File "C:\Users\MSI\AppData\Local\Packages\PythonSoftwareFoundation.Python.3.11_qbz5n2kfra8p0\LocalCache\local-packages\Python311\site-packages\discord\gateway.py", line 374, in from_client
    socket = await client.http.ws_connect(str(url))
             ^^^^^^^^^^^^^^^^^^^^^^^^^^^^^^^^^^^^^^
  File "C:\Users\MSI\AppData\Local\Packages\PythonSoftwareFoundation.Python.3.11_qbz5n2kfra8p0\LocalCache\local-packages\Python311\site-packages\discord\http.py", line 550, in ws_connect
    return await self.__session.ws_connect(url, **kwargs)
           ^^^^^^^^^^^^^^^^^^^^^^^^^^^^^^^^^^^^^^^^^^^^^^
  File "C:\Users\MSI\AppData\Local\Packages\PythonSoftwareFoundation.Python.3.11_qbz5n2kfra8p0\LocalCache\local-packages\Python311\site-packages\aiohttp\client.py", line 1002, in _ws_connect
    resp = await self.request(
           ^^^^^^^^^^^^^^^^^^^
  File "C:\Users\MSI\AppData\Local\Packages\PythonSoftwareFoundation.Python.3.11_qbz5n2kfra8p0\LocalCache\local-packages\Python311\site-packages\aiohttp\client.py", line 701, in _request
    conn = await self._connector.connect(
           ^^^^^^^^^^^^^^^^^^^^^^^^^^^^^^
  File "C:\Users\MSI\AppData\Local\Packages\PythonSoftwareFoundation.Python.3.11_qbz5n2kfra8p0\LocalCache\local-packages\Python311\site-packages\aiohttp\connector.py", line 544, in connect
    proto = await self._create_connection(req, traces, timeout)
            ^^^^^^^^^^^^^^^^^^^^^^^^^^^^^^^^^^^^^^^^^^^^^^^^^^^
  File "C:\Users\MSI\AppData\Local\Packages\PythonSoftwareFoundation.Python.3.11_qbz5n2kfra8p0\LocalCache\local-packages\Python311\site-packages\aiohttp\connector.py", line 1050, in _create_connection
    _, proto = await self._create_direct_connection(req, traces, timeout)
               ^^^^^^^^^^^^^^^^^^^^^^^^^^^^^^^^^^^^^^^^^^^^^^^^^^^^^^^^^^
  File "C:\Users\MSI\AppData\Local\Packages\PythonSoftwareFoundation.Python.3.11_qbz5n2kfra8p0\LocalCache\local-packages\Python311\site-packages\aiohttp\connector.py", line 1351, in _create_direct_connection
    raise ClientConnectorDNSError(req.connection_key, exc) from exc
aiohttp.client_exceptions.ClientConnectorDNSError: Cannot connect to host gateway-us-east1-d.discord.gg:443 ssl:default [getaddrinfo failed]
2024-12-22 20:29:57,465 - ERROR - Attempting a reconnect in 6.04s
Traceback (most recent call last):
  File "C:\Users\MSI\AppData\Local\Packages\PythonSoftwareFoundation.Python.3.11_qbz5n2kfra8p0\LocalCache\local-packages\Python311\site-packages\aiohttp\connector.py", line 1345, in _create_direct_connection
    hosts = await self._resolve_host(host, port, traces=traces)
            ^^^^^^^^^^^^^^^^^^^^^^^^^^^^^^^^^^^^^^^^^^^^^^^^^^^
  File "C:\Users\MSI\AppData\Local\Packages\PythonSoftwareFoundation.Python.3.11_qbz5n2kfra8p0\LocalCache\local-packages\Python311\site-packages\aiohttp\connector.py", line 989, in _resolve_host
    return await asyncio.shield(resolved_host_task)
           ^^^^^^^^^^^^^^^^^^^^^^^^^^^^^^^^^^^^^^^^
  File "C:\Users\MSI\AppData\Local\Packages\PythonSoftwareFoundation.Python.3.11_qbz5n2kfra8p0\LocalCache\local-packages\Python311\site-packages\aiohttp\connector.py", line 1020, in _resolve_host_with_throttle
    addrs = await self._resolver.resolve(host, port, family=self._family)
            ^^^^^^^^^^^^^^^^^^^^^^^^^^^^^^^^^^^^^^^^^^^^^^^^^^^^^^^^^^^^^
  File "C:\Users\MSI\AppData\Local\Packages\PythonSoftwareFoundation.Python.3.11_qbz5n2kfra8p0\LocalCache\local-packages\Python311\site-packages\aiohttp\resolver.py", line 36, in resolve
    infos = await self._loop.getaddrinfo(
            ^^^^^^^^^^^^^^^^^^^^^^^^^^^^^
  File "C:\Program Files\WindowsApps\PythonSoftwareFoundation.Python.3.11_3.11.2544.0_x64__qbz5n2kfra8p0\Lib\asyncio\base_events.py", line 868, in getaddrinfo
    return await self.run_in_executor(
           ^^^^^^^^^^^^^^^^^^^^^^^^^^^
  File "C:\Program Files\WindowsApps\PythonSoftwareFoundation.Python.3.11_3.11.2544.0_x64__qbz5n2kfra8p0\Lib\concurrent\futures\thread.py", line 58, in run
    result = self.fn(*self.args, **self.kwargs)
             ^^^^^^^^^^^^^^^^^^^^^^^^^^^^^^^^^^
  File "C:\Program Files\WindowsApps\PythonSoftwareFoundation.Python.3.11_3.11.2544.0_x64__qbz5n2kfra8p0\Lib\socket.py", line 962, in getaddrinfo
    for res in _socket.getaddrinfo(host, port, family, type, proto, flags):
               ^^^^^^^^^^^^^^^^^^^^^^^^^^^^^^^^^^^^^^^^^^^^^^^^^^^^^^^^^^^
socket.gaierror: [Errno 11001] getaddrinfo failed

The above exception was the direct cause of the following exception:

Traceback (most recent call last):
  File "C:\Users\MSI\AppData\Local\Packages\PythonSoftwareFoundation.Python.3.11_qbz5n2kfra8p0\LocalCache\local-packages\Python311\site-packages\discord\client.py", line 664, in connect
    self.ws = await asyncio.wait_for(coro, timeout=60.0)
              ^^^^^^^^^^^^^^^^^^^^^^^^^^^^^^^^^^^^^^^^^^
  File "C:\Program Files\WindowsApps\PythonSoftwareFoundation.Python.3.11_3.11.2544.0_x64__qbz5n2kfra8p0\Lib\asyncio\tasks.py", line 489, in wait_for
    return fut.result()
           ^^^^^^^^^^^^
  File "C:\Users\MSI\AppData\Local\Packages\PythonSoftwareFoundation.Python.3.11_qbz5n2kfra8p0\LocalCache\local-packages\Python311\site-packages\discord\gateway.py", line 374, in from_client
    socket = await client.http.ws_connect(str(url))
             ^^^^^^^^^^^^^^^^^^^^^^^^^^^^^^^^^^^^^^
  File "C:\Users\MSI\AppData\Local\Packages\PythonSoftwareFoundation.Python.3.11_qbz5n2kfra8p0\LocalCache\local-packages\Python311\site-packages\discord\http.py", line 550, in ws_connect
    return await self.__session.ws_connect(url, **kwargs)
           ^^^^^^^^^^^^^^^^^^^^^^^^^^^^^^^^^^^^^^^^^^^^^^
  File "C:\Users\MSI\AppData\Local\Packages\PythonSoftwareFoundation.Python.3.11_qbz5n2kfra8p0\LocalCache\local-packages\Python311\site-packages\aiohttp\client.py", line 1002, in _ws_connect
    resp = await self.request(
           ^^^^^^^^^^^^^^^^^^^
  File "C:\Users\MSI\AppData\Local\Packages\PythonSoftwareFoundation.Python.3.11_qbz5n2kfra8p0\LocalCache\local-packages\Python311\site-packages\aiohttp\client.py", line 701, in _request
    conn = await self._connector.connect(
           ^^^^^^^^^^^^^^^^^^^^^^^^^^^^^^
  File "C:\Users\MSI\AppData\Local\Packages\PythonSoftwareFoundation.Python.3.11_qbz5n2kfra8p0\LocalCache\local-packages\Python311\site-packages\aiohttp\connector.py", line 544, in connect
    proto = await self._create_connection(req, traces, timeout)
            ^^^^^^^^^^^^^^^^^^^^^^^^^^^^^^^^^^^^^^^^^^^^^^^^^^^
  File "C:\Users\MSI\AppData\Local\Packages\PythonSoftwareFoundation.Python.3.11_qbz5n2kfra8p0\LocalCache\local-packages\Python311\site-packages\aiohttp\connector.py", line 1050, in _create_connection
    _, proto = await self._create_direct_connection(req, traces, timeout)
               ^^^^^^^^^^^^^^^^^^^^^^^^^^^^^^^^^^^^^^^^^^^^^^^^^^^^^^^^^^
  File "C:\Users\MSI\AppData\Local\Packages\PythonSoftwareFoundation.Python.3.11_qbz5n2kfra8p0\LocalCache\local-packages\Python311\site-packages\aiohttp\connector.py", line 1351, in _create_direct_connection
    raise ClientConnectorDNSError(req.connection_key, exc) from exc
aiohttp.client_exceptions.ClientConnectorDNSError: Cannot connect to host gateway-us-east1-d.discord.gg:443 ssl:default [getaddrinfo failed]
2024-12-22 20:30:03,506 - ERROR - Attempting a reconnect in 13.36s
Traceback (most recent call last):
  File "C:\Users\MSI\AppData\Local\Packages\PythonSoftwareFoundation.Python.3.11_qbz5n2kfra8p0\LocalCache\local-packages\Python311\site-packages\aiohttp\connector.py", line 1345, in _create_direct_connection
    hosts = await self._resolve_host(host, port, traces=traces)
            ^^^^^^^^^^^^^^^^^^^^^^^^^^^^^^^^^^^^^^^^^^^^^^^^^^^
  File "C:\Users\MSI\AppData\Local\Packages\PythonSoftwareFoundation.Python.3.11_qbz5n2kfra8p0\LocalCache\local-packages\Python311\site-packages\aiohttp\connector.py", line 989, in _resolve_host
    return await asyncio.shield(resolved_host_task)
           ^^^^^^^^^^^^^^^^^^^^^^^^^^^^^^^^^^^^^^^^
  File "C:\Users\MSI\AppData\Local\Packages\PythonSoftwareFoundation.Python.3.11_qbz5n2kfra8p0\LocalCache\local-packages\Python311\site-packages\aiohttp\connector.py", line 1020, in _resolve_host_with_throttle
    addrs = await self._resolver.resolve(host, port, family=self._family)
            ^^^^^^^^^^^^^^^^^^^^^^^^^^^^^^^^^^^^^^^^^^^^^^^^^^^^^^^^^^^^^
  File "C:\Users\MSI\AppData\Local\Packages\PythonSoftwareFoundation.Python.3.11_qbz5n2kfra8p0\LocalCache\local-packages\Python311\site-packages\aiohttp\resolver.py", line 36, in resolve
    infos = await self._loop.getaddrinfo(
            ^^^^^^^^^^^^^^^^^^^^^^^^^^^^^
  File "C:\Program Files\WindowsApps\PythonSoftwareFoundation.Python.3.11_3.11.2544.0_x64__qbz5n2kfra8p0\Lib\asyncio\base_events.py", line 868, in getaddrinfo
    return await self.run_in_executor(
           ^^^^^^^^^^^^^^^^^^^^^^^^^^^
  File "C:\Program Files\WindowsApps\PythonSoftwareFoundation.Python.3.11_3.11.2544.0_x64__qbz5n2kfra8p0\Lib\concurrent\futures\thread.py", line 58, in run
    result = self.fn(*self.args, **self.kwargs)
             ^^^^^^^^^^^^^^^^^^^^^^^^^^^^^^^^^^
  File "C:\Program Files\WindowsApps\PythonSoftwareFoundation.Python.3.11_3.11.2544.0_x64__qbz5n2kfra8p0\Lib\socket.py", line 962, in getaddrinfo
    for res in _socket.getaddrinfo(host, port, family, type, proto, flags):
               ^^^^^^^^^^^^^^^^^^^^^^^^^^^^^^^^^^^^^^^^^^^^^^^^^^^^^^^^^^^
socket.gaierror: [Errno 11001] getaddrinfo failed

The above exception was the direct cause of the following exception:

Traceback (most recent call last):
  File "C:\Users\MSI\AppData\Local\Packages\PythonSoftwareFoundation.Python.3.11_qbz5n2kfra8p0\LocalCache\local-packages\Python311\site-packages\discord\client.py", line 664, in connect
    self.ws = await asyncio.wait_for(coro, timeout=60.0)
              ^^^^^^^^^^^^^^^^^^^^^^^^^^^^^^^^^^^^^^^^^^
  File "C:\Program Files\WindowsApps\PythonSoftwareFoundation.Python.3.11_3.11.2544.0_x64__qbz5n2kfra8p0\Lib\asyncio\tasks.py", line 489, in wait_for
    return fut.result()
           ^^^^^^^^^^^^
  File "C:\Users\MSI\AppData\Local\Packages\PythonSoftwareFoundation.Python.3.11_qbz5n2kfra8p0\LocalCache\local-packages\Python311\site-packages\discord\gateway.py", line 374, in from_client
    socket = await client.http.ws_connect(str(url))
             ^^^^^^^^^^^^^^^^^^^^^^^^^^^^^^^^^^^^^^
  File "C:\Users\MSI\AppData\Local\Packages\PythonSoftwareFoundation.Python.3.11_qbz5n2kfra8p0\LocalCache\local-packages\Python311\site-packages\discord\http.py", line 550, in ws_connect
    return await self.__session.ws_connect(url, **kwargs)
           ^^^^^^^^^^^^^^^^^^^^^^^^^^^^^^^^^^^^^^^^^^^^^^
  File "C:\Users\MSI\AppData\Local\Packages\PythonSoftwareFoundation.Python.3.11_qbz5n2kfra8p0\LocalCache\local-packages\Python311\site-packages\aiohttp\client.py", line 1002, in _ws_connect
    resp = await self.request(
           ^^^^^^^^^^^^^^^^^^^
  File "C:\Users\MSI\AppData\Local\Packages\PythonSoftwareFoundation.Python.3.11_qbz5n2kfra8p0\LocalCache\local-packages\Python311\site-packages\aiohttp\client.py", line 701, in _request
    conn = await self._connector.connect(
           ^^^^^^^^^^^^^^^^^^^^^^^^^^^^^^
  File "C:\Users\MSI\AppData\Local\Packages\PythonSoftwareFoundation.Python.3.11_qbz5n2kfra8p0\LocalCache\local-packages\Python311\site-packages\aiohttp\connector.py", line 544, in connect
    proto = await self._create_connection(req, traces, timeout)
            ^^^^^^^^^^^^^^^^^^^^^^^^^^^^^^^^^^^^^^^^^^^^^^^^^^^
  File "C:\Users\MSI\AppData\Local\Packages\PythonSoftwareFoundation.Python.3.11_qbz5n2kfra8p0\LocalCache\local-packages\Python311\site-packages\aiohttp\connector.py", line 1050, in _create_connection
    _, proto = await self._create_direct_connection(req, traces, timeout)
               ^^^^^^^^^^^^^^^^^^^^^^^^^^^^^^^^^^^^^^^^^^^^^^^^^^^^^^^^^^
  File "C:\Users\MSI\AppData\Local\Packages\PythonSoftwareFoundation.Python.3.11_qbz5n2kfra8p0\LocalCache\local-packages\Python311\site-packages\aiohttp\connector.py", line 1351, in _create_direct_connection
    raise ClientConnectorDNSError(req.connection_key, exc) from exc
aiohttp.client_exceptions.ClientConnectorDNSError: Cannot connect to host gateway-us-east1-d.discord.gg:443 ssl:default [getaddrinfo failed]
2024-12-22 23:09:49,935 - INFO - Shard ID None session has been invalidated.
2024-12-22 23:09:55,669 - INFO - Shard ID None has connected to Gateway (Session ID: 1ad6cd72a2d57b4168cbff87c66624d9).
2024-12-22 23:09:57,741 - INFO - Bot is online as OF verification#6016
2024-12-22 23:18:46,627 - INFO - Shard ID None session has been invalidated.
2024-12-22 23:18:52,613 - INFO - Shard ID None has connected to Gateway (Session ID: 8a566b8c4500e703439aec584033c8af).
2024-12-22 23:18:54,737 - INFO - Bot is online as OF verification#6016
2024-12-22 23:35:18,309 - INFO - Shard ID None has successfully RESUMED session 8a566b8c4500e703439aec584033c8af.
2024-12-23 02:33:43,629 - INFO - Shard ID None has successfully RESUMED session 8a566b8c4500e703439aec584033c8af.
2024-12-23 03:12:20,574 - INFO - Shard ID None has successfully RESUMED session 8a566b8c4500e703439aec584033c8af.
2024-12-23 05:32:12,406 - INFO - Shard ID None has successfully RESUMED session 8a566b8c4500e703439aec584033c8af.
2024-12-23 07:33:57,148 - INFO - Shard ID None has successfully RESUMED session 8a566b8c4500e703439aec584033c8af.
2024-12-23 08:50:47,674 - WARNING - Shard ID None has stopped responding to the gateway. Closing and restarting.
2024-12-23 08:50:48,219 - INFO - Shard ID None session has been invalidated.
2024-12-23 08:50:53,964 - INFO - Shard ID None has connected to Gateway (Session ID: a4ae20b70020b0063b1812fff44d2b8d).
2024-12-23 08:50:56,019 - INFO - Bot is online as OF verification#6016
2024-12-23 10:34:16,753 - INFO - Shard ID None session has been invalidated.
2024-12-23 10:34:22,661 - INFO - Shard ID None has connected to Gateway (Session ID: af64c8522d34fff74c42c530907e165e).
2024-12-23 10:34:24,999 - INFO - Bot is online as OF verification#6016
2024-12-23 12:19:31,195 - ERROR - Attempting a reconnect in 0.15s
Traceback (most recent call last):
  File "C:\Users\MSI\AppData\Local\Packages\PythonSoftwareFoundation.Python.3.11_qbz5n2kfra8p0\LocalCache\local-packages\Python311\site-packages\aiohttp\connector.py", line 1345, in _create_direct_connection
    hosts = await self._resolve_host(host, port, traces=traces)
            ^^^^^^^^^^^^^^^^^^^^^^^^^^^^^^^^^^^^^^^^^^^^^^^^^^^
  File "C:\Users\MSI\AppData\Local\Packages\PythonSoftwareFoundation.Python.3.11_qbz5n2kfra8p0\LocalCache\local-packages\Python311\site-packages\aiohttp\connector.py", line 989, in _resolve_host
    return await asyncio.shield(resolved_host_task)
           ^^^^^^^^^^^^^^^^^^^^^^^^^^^^^^^^^^^^^^^^
  File "C:\Users\MSI\AppData\Local\Packages\PythonSoftwareFoundation.Python.3.11_qbz5n2kfra8p0\LocalCache\local-packages\Python311\site-packages\aiohttp\connector.py", line 1020, in _resolve_host_with_throttle
    addrs = await self._resolver.resolve(host, port, family=self._family)
            ^^^^^^^^^^^^^^^^^^^^^^^^^^^^^^^^^^^^^^^^^^^^^^^^^^^^^^^^^^^^^
  File "C:\Users\MSI\AppData\Local\Packages\PythonSoftwareFoundation.Python.3.11_qbz5n2kfra8p0\LocalCache\local-packages\Python311\site-packages\aiohttp\resolver.py", line 36, in resolve
    infos = await self._loop.getaddrinfo(
            ^^^^^^^^^^^^^^^^^^^^^^^^^^^^^
  File "C:\Program Files\WindowsApps\PythonSoftwareFoundation.Python.3.11_3.11.2544.0_x64__qbz5n2kfra8p0\Lib\asyncio\base_events.py", line 868, in getaddrinfo
    return await self.run_in_executor(
           ^^^^^^^^^^^^^^^^^^^^^^^^^^^
  File "C:\Program Files\WindowsApps\PythonSoftwareFoundation.Python.3.11_3.11.2544.0_x64__qbz5n2kfra8p0\Lib\concurrent\futures\thread.py", line 58, in run
    result = self.fn(*self.args, **self.kwargs)
             ^^^^^^^^^^^^^^^^^^^^^^^^^^^^^^^^^^
  File "C:\Program Files\WindowsApps\PythonSoftwareFoundation.Python.3.11_3.11.2544.0_x64__qbz5n2kfra8p0\Lib\socket.py", line 962, in getaddrinfo
    for res in _socket.getaddrinfo(host, port, family, type, proto, flags):
               ^^^^^^^^^^^^^^^^^^^^^^^^^^^^^^^^^^^^^^^^^^^^^^^^^^^^^^^^^^^
socket.gaierror: [Errno 11001] getaddrinfo failed

The above exception was the direct cause of the following exception:

Traceback (most recent call last):
  File "C:\Users\MSI\AppData\Local\Packages\PythonSoftwareFoundation.Python.3.11_qbz5n2kfra8p0\LocalCache\local-packages\Python311\site-packages\discord\client.py", line 664, in connect
    self.ws = await asyncio.wait_for(coro, timeout=60.0)
              ^^^^^^^^^^^^^^^^^^^^^^^^^^^^^^^^^^^^^^^^^^
  File "C:\Program Files\WindowsApps\PythonSoftwareFoundation.Python.3.11_3.11.2544.0_x64__qbz5n2kfra8p0\Lib\asyncio\tasks.py", line 489, in wait_for
    return fut.result()
           ^^^^^^^^^^^^
  File "C:\Users\MSI\AppData\Local\Packages\PythonSoftwareFoundation.Python.3.11_qbz5n2kfra8p0\LocalCache\local-packages\Python311\site-packages\discord\gateway.py", line 374, in from_client
    socket = await client.http.ws_connect(str(url))
             ^^^^^^^^^^^^^^^^^^^^^^^^^^^^^^^^^^^^^^
  File "C:\Users\MSI\AppData\Local\Packages\PythonSoftwareFoundation.Python.3.11_qbz5n2kfra8p0\LocalCache\local-packages\Python311\site-packages\discord\http.py", line 550, in ws_connect
    return await self.__session.ws_connect(url, **kwargs)
           ^^^^^^^^^^^^^^^^^^^^^^^^^^^^^^^^^^^^^^^^^^^^^^
  File "C:\Users\MSI\AppData\Local\Packages\PythonSoftwareFoundation.Python.3.11_qbz5n2kfra8p0\LocalCache\local-packages\Python311\site-packages\aiohttp\client.py", line 1002, in _ws_connect
    resp = await self.request(
           ^^^^^^^^^^^^^^^^^^^
  File "C:\Users\MSI\AppData\Local\Packages\PythonSoftwareFoundation.Python.3.11_qbz5n2kfra8p0\LocalCache\local-packages\Python311\site-packages\aiohttp\client.py", line 701, in _request
    conn = await self._connector.connect(
           ^^^^^^^^^^^^^^^^^^^^^^^^^^^^^^
  File "C:\Users\MSI\AppData\Local\Packages\PythonSoftwareFoundation.Python.3.11_qbz5n2kfra8p0\LocalCache\local-packages\Python311\site-packages\aiohttp\connector.py", line 544, in connect
    proto = await self._create_connection(req, traces, timeout)
            ^^^^^^^^^^^^^^^^^^^^^^^^^^^^^^^^^^^^^^^^^^^^^^^^^^^
  File "C:\Users\MSI\AppData\Local\Packages\PythonSoftwareFoundation.Python.3.11_qbz5n2kfra8p0\LocalCache\local-packages\Python311\site-packages\aiohttp\connector.py", line 1050, in _create_connection
    _, proto = await self._create_direct_connection(req, traces, timeout)
               ^^^^^^^^^^^^^^^^^^^^^^^^^^^^^^^^^^^^^^^^^^^^^^^^^^^^^^^^^^
  File "C:\Users\MSI\AppData\Local\Packages\PythonSoftwareFoundation.Python.3.11_qbz5n2kfra8p0\LocalCache\local-packages\Python311\site-packages\aiohttp\connector.py", line 1351, in _create_direct_connection
    raise ClientConnectorDNSError(req.connection_key, exc) from exc
aiohttp.client_exceptions.ClientConnectorDNSError: Cannot connect to host gateway-us-east1-d.discord.gg:443 ssl:default [getaddrinfo failed]
2024-12-23 12:19:31,464 - ERROR - Attempting a reconnect in 3.25s
Traceback (most recent call last):
  File "C:\Users\MSI\AppData\Local\Packages\PythonSoftwareFoundation.Python.3.11_qbz5n2kfra8p0\LocalCache\local-packages\Python311\site-packages\aiohttp\connector.py", line 1345, in _create_direct_connection
    hosts = await self._resolve_host(host, port, traces=traces)
            ^^^^^^^^^^^^^^^^^^^^^^^^^^^^^^^^^^^^^^^^^^^^^^^^^^^
  File "C:\Users\MSI\AppData\Local\Packages\PythonSoftwareFoundation.Python.3.11_qbz5n2kfra8p0\LocalCache\local-packages\Python311\site-packages\aiohttp\connector.py", line 989, in _resolve_host
    return await asyncio.shield(resolved_host_task)
           ^^^^^^^^^^^^^^^^^^^^^^^^^^^^^^^^^^^^^^^^
  File "C:\Users\MSI\AppData\Local\Packages\PythonSoftwareFoundation.Python.3.11_qbz5n2kfra8p0\LocalCache\local-packages\Python311\site-packages\aiohttp\connector.py", line 1020, in _resolve_host_with_throttle
    addrs = await self._resolver.resolve(host, port, family=self._family)
            ^^^^^^^^^^^^^^^^^^^^^^^^^^^^^^^^^^^^^^^^^^^^^^^^^^^^^^^^^^^^^
  File "C:\Users\MSI\AppData\Local\Packages\PythonSoftwareFoundation.Python.3.11_qbz5n2kfra8p0\LocalCache\local-packages\Python311\site-packages\aiohttp\resolver.py", line 36, in resolve
    infos = await self._loop.getaddrinfo(
            ^^^^^^^^^^^^^^^^^^^^^^^^^^^^^
  File "C:\Program Files\WindowsApps\PythonSoftwareFoundation.Python.3.11_3.11.2544.0_x64__qbz5n2kfra8p0\Lib\asyncio\base_events.py", line 868, in getaddrinfo
    return await self.run_in_executor(
           ^^^^^^^^^^^^^^^^^^^^^^^^^^^
  File "C:\Program Files\WindowsApps\PythonSoftwareFoundation.Python.3.11_3.11.2544.0_x64__qbz5n2kfra8p0\Lib\concurrent\futures\thread.py", line 58, in run
    result = self.fn(*self.args, **self.kwargs)
             ^^^^^^^^^^^^^^^^^^^^^^^^^^^^^^^^^^
  File "C:\Program Files\WindowsApps\PythonSoftwareFoundation.Python.3.11_3.11.2544.0_x64__qbz5n2kfra8p0\Lib\socket.py", line 962, in getaddrinfo
    for res in _socket.getaddrinfo(host, port, family, type, proto, flags):
               ^^^^^^^^^^^^^^^^^^^^^^^^^^^^^^^^^^^^^^^^^^^^^^^^^^^^^^^^^^^
socket.gaierror: [Errno 11001] getaddrinfo failed

The above exception was the direct cause of the following exception:

Traceback (most recent call last):
  File "C:\Users\MSI\AppData\Local\Packages\PythonSoftwareFoundation.Python.3.11_qbz5n2kfra8p0\LocalCache\local-packages\Python311\site-packages\discord\client.py", line 664, in connect
    self.ws = await asyncio.wait_for(coro, timeout=60.0)
              ^^^^^^^^^^^^^^^^^^^^^^^^^^^^^^^^^^^^^^^^^^
  File "C:\Program Files\WindowsApps\PythonSoftwareFoundation.Python.3.11_3.11.2544.0_x64__qbz5n2kfra8p0\Lib\asyncio\tasks.py", line 489, in wait_for
    return fut.result()
           ^^^^^^^^^^^^
  File "C:\Users\MSI\AppData\Local\Packages\PythonSoftwareFoundation.Python.3.11_qbz5n2kfra8p0\LocalCache\local-packages\Python311\site-packages\discord\gateway.py", line 374, in from_client
    socket = await client.http.ws_connect(str(url))
             ^^^^^^^^^^^^^^^^^^^^^^^^^^^^^^^^^^^^^^
  File "C:\Users\MSI\AppData\Local\Packages\PythonSoftwareFoundation.Python.3.11_qbz5n2kfra8p0\LocalCache\local-packages\Python311\site-packages\discord\http.py", line 550, in ws_connect
    return await self.__session.ws_connect(url, **kwargs)
           ^^^^^^^^^^^^^^^^^^^^^^^^^^^^^^^^^^^^^^^^^^^^^^
  File "C:\Users\MSI\AppData\Local\Packages\PythonSoftwareFoundation.Python.3.11_qbz5n2kfra8p0\LocalCache\local-packages\Python311\site-packages\aiohttp\client.py", line 1002, in _ws_connect
    resp = await self.request(
           ^^^^^^^^^^^^^^^^^^^
  File "C:\Users\MSI\AppData\Local\Packages\PythonSoftwareFoundation.Python.3.11_qbz5n2kfra8p0\LocalCache\local-packages\Python311\site-packages\aiohttp\client.py", line 701, in _request
    conn = await self._connector.connect(
           ^^^^^^^^^^^^^^^^^^^^^^^^^^^^^^
  File "C:\Users\MSI\AppData\Local\Packages\PythonSoftwareFoundation.Python.3.11_qbz5n2kfra8p0\LocalCache\local-packages\Python311\site-packages\aiohttp\connector.py", line 544, in connect
    proto = await self._create_connection(req, traces, timeout)
            ^^^^^^^^^^^^^^^^^^^^^^^^^^^^^^^^^^^^^^^^^^^^^^^^^^^
  File "C:\Users\MSI\AppData\Local\Packages\PythonSoftwareFoundation.Python.3.11_qbz5n2kfra8p0\LocalCache\local-packages\Python311\site-packages\aiohttp\connector.py", line 1050, in _create_connection
    _, proto = await self._create_direct_connection(req, traces, timeout)
               ^^^^^^^^^^^^^^^^^^^^^^^^^^^^^^^^^^^^^^^^^^^^^^^^^^^^^^^^^^
  File "C:\Users\MSI\AppData\Local\Packages\PythonSoftwareFoundation.Python.3.11_qbz5n2kfra8p0\LocalCache\local-packages\Python311\site-packages\aiohttp\connector.py", line 1351, in _create_direct_connection
    raise ClientConnectorDNSError(req.connection_key, exc) from exc
aiohttp.client_exceptions.ClientConnectorDNSError: Cannot connect to host gateway-us-east1-d.discord.gg:443 ssl:default [getaddrinfo failed]
2024-12-23 12:19:34,745 - ERROR - Attempting a reconnect in 2.88s
Traceback (most recent call last):
  File "C:\Users\MSI\AppData\Local\Packages\PythonSoftwareFoundation.Python.3.11_qbz5n2kfra8p0\LocalCache\local-packages\Python311\site-packages\aiohttp\connector.py", line 1345, in _create_direct_connection
    hosts = await self._resolve_host(host, port, traces=traces)
            ^^^^^^^^^^^^^^^^^^^^^^^^^^^^^^^^^^^^^^^^^^^^^^^^^^^
  File "C:\Users\MSI\AppData\Local\Packages\PythonSoftwareFoundation.Python.3.11_qbz5n2kfra8p0\LocalCache\local-packages\Python311\site-packages\aiohttp\connector.py", line 989, in _resolve_host
    return await asyncio.shield(resolved_host_task)
           ^^^^^^^^^^^^^^^^^^^^^^^^^^^^^^^^^^^^^^^^
  File "C:\Users\MSI\AppData\Local\Packages\PythonSoftwareFoundation.Python.3.11_qbz5n2kfra8p0\LocalCache\local-packages\Python311\site-packages\aiohttp\connector.py", line 1020, in _resolve_host_with_throttle
    addrs = await self._resolver.resolve(host, port, family=self._family)
            ^^^^^^^^^^^^^^^^^^^^^^^^^^^^^^^^^^^^^^^^^^^^^^^^^^^^^^^^^^^^^
  File "C:\Users\MSI\AppData\Local\Packages\PythonSoftwareFoundation.Python.3.11_qbz5n2kfra8p0\LocalCache\local-packages\Python311\site-packages\aiohttp\resolver.py", line 36, in resolve
    infos = await self._loop.getaddrinfo(
            ^^^^^^^^^^^^^^^^^^^^^^^^^^^^^
  File "C:\Program Files\WindowsApps\PythonSoftwareFoundation.Python.3.11_3.11.2544.0_x64__qbz5n2kfra8p0\Lib\asyncio\base_events.py", line 868, in getaddrinfo
    return await self.run_in_executor(
           ^^^^^^^^^^^^^^^^^^^^^^^^^^^
  File "C:\Program Files\WindowsApps\PythonSoftwareFoundation.Python.3.11_3.11.2544.0_x64__qbz5n2kfra8p0\Lib\concurrent\futures\thread.py", line 58, in run
    result = self.fn(*self.args, **self.kwargs)
             ^^^^^^^^^^^^^^^^^^^^^^^^^^^^^^^^^^
  File "C:\Program Files\WindowsApps\PythonSoftwareFoundation.Python.3.11_3.11.2544.0_x64__qbz5n2kfra8p0\Lib\socket.py", line 962, in getaddrinfo
    for res in _socket.getaddrinfo(host, port, family, type, proto, flags):
               ^^^^^^^^^^^^^^^^^^^^^^^^^^^^^^^^^^^^^^^^^^^^^^^^^^^^^^^^^^^
socket.gaierror: [Errno 11001] getaddrinfo failed

The above exception was the direct cause of the following exception:

Traceback (most recent call last):
  File "C:\Users\MSI\AppData\Local\Packages\PythonSoftwareFoundation.Python.3.11_qbz5n2kfra8p0\LocalCache\local-packages\Python311\site-packages\discord\client.py", line 664, in connect
    self.ws = await asyncio.wait_for(coro, timeout=60.0)
              ^^^^^^^^^^^^^^^^^^^^^^^^^^^^^^^^^^^^^^^^^^
  File "C:\Program Files\WindowsApps\PythonSoftwareFoundation.Python.3.11_3.11.2544.0_x64__qbz5n2kfra8p0\Lib\asyncio\tasks.py", line 489, in wait_for
    return fut.result()
           ^^^^^^^^^^^^
  File "C:\Users\MSI\AppData\Local\Packages\PythonSoftwareFoundation.Python.3.11_qbz5n2kfra8p0\LocalCache\local-packages\Python311\site-packages\discord\gateway.py", line 374, in from_client
    socket = await client.http.ws_connect(str(url))
             ^^^^^^^^^^^^^^^^^^^^^^^^^^^^^^^^^^^^^^
  File "C:\Users\MSI\AppData\Local\Packages\PythonSoftwareFoundation.Python.3.11_qbz5n2kfra8p0\LocalCache\local-packages\Python311\site-packages\discord\http.py", line 550, in ws_connect
    return await self.__session.ws_connect(url, **kwargs)
           ^^^^^^^^^^^^^^^^^^^^^^^^^^^^^^^^^^^^^^^^^^^^^^
  File "C:\Users\MSI\AppData\Local\Packages\PythonSoftwareFoundation.Python.3.11_qbz5n2kfra8p0\LocalCache\local-packages\Python311\site-packages\aiohttp\client.py", line 1002, in _ws_connect
    resp = await self.request(
           ^^^^^^^^^^^^^^^^^^^
  File "C:\Users\MSI\AppData\Local\Packages\PythonSoftwareFoundation.Python.3.11_qbz5n2kfra8p0\LocalCache\local-packages\Python311\site-packages\aiohttp\client.py", line 701, in _request
    conn = await self._connector.connect(
           ^^^^^^^^^^^^^^^^^^^^^^^^^^^^^^
  File "C:\Users\MSI\AppData\Local\Packages\PythonSoftwareFoundation.Python.3.11_qbz5n2kfra8p0\LocalCache\local-packages\Python311\site-packages\aiohttp\connector.py", line 544, in connect
    proto = await self._create_connection(req, traces, timeout)
            ^^^^^^^^^^^^^^^^^^^^^^^^^^^^^^^^^^^^^^^^^^^^^^^^^^^
  File "C:\Users\MSI\AppData\Local\Packages\PythonSoftwareFoundation.Python.3.11_qbz5n2kfra8p0\LocalCache\local-packages\Python311\site-packages\aiohttp\connector.py", line 1050, in _create_connection
    _, proto = await self._create_direct_connection(req, traces, timeout)
               ^^^^^^^^^^^^^^^^^^^^^^^^^^^^^^^^^^^^^^^^^^^^^^^^^^^^^^^^^^
  File "C:\Users\MSI\AppData\Local\Packages\PythonSoftwareFoundation.Python.3.11_qbz5n2kfra8p0\LocalCache\local-packages\Python311\site-packages\aiohttp\connector.py", line 1351, in _create_direct_connection
    raise ClientConnectorDNSError(req.connection_key, exc) from exc
aiohttp.client_exceptions.ClientConnectorDNSError: Cannot connect to host gateway-us-east1-d.discord.gg:443 ssl:default [getaddrinfo failed]
2024-12-23 12:19:37,642 - ERROR - Attempting a reconnect in 14.11s
Traceback (most recent call last):
  File "C:\Users\MSI\AppData\Local\Packages\PythonSoftwareFoundation.Python.3.11_qbz5n2kfra8p0\LocalCache\local-packages\Python311\site-packages\aiohttp\connector.py", line 1345, in _create_direct_connection
    hosts = await self._resolve_host(host, port, traces=traces)
            ^^^^^^^^^^^^^^^^^^^^^^^^^^^^^^^^^^^^^^^^^^^^^^^^^^^
  File "C:\Users\MSI\AppData\Local\Packages\PythonSoftwareFoundation.Python.3.11_qbz5n2kfra8p0\LocalCache\local-packages\Python311\site-packages\aiohttp\connector.py", line 989, in _resolve_host
    return await asyncio.shield(resolved_host_task)
           ^^^^^^^^^^^^^^^^^^^^^^^^^^^^^^^^^^^^^^^^
  File "C:\Users\MSI\AppData\Local\Packages\PythonSoftwareFoundation.Python.3.11_qbz5n2kfra8p0\LocalCache\local-packages\Python311\site-packages\aiohttp\connector.py", line 1020, in _resolve_host_with_throttle
    addrs = await self._resolver.resolve(host, port, family=self._family)
            ^^^^^^^^^^^^^^^^^^^^^^^^^^^^^^^^^^^^^^^^^^^^^^^^^^^^^^^^^^^^^
  File "C:\Users\MSI\AppData\Local\Packages\PythonSoftwareFoundation.Python.3.11_qbz5n2kfra8p0\LocalCache\local-packages\Python311\site-packages\aiohttp\resolver.py", line 36, in resolve
    infos = await self._loop.getaddrinfo(
            ^^^^^^^^^^^^^^^^^^^^^^^^^^^^^
  File "C:\Program Files\WindowsApps\PythonSoftwareFoundation.Python.3.11_3.11.2544.0_x64__qbz5n2kfra8p0\Lib\asyncio\base_events.py", line 868, in getaddrinfo
    return await self.run_in_executor(
           ^^^^^^^^^^^^^^^^^^^^^^^^^^^
  File "C:\Program Files\WindowsApps\PythonSoftwareFoundation.Python.3.11_3.11.2544.0_x64__qbz5n2kfra8p0\Lib\concurrent\futures\thread.py", line 58, in run
    result = self.fn(*self.args, **self.kwargs)
             ^^^^^^^^^^^^^^^^^^^^^^^^^^^^^^^^^^
  File "C:\Program Files\WindowsApps\PythonSoftwareFoundation.Python.3.11_3.11.2544.0_x64__qbz5n2kfra8p0\Lib\socket.py", line 962, in getaddrinfo
    for res in _socket.getaddrinfo(host, port, family, type, proto, flags):
               ^^^^^^^^^^^^^^^^^^^^^^^^^^^^^^^^^^^^^^^^^^^^^^^^^^^^^^^^^^^
socket.gaierror: [Errno 11001] getaddrinfo failed

The above exception was the direct cause of the following exception:

Traceback (most recent call last):
  File "C:\Users\MSI\AppData\Local\Packages\PythonSoftwareFoundation.Python.3.11_qbz5n2kfra8p0\LocalCache\local-packages\Python311\site-packages\discord\client.py", line 664, in connect
    self.ws = await asyncio.wait_for(coro, timeout=60.0)
              ^^^^^^^^^^^^^^^^^^^^^^^^^^^^^^^^^^^^^^^^^^
  File "C:\Program Files\WindowsApps\PythonSoftwareFoundation.Python.3.11_3.11.2544.0_x64__qbz5n2kfra8p0\Lib\asyncio\tasks.py", line 489, in wait_for
    return fut.result()
           ^^^^^^^^^^^^
  File "C:\Users\MSI\AppData\Local\Packages\PythonSoftwareFoundation.Python.3.11_qbz5n2kfra8p0\LocalCache\local-packages\Python311\site-packages\discord\gateway.py", line 374, in from_client
    socket = await client.http.ws_connect(str(url))
             ^^^^^^^^^^^^^^^^^^^^^^^^^^^^^^^^^^^^^^
  File "C:\Users\MSI\AppData\Local\Packages\PythonSoftwareFoundation.Python.3.11_qbz5n2kfra8p0\LocalCache\local-packages\Python311\site-packages\discord\http.py", line 550, in ws_connect
    return await self.__session.ws_connect(url, **kwargs)
           ^^^^^^^^^^^^^^^^^^^^^^^^^^^^^^^^^^^^^^^^^^^^^^
  File "C:\Users\MSI\AppData\Local\Packages\PythonSoftwareFoundation.Python.3.11_qbz5n2kfra8p0\LocalCache\local-packages\Python311\site-packages\aiohttp\client.py", line 1002, in _ws_connect
    resp = await self.request(
           ^^^^^^^^^^^^^^^^^^^
  File "C:\Users\MSI\AppData\Local\Packages\PythonSoftwareFoundation.Python.3.11_qbz5n2kfra8p0\LocalCache\local-packages\Python311\site-packages\aiohttp\client.py", line 701, in _request
    conn = await self._connector.connect(
           ^^^^^^^^^^^^^^^^^^^^^^^^^^^^^^
  File "C:\Users\MSI\AppData\Local\Packages\PythonSoftwareFoundation.Python.3.11_qbz5n2kfra8p0\LocalCache\local-packages\Python311\site-packages\aiohttp\connector.py", line 544, in connect
    proto = await self._create_connection(req, traces, timeout)
            ^^^^^^^^^^^^^^^^^^^^^^^^^^^^^^^^^^^^^^^^^^^^^^^^^^^
  File "C:\Users\MSI\AppData\Local\Packages\PythonSoftwareFoundation.Python.3.11_qbz5n2kfra8p0\LocalCache\local-packages\Python311\site-packages\aiohttp\connector.py", line 1050, in _create_connection
    _, proto = await self._create_direct_connection(req, traces, timeout)
               ^^^^^^^^^^^^^^^^^^^^^^^^^^^^^^^^^^^^^^^^^^^^^^^^^^^^^^^^^^
  File "C:\Users\MSI\AppData\Local\Packages\PythonSoftwareFoundation.Python.3.11_qbz5n2kfra8p0\LocalCache\local-packages\Python311\site-packages\aiohttp\connector.py", line 1351, in _create_direct_connection
    raise ClientConnectorDNSError(req.connection_key, exc) from exc
aiohttp.client_exceptions.ClientConnectorDNSError: Cannot connect to host gateway-us-east1-d.discord.gg:443 ssl:default [getaddrinfo failed]
2024-12-23 12:23:13,310 - INFO - Shard ID None session has been invalidated.
2024-12-23 12:23:19,348 - INFO - Shard ID None has connected to Gateway (Session ID: 0910295c80adc012450c7f2006c20460).
2024-12-23 12:23:21,405 - INFO - Bot is online as OF verification#6016
2024-12-23 12:38:46,313 - WARNING - PyNaCl is not installed, voice will NOT be supported
2024-12-23 12:38:48,396 - INFO - HTTP Request: GET https://3morrrrr-of-verification-bot.hf.space/config "HTTP/1.1 200 OK"
2024-12-23 12:38:49,546 - INFO - HTTP Request: GET https://3morrrrr-of-verification-bot.hf.space/gradio_api/info?serialize=False "HTTP/1.1 200 OK"
2024-12-23 12:38:49,559 - INFO - logging in using static token
2024-12-23 12:38:50,514 - INFO - HTTP Request: GET https://3morrrrr-of-verification-bot.hf.space/gradio_api/heartbeat/06018466-29fc-4079-9248-8e85e23650e7 "HTTP/1.1 200 OK"
2024-12-23 12:38:51,165 - INFO - Shard ID None has connected to Gateway (Session ID: 7ec6d54c9c0125830f83656abee225ef).
2024-12-23 12:38:53,238 - INFO - Bot is online as OF verification#6016
